
INFO 2024-06-04 11:03:05,107 views 15772 19832 посещение страницы about в: 2024-06-04 11:03:05.107020
INFO 2024-06-04 11:03:05,107 basehttp 15772 19832 "GET /about/ HTTP/1.1" 200 1542
INFO 2024-06-10 11:35:12,024 autoreload 20304 10248 Watching for file changes with StatReloader
INFO 2024-06-10 11:35:14,017 views 20304 13268 посещение страницы index в: 2024-06-10 11:35:14.017911
INFO 2024-06-10 11:35:14,018 basehttp 20304 13268 "GET / HTTP/1.1" 200 1373
WARNING 2024-06-10 11:35:14,203 log 20304 13268 Not Found: /favicon.ico
WARNING 2024-06-10 11:35:14,204 basehttp 20304 13268 "GET /favicon.ico HTTP/1.1" 404 2441
INFO 2024-06-11 11:59:12,798 autoreload 14468 4576 Watching for file changes with StatReloader
WARNING 2024-06-11 11:59:17,533 log 14468 11876 Not Found: /users/login/
WARNING 2024-06-11 11:59:17,533 basehttp 14468 11876 "GET /users/login/ HTTP/1.1" 404 2444
INFO 2024-06-11 11:59:19,975 basehttp 14468 11876 "GET / HTTP/1.1" 200 175
INFO 2024-06-11 12:00:25,490 autoreload 14468 4576 C:\Users\Ivan\PycharmProjects\Django_geek_dz\myproject\myapp\views.py changed, reloading.
INFO 2024-06-11 12:00:25,927 autoreload 13760 15220 Watching for file changes with StatReloader
INFO 2024-06-11 12:00:34,196 basehttp 13760 3548 "GET /about HTTP/1.1" 301 0
INFO 2024-06-11 12:00:34,202 views 13760 14828 посещение страницы about в: 2024-06-11 12:00:34.202145
INFO 2024-06-11 12:00:34,205 basehttp 13760 14828 "GET /about/ HTTP/1.1" 200 1110
INFO 2024-06-11 13:29:44,056 views 13760 6256 посещение страницы about в: 2024-06-11 13:29:44.056502
INFO 2024-06-11 13:29:44,057 basehttp 13760 6256 "GET /about/ HTTP/1.1" 200 1110
INFO 2024-06-11 13:29:46,967 views 13760 2168 посещение страницы about в: 2024-06-11 13:29:46.967416
INFO 2024-06-11 13:29:46,968 basehttp 13760 2168 "GET / HTTP/1.1" 200 1115
INFO 2024-06-11 13:40:36,089 views 13760 4288 посещение страницы about в: 2024-06-11 13:40:36.089323
ERROR 2024-06-11 13:40:36,195 log 13760 4288 Internal Server Error: /
Traceback (most recent call last):
  File "C:\Users\Ivan\PycharmProjects\Django_geek_dz\.venv\Lib\site-packages\django\template\backends\django.py", line 61, in render
    return self.template.render(context)
           ^^^^^^^^^^^^^^^^^^^^^^^^^^^^^
  File "C:\Users\Ivan\PycharmProjects\Django_geek_dz\.venv\Lib\site-packages\django\template\base.py", line 171, in render
    return self._render(context)
           ^^^^^^^^^^^^^^^^^^^^^
  File "C:\Users\Ivan\PycharmProjects\Django_geek_dz\.venv\Lib\site-packages\django\template\base.py", line 163, in _render
    return self.nodelist.render(context)
           ^^^^^^^^^^^^^^^^^^^^^^^^^^^^^
  File "C:\Users\Ivan\PycharmProjects\Django_geek_dz\.venv\Lib\site-packages\django\template\base.py", line 1000, in render
    return SafeString("".join([node.render_annotated(context) for node in self]))
                               ^^^^^^^^^^^^^^^^^^^^^^^^^^^^^^
  File "C:\Users\Ivan\PycharmProjects\Django_geek_dz\.venv\Lib\site-packages\django\template\base.py", line 961, in render_annotated
    return self.render(context)
           ^^^^^^^^^^^^^^^^^^^^
  File "C:\Users\Ivan\PycharmProjects\Django_geek_dz\.venv\Lib\site-packages\django\template\loader_tags.py", line 134, in render
    compiled_parent = self.get_parent(context)
                      ^^^^^^^^^^^^^^^^^^^^^^^^
  File "C:\Users\Ivan\PycharmProjects\Django_geek_dz\.venv\Lib\site-packages\django\template\loader_tags.py", line 131, in get_parent
    return self.find_template(parent, context)
           ^^^^^^^^^^^^^^^^^^^^^^^^^^^^^^^^^^^
  File "C:\Users\Ivan\PycharmProjects\Django_geek_dz\.venv\Lib\site-packages\django\template\loader_tags.py", line 109, in find_template
    template, origin = context.template.engine.find_template(
                       ^^^^^^^^^^^^^^^^^^^^^^^^^^^^^^^^^^^^^^
  File "C:\Users\Ivan\PycharmProjects\Django_geek_dz\.venv\Lib\site-packages\django\template\engine.py", line 163, in find_template
    raise TemplateDoesNotExist(name, tried=tried)
django.template.exceptions.TemplateDoesNotExist: base.html

The above exception was the direct cause of the following exception:

Traceback (most recent call last):
  File "C:\Users\Ivan\PycharmProjects\Django_geek_dz\.venv\Lib\site-packages\django\core\handlers\exception.py", line 55, in inner
    response = get_response(request)
               ^^^^^^^^^^^^^^^^^^^^^
  File "C:\Users\Ivan\PycharmProjects\Django_geek_dz\.venv\Lib\site-packages\django\core\handlers\base.py", line 197, in _get_response
    response = wrapped_callback(request, *callback_args, **callback_kwargs)
               ^^^^^^^^^^^^^^^^^^^^^^^^^^^^^^^^^^^^^^^^^^^^^^^^^^^^^^^^^^^^
  File "C:\Users\Ivan\PycharmProjects\Django_geek_dz\myproject\myapp\views.py", line 13, in index
    return render(request, "myapp/index.html", context)
           ^^^^^^^^^^^^^^^^^^^^^^^^^^^^^^^^^^^^^^^^^^^^
  File "C:\Users\Ivan\PycharmProjects\Django_geek_dz\.venv\Lib\site-packages\django\shortcuts.py", line 25, in render
    content = loader.render_to_string(template_name, context, request, using=using)
              ^^^^^^^^^^^^^^^^^^^^^^^^^^^^^^^^^^^^^^^^^^^^^^^^^^^^^^^^^^^^^^^^^^^^^
  File "C:\Users\Ivan\PycharmProjects\Django_geek_dz\.venv\Lib\site-packages\django\template\loader.py", line 62, in render_to_string
    return template.render(context, request)
           ^^^^^^^^^^^^^^^^^^^^^^^^^^^^^^^^^
  File "C:\Users\Ivan\PycharmProjects\Django_geek_dz\.venv\Lib\site-packages\django\template\backends\django.py", line 63, in render
    reraise(exc, self.backend)
  File "C:\Users\Ivan\PycharmProjects\Django_geek_dz\.venv\Lib\site-packages\django\template\backends\django.py", line 84, in reraise
    raise new from exc
django.template.exceptions.TemplateDoesNotExist: base.html
ERROR 2024-06-11 13:40:36,200 basehttp 13760 4288 "GET / HTTP/1.1" 500 127615
INFO 2024-06-11 13:41:54,926 autoreload 17104 1768 Watching for file changes with StatReloader
INFO 2024-06-11 13:41:56,181 views 13760 4288 посещение страницы about в: 2024-06-11 13:41:56.181735
ERROR 2024-06-11 13:41:56,204 log 13760 4288 Internal Server Error: /
Traceback (most recent call last):
  File "C:\Users\Ivan\PycharmProjects\Django_geek_dz\.venv\Lib\site-packages\django\template\backends\django.py", line 61, in render
    return self.template.render(context)
           ^^^^^^^^^^^^^^^^^^^^^^^^^^^^^
  File "C:\Users\Ivan\PycharmProjects\Django_geek_dz\.venv\Lib\site-packages\django\template\base.py", line 171, in render
    return self._render(context)
           ^^^^^^^^^^^^^^^^^^^^^
  File "C:\Users\Ivan\PycharmProjects\Django_geek_dz\.venv\Lib\site-packages\django\template\base.py", line 163, in _render
    return self.nodelist.render(context)
           ^^^^^^^^^^^^^^^^^^^^^^^^^^^^^
  File "C:\Users\Ivan\PycharmProjects\Django_geek_dz\.venv\Lib\site-packages\django\template\base.py", line 1000, in render
    return SafeString("".join([node.render_annotated(context) for node in self]))
                               ^^^^^^^^^^^^^^^^^^^^^^^^^^^^^^
  File "C:\Users\Ivan\PycharmProjects\Django_geek_dz\.venv\Lib\site-packages\django\template\base.py", line 961, in render_annotated
    return self.render(context)
           ^^^^^^^^^^^^^^^^^^^^
  File "C:\Users\Ivan\PycharmProjects\Django_geek_dz\.venv\Lib\site-packages\django\template\loader_tags.py", line 134, in render
    compiled_parent = self.get_parent(context)
                      ^^^^^^^^^^^^^^^^^^^^^^^^
  File "C:\Users\Ivan\PycharmProjects\Django_geek_dz\.venv\Lib\site-packages\django\template\loader_tags.py", line 131, in get_parent
    return self.find_template(parent, context)
           ^^^^^^^^^^^^^^^^^^^^^^^^^^^^^^^^^^^
  File "C:\Users\Ivan\PycharmProjects\Django_geek_dz\.venv\Lib\site-packages\django\template\loader_tags.py", line 109, in find_template
    template, origin = context.template.engine.find_template(
                       ^^^^^^^^^^^^^^^^^^^^^^^^^^^^^^^^^^^^^^
  File "C:\Users\Ivan\PycharmProjects\Django_geek_dz\.venv\Lib\site-packages\django\template\engine.py", line 163, in find_template
    raise TemplateDoesNotExist(name, tried=tried)
django.template.exceptions.TemplateDoesNotExist: base.html

The above exception was the direct cause of the following exception:

Traceback (most recent call last):
  File "C:\Users\Ivan\PycharmProjects\Django_geek_dz\.venv\Lib\site-packages\django\core\handlers\exception.py", line 55, in inner
    response = get_response(request)
               ^^^^^^^^^^^^^^^^^^^^^
  File "C:\Users\Ivan\PycharmProjects\Django_geek_dz\.venv\Lib\site-packages\django\core\handlers\base.py", line 197, in _get_response
    response = wrapped_callback(request, *callback_args, **callback_kwargs)
               ^^^^^^^^^^^^^^^^^^^^^^^^^^^^^^^^^^^^^^^^^^^^^^^^^^^^^^^^^^^^
  File "C:\Users\Ivan\PycharmProjects\Django_geek_dz\myproject\myapp\views.py", line 13, in index
    return render(request, "myapp/index.html", context)
           ^^^^^^^^^^^^^^^^^^^^^^^^^^^^^^^^^^^^^^^^^^^^
  File "C:\Users\Ivan\PycharmProjects\Django_geek_dz\.venv\Lib\site-packages\django\shortcuts.py", line 25, in render
    content = loader.render_to_string(template_name, context, request, using=using)
              ^^^^^^^^^^^^^^^^^^^^^^^^^^^^^^^^^^^^^^^^^^^^^^^^^^^^^^^^^^^^^^^^^^^^^
  File "C:\Users\Ivan\PycharmProjects\Django_geek_dz\.venv\Lib\site-packages\django\template\loader.py", line 62, in render_to_string
    return template.render(context, request)
           ^^^^^^^^^^^^^^^^^^^^^^^^^^^^^^^^^
  File "C:\Users\Ivan\PycharmProjects\Django_geek_dz\.venv\Lib\site-packages\django\template\backends\django.py", line 63, in render
    reraise(exc, self.backend)
  File "C:\Users\Ivan\PycharmProjects\Django_geek_dz\.venv\Lib\site-packages\django\template\backends\django.py", line 84, in reraise
    raise new from exc
django.template.exceptions.TemplateDoesNotExist: base.html
ERROR 2024-06-11 13:41:56,207 basehttp 13760 4288 "GET / HTTP/1.1" 500 127478
INFO 2024-06-11 13:42:04,925 views 13760 4288 посещение страницы about в: 2024-06-11 13:42:04.925151
ERROR 2024-06-11 13:42:04,941 log 13760 4288 Internal Server Error: /
Traceback (most recent call last):
  File "C:\Users\Ivan\PycharmProjects\Django_geek_dz\.venv\Lib\site-packages\django\template\backends\django.py", line 61, in render
    return self.template.render(context)
           ^^^^^^^^^^^^^^^^^^^^^^^^^^^^^
  File "C:\Users\Ivan\PycharmProjects\Django_geek_dz\.venv\Lib\site-packages\django\template\base.py", line 171, in render
    return self._render(context)
           ^^^^^^^^^^^^^^^^^^^^^
  File "C:\Users\Ivan\PycharmProjects\Django_geek_dz\.venv\Lib\site-packages\django\template\base.py", line 163, in _render
    return self.nodelist.render(context)
           ^^^^^^^^^^^^^^^^^^^^^^^^^^^^^
  File "C:\Users\Ivan\PycharmProjects\Django_geek_dz\.venv\Lib\site-packages\django\template\base.py", line 1000, in render
    return SafeString("".join([node.render_annotated(context) for node in self]))
                               ^^^^^^^^^^^^^^^^^^^^^^^^^^^^^^
  File "C:\Users\Ivan\PycharmProjects\Django_geek_dz\.venv\Lib\site-packages\django\template\base.py", line 961, in render_annotated
    return self.render(context)
           ^^^^^^^^^^^^^^^^^^^^
  File "C:\Users\Ivan\PycharmProjects\Django_geek_dz\.venv\Lib\site-packages\django\template\loader_tags.py", line 134, in render
    compiled_parent = self.get_parent(context)
                      ^^^^^^^^^^^^^^^^^^^^^^^^
  File "C:\Users\Ivan\PycharmProjects\Django_geek_dz\.venv\Lib\site-packages\django\template\loader_tags.py", line 131, in get_parent
    return self.find_template(parent, context)
           ^^^^^^^^^^^^^^^^^^^^^^^^^^^^^^^^^^^
  File "C:\Users\Ivan\PycharmProjects\Django_geek_dz\.venv\Lib\site-packages\django\template\loader_tags.py", line 109, in find_template
    template, origin = context.template.engine.find_template(
                       ^^^^^^^^^^^^^^^^^^^^^^^^^^^^^^^^^^^^^^
  File "C:\Users\Ivan\PycharmProjects\Django_geek_dz\.venv\Lib\site-packages\django\template\engine.py", line 163, in find_template
    raise TemplateDoesNotExist(name, tried=tried)
django.template.exceptions.TemplateDoesNotExist: base.html

The above exception was the direct cause of the following exception:

Traceback (most recent call last):
  File "C:\Users\Ivan\PycharmProjects\Django_geek_dz\.venv\Lib\site-packages\django\core\handlers\exception.py", line 55, in inner
    response = get_response(request)
               ^^^^^^^^^^^^^^^^^^^^^
  File "C:\Users\Ivan\PycharmProjects\Django_geek_dz\.venv\Lib\site-packages\django\core\handlers\base.py", line 197, in _get_response
    response = wrapped_callback(request, *callback_args, **callback_kwargs)
               ^^^^^^^^^^^^^^^^^^^^^^^^^^^^^^^^^^^^^^^^^^^^^^^^^^^^^^^^^^^^
  File "C:\Users\Ivan\PycharmProjects\Django_geek_dz\myproject\myapp\views.py", line 13, in index
    return render(request, "myapp/index.html", context)
           ^^^^^^^^^^^^^^^^^^^^^^^^^^^^^^^^^^^^^^^^^^^^
  File "C:\Users\Ivan\PycharmProjects\Django_geek_dz\.venv\Lib\site-packages\django\shortcuts.py", line 25, in render
    content = loader.render_to_string(template_name, context, request, using=using)
              ^^^^^^^^^^^^^^^^^^^^^^^^^^^^^^^^^^^^^^^^^^^^^^^^^^^^^^^^^^^^^^^^^^^^^
  File "C:\Users\Ivan\PycharmProjects\Django_geek_dz\.venv\Lib\site-packages\django\template\loader.py", line 62, in render_to_string
    return template.render(context, request)
           ^^^^^^^^^^^^^^^^^^^^^^^^^^^^^^^^^
  File "C:\Users\Ivan\PycharmProjects\Django_geek_dz\.venv\Lib\site-packages\django\template\backends\django.py", line 63, in render
    reraise(exc, self.backend)
  File "C:\Users\Ivan\PycharmProjects\Django_geek_dz\.venv\Lib\site-packages\django\template\backends\django.py", line 84, in reraise
    raise new from exc
django.template.exceptions.TemplateDoesNotExist: base.html
ERROR 2024-06-11 13:42:04,941 basehttp 13760 4288 "GET / HTTP/1.1" 500 127615
INFO 2024-06-11 13:42:42,763 views 13760 14692 посещение страницы about в: 2024-06-11 13:42:42.763912
ERROR 2024-06-11 13:42:42,784 log 13760 14692 Internal Server Error: /
Traceback (most recent call last):
  File "C:\Users\Ivan\PycharmProjects\Django_geek_dz\.venv\Lib\site-packages\django\template\backends\django.py", line 61, in render
    return self.template.render(context)
           ^^^^^^^^^^^^^^^^^^^^^^^^^^^^^
  File "C:\Users\Ivan\PycharmProjects\Django_geek_dz\.venv\Lib\site-packages\django\template\base.py", line 171, in render
    return self._render(context)
           ^^^^^^^^^^^^^^^^^^^^^
  File "C:\Users\Ivan\PycharmProjects\Django_geek_dz\.venv\Lib\site-packages\django\template\base.py", line 163, in _render
    return self.nodelist.render(context)
           ^^^^^^^^^^^^^^^^^^^^^^^^^^^^^
  File "C:\Users\Ivan\PycharmProjects\Django_geek_dz\.venv\Lib\site-packages\django\template\base.py", line 1000, in render
    return SafeString("".join([node.render_annotated(context) for node in self]))
                               ^^^^^^^^^^^^^^^^^^^^^^^^^^^^^^
  File "C:\Users\Ivan\PycharmProjects\Django_geek_dz\.venv\Lib\site-packages\django\template\base.py", line 961, in render_annotated
    return self.render(context)
           ^^^^^^^^^^^^^^^^^^^^
  File "C:\Users\Ivan\PycharmProjects\Django_geek_dz\.venv\Lib\site-packages\django\template\loader_tags.py", line 134, in render
    compiled_parent = self.get_parent(context)
                      ^^^^^^^^^^^^^^^^^^^^^^^^
  File "C:\Users\Ivan\PycharmProjects\Django_geek_dz\.venv\Lib\site-packages\django\template\loader_tags.py", line 131, in get_parent
    return self.find_template(parent, context)
           ^^^^^^^^^^^^^^^^^^^^^^^^^^^^^^^^^^^
  File "C:\Users\Ivan\PycharmProjects\Django_geek_dz\.venv\Lib\site-packages\django\template\loader_tags.py", line 109, in find_template
    template, origin = context.template.engine.find_template(
                       ^^^^^^^^^^^^^^^^^^^^^^^^^^^^^^^^^^^^^^
  File "C:\Users\Ivan\PycharmProjects\Django_geek_dz\.venv\Lib\site-packages\django\template\engine.py", line 163, in find_template
    raise TemplateDoesNotExist(name, tried=tried)
django.template.exceptions.TemplateDoesNotExist: myproject/base.html

The above exception was the direct cause of the following exception:

Traceback (most recent call last):
  File "C:\Users\Ivan\PycharmProjects\Django_geek_dz\.venv\Lib\site-packages\django\core\handlers\exception.py", line 55, in inner
    response = get_response(request)
               ^^^^^^^^^^^^^^^^^^^^^
  File "C:\Users\Ivan\PycharmProjects\Django_geek_dz\.venv\Lib\site-packages\django\core\handlers\base.py", line 197, in _get_response
    response = wrapped_callback(request, *callback_args, **callback_kwargs)
               ^^^^^^^^^^^^^^^^^^^^^^^^^^^^^^^^^^^^^^^^^^^^^^^^^^^^^^^^^^^^
  File "C:\Users\Ivan\PycharmProjects\Django_geek_dz\myproject\myapp\views.py", line 13, in index
    return render(request, "myapp/index.html", context)
           ^^^^^^^^^^^^^^^^^^^^^^^^^^^^^^^^^^^^^^^^^^^^
  File "C:\Users\Ivan\PycharmProjects\Django_geek_dz\.venv\Lib\site-packages\django\shortcuts.py", line 25, in render
    content = loader.render_to_string(template_name, context, request, using=using)
              ^^^^^^^^^^^^^^^^^^^^^^^^^^^^^^^^^^^^^^^^^^^^^^^^^^^^^^^^^^^^^^^^^^^^^
  File "C:\Users\Ivan\PycharmProjects\Django_geek_dz\.venv\Lib\site-packages\django\template\loader.py", line 62, in render_to_string
    return template.render(context, request)
           ^^^^^^^^^^^^^^^^^^^^^^^^^^^^^^^^^
  File "C:\Users\Ivan\PycharmProjects\Django_geek_dz\.venv\Lib\site-packages\django\template\backends\django.py", line 63, in render
    reraise(exc, self.backend)
  File "C:\Users\Ivan\PycharmProjects\Django_geek_dz\.venv\Lib\site-packages\django\template\backends\django.py", line 84, in reraise
    raise new from exc
django.template.exceptions.TemplateDoesNotExist: myproject/base.html
ERROR 2024-06-11 13:42:42,786 basehttp 13760 14692 "GET / HTTP/1.1" 500 127908
INFO 2024-06-11 13:42:43,625 views 13760 14692 посещение страницы about в: 2024-06-11 13:42:43.625362
ERROR 2024-06-11 13:42:43,646 log 13760 14692 Internal Server Error: /
Traceback (most recent call last):
  File "C:\Users\Ivan\PycharmProjects\Django_geek_dz\.venv\Lib\site-packages\django\template\backends\django.py", line 61, in render
    return self.template.render(context)
           ^^^^^^^^^^^^^^^^^^^^^^^^^^^^^
  File "C:\Users\Ivan\PycharmProjects\Django_geek_dz\.venv\Lib\site-packages\django\template\base.py", line 171, in render
    return self._render(context)
           ^^^^^^^^^^^^^^^^^^^^^
  File "C:\Users\Ivan\PycharmProjects\Django_geek_dz\.venv\Lib\site-packages\django\template\base.py", line 163, in _render
    return self.nodelist.render(context)
           ^^^^^^^^^^^^^^^^^^^^^^^^^^^^^
  File "C:\Users\Ivan\PycharmProjects\Django_geek_dz\.venv\Lib\site-packages\django\template\base.py", line 1000, in render
    return SafeString("".join([node.render_annotated(context) for node in self]))
                               ^^^^^^^^^^^^^^^^^^^^^^^^^^^^^^
  File "C:\Users\Ivan\PycharmProjects\Django_geek_dz\.venv\Lib\site-packages\django\template\base.py", line 961, in render_annotated
    return self.render(context)
           ^^^^^^^^^^^^^^^^^^^^
  File "C:\Users\Ivan\PycharmProjects\Django_geek_dz\.venv\Lib\site-packages\django\template\loader_tags.py", line 134, in render
    compiled_parent = self.get_parent(context)
                      ^^^^^^^^^^^^^^^^^^^^^^^^
  File "C:\Users\Ivan\PycharmProjects\Django_geek_dz\.venv\Lib\site-packages\django\template\loader_tags.py", line 131, in get_parent
    return self.find_template(parent, context)
           ^^^^^^^^^^^^^^^^^^^^^^^^^^^^^^^^^^^
  File "C:\Users\Ivan\PycharmProjects\Django_geek_dz\.venv\Lib\site-packages\django\template\loader_tags.py", line 109, in find_template
    template, origin = context.template.engine.find_template(
                       ^^^^^^^^^^^^^^^^^^^^^^^^^^^^^^^^^^^^^^
  File "C:\Users\Ivan\PycharmProjects\Django_geek_dz\.venv\Lib\site-packages\django\template\engine.py", line 163, in find_template
    raise TemplateDoesNotExist(name, tried=tried)
django.template.exceptions.TemplateDoesNotExist: myproject/base.html

The above exception was the direct cause of the following exception:

Traceback (most recent call last):
  File "C:\Users\Ivan\PycharmProjects\Django_geek_dz\.venv\Lib\site-packages\django\core\handlers\exception.py", line 55, in inner
    response = get_response(request)
               ^^^^^^^^^^^^^^^^^^^^^
  File "C:\Users\Ivan\PycharmProjects\Django_geek_dz\.venv\Lib\site-packages\django\core\handlers\base.py", line 197, in _get_response
    response = wrapped_callback(request, *callback_args, **callback_kwargs)
               ^^^^^^^^^^^^^^^^^^^^^^^^^^^^^^^^^^^^^^^^^^^^^^^^^^^^^^^^^^^^
  File "C:\Users\Ivan\PycharmProjects\Django_geek_dz\myproject\myapp\views.py", line 13, in index
    return render(request, "myapp/index.html", context)
           ^^^^^^^^^^^^^^^^^^^^^^^^^^^^^^^^^^^^^^^^^^^^
  File "C:\Users\Ivan\PycharmProjects\Django_geek_dz\.venv\Lib\site-packages\django\shortcuts.py", line 25, in render
    content = loader.render_to_string(template_name, context, request, using=using)
              ^^^^^^^^^^^^^^^^^^^^^^^^^^^^^^^^^^^^^^^^^^^^^^^^^^^^^^^^^^^^^^^^^^^^^
  File "C:\Users\Ivan\PycharmProjects\Django_geek_dz\.venv\Lib\site-packages\django\template\loader.py", line 62, in render_to_string
    return template.render(context, request)
           ^^^^^^^^^^^^^^^^^^^^^^^^^^^^^^^^^
  File "C:\Users\Ivan\PycharmProjects\Django_geek_dz\.venv\Lib\site-packages\django\template\backends\django.py", line 63, in render
    reraise(exc, self.backend)
  File "C:\Users\Ivan\PycharmProjects\Django_geek_dz\.venv\Lib\site-packages\django\template\backends\django.py", line 84, in reraise
    raise new from exc
django.template.exceptions.TemplateDoesNotExist: myproject/base.html
ERROR 2024-06-11 13:42:43,648 basehttp 13760 14692 "GET / HTTP/1.1" 500 127908
INFO 2024-06-11 13:42:44,483 views 13760 14692 посещение страницы about в: 2024-06-11 13:42:44.483234
ERROR 2024-06-11 13:42:44,504 log 13760 14692 Internal Server Error: /
Traceback (most recent call last):
  File "C:\Users\Ivan\PycharmProjects\Django_geek_dz\.venv\Lib\site-packages\django\template\backends\django.py", line 61, in render
    return self.template.render(context)
           ^^^^^^^^^^^^^^^^^^^^^^^^^^^^^
  File "C:\Users\Ivan\PycharmProjects\Django_geek_dz\.venv\Lib\site-packages\django\template\base.py", line 171, in render
    return self._render(context)
           ^^^^^^^^^^^^^^^^^^^^^
  File "C:\Users\Ivan\PycharmProjects\Django_geek_dz\.venv\Lib\site-packages\django\template\base.py", line 163, in _render
    return self.nodelist.render(context)
           ^^^^^^^^^^^^^^^^^^^^^^^^^^^^^
  File "C:\Users\Ivan\PycharmProjects\Django_geek_dz\.venv\Lib\site-packages\django\template\base.py", line 1000, in render
    return SafeString("".join([node.render_annotated(context) for node in self]))
                               ^^^^^^^^^^^^^^^^^^^^^^^^^^^^^^
  File "C:\Users\Ivan\PycharmProjects\Django_geek_dz\.venv\Lib\site-packages\django\template\base.py", line 961, in render_annotated
    return self.render(context)
           ^^^^^^^^^^^^^^^^^^^^
  File "C:\Users\Ivan\PycharmProjects\Django_geek_dz\.venv\Lib\site-packages\django\template\loader_tags.py", line 134, in render
    compiled_parent = self.get_parent(context)
                      ^^^^^^^^^^^^^^^^^^^^^^^^
  File "C:\Users\Ivan\PycharmProjects\Django_geek_dz\.venv\Lib\site-packages\django\template\loader_tags.py", line 131, in get_parent
    return self.find_template(parent, context)
           ^^^^^^^^^^^^^^^^^^^^^^^^^^^^^^^^^^^
  File "C:\Users\Ivan\PycharmProjects\Django_geek_dz\.venv\Lib\site-packages\django\template\loader_tags.py", line 109, in find_template
    template, origin = context.template.engine.find_template(
                       ^^^^^^^^^^^^^^^^^^^^^^^^^^^^^^^^^^^^^^
  File "C:\Users\Ivan\PycharmProjects\Django_geek_dz\.venv\Lib\site-packages\django\template\engine.py", line 163, in find_template
    raise TemplateDoesNotExist(name, tried=tried)
django.template.exceptions.TemplateDoesNotExist: myproject/base.html

The above exception was the direct cause of the following exception:

Traceback (most recent call last):
  File "C:\Users\Ivan\PycharmProjects\Django_geek_dz\.venv\Lib\site-packages\django\core\handlers\exception.py", line 55, in inner
    response = get_response(request)
               ^^^^^^^^^^^^^^^^^^^^^
  File "C:\Users\Ivan\PycharmProjects\Django_geek_dz\.venv\Lib\site-packages\django\core\handlers\base.py", line 197, in _get_response
    response = wrapped_callback(request, *callback_args, **callback_kwargs)
               ^^^^^^^^^^^^^^^^^^^^^^^^^^^^^^^^^^^^^^^^^^^^^^^^^^^^^^^^^^^^
  File "C:\Users\Ivan\PycharmProjects\Django_geek_dz\myproject\myapp\views.py", line 13, in index
    return render(request, "myapp/index.html", context)
           ^^^^^^^^^^^^^^^^^^^^^^^^^^^^^^^^^^^^^^^^^^^^
  File "C:\Users\Ivan\PycharmProjects\Django_geek_dz\.venv\Lib\site-packages\django\shortcuts.py", line 25, in render
    content = loader.render_to_string(template_name, context, request, using=using)
              ^^^^^^^^^^^^^^^^^^^^^^^^^^^^^^^^^^^^^^^^^^^^^^^^^^^^^^^^^^^^^^^^^^^^^
  File "C:\Users\Ivan\PycharmProjects\Django_geek_dz\.venv\Lib\site-packages\django\template\loader.py", line 62, in render_to_string
    return template.render(context, request)
           ^^^^^^^^^^^^^^^^^^^^^^^^^^^^^^^^^
  File "C:\Users\Ivan\PycharmProjects\Django_geek_dz\.venv\Lib\site-packages\django\template\backends\django.py", line 63, in render
    reraise(exc, self.backend)
  File "C:\Users\Ivan\PycharmProjects\Django_geek_dz\.venv\Lib\site-packages\django\template\backends\django.py", line 84, in reraise
    raise new from exc
django.template.exceptions.TemplateDoesNotExist: myproject/base.html
ERROR 2024-06-11 13:42:44,506 basehttp 13760 14692 "GET / HTTP/1.1" 500 127908
INFO 2024-06-11 13:44:04,196 autoreload 13760 15220 C:\Users\Ivan\PycharmProjects\Django_geek_dz\myproject\myproject\settings.py changed, reloading.
INFO 2024-06-11 13:44:04,430 autoreload 17104 1768 C:\Users\Ivan\PycharmProjects\Django_geek_dz\myproject\myproject\settings.py changed, reloading.
INFO 2024-06-11 13:44:04,684 autoreload 19056 13740 Watching for file changes with StatReloader
INFO 2024-06-11 13:44:04,910 autoreload 9572 5568 Watching for file changes with StatReloader
INFO 2024-06-11 13:44:07,852 views 19056 12276 посещение страницы about в: 2024-06-11 13:44:07.852123
ERROR 2024-06-11 13:44:07,905 log 19056 12276 Internal Server Error: /
Traceback (most recent call last):
  File "C:\Users\Ivan\PycharmProjects\Django_geek_dz\.venv\Lib\site-packages\django\template\backends\django.py", line 61, in render
    return self.template.render(context)
           ^^^^^^^^^^^^^^^^^^^^^^^^^^^^^
  File "C:\Users\Ivan\PycharmProjects\Django_geek_dz\.venv\Lib\site-packages\django\template\base.py", line 171, in render
    return self._render(context)
           ^^^^^^^^^^^^^^^^^^^^^
  File "C:\Users\Ivan\PycharmProjects\Django_geek_dz\.venv\Lib\site-packages\django\template\base.py", line 163, in _render
    return self.nodelist.render(context)
           ^^^^^^^^^^^^^^^^^^^^^^^^^^^^^
  File "C:\Users\Ivan\PycharmProjects\Django_geek_dz\.venv\Lib\site-packages\django\template\base.py", line 1000, in render
    return SafeString("".join([node.render_annotated(context) for node in self]))
                               ^^^^^^^^^^^^^^^^^^^^^^^^^^^^^^
  File "C:\Users\Ivan\PycharmProjects\Django_geek_dz\.venv\Lib\site-packages\django\template\base.py", line 961, in render_annotated
    return self.render(context)
           ^^^^^^^^^^^^^^^^^^^^
  File "C:\Users\Ivan\PycharmProjects\Django_geek_dz\.venv\Lib\site-packages\django\template\loader_tags.py", line 134, in render
    compiled_parent = self.get_parent(context)
                      ^^^^^^^^^^^^^^^^^^^^^^^^
  File "C:\Users\Ivan\PycharmProjects\Django_geek_dz\.venv\Lib\site-packages\django\template\loader_tags.py", line 131, in get_parent
    return self.find_template(parent, context)
           ^^^^^^^^^^^^^^^^^^^^^^^^^^^^^^^^^^^
  File "C:\Users\Ivan\PycharmProjects\Django_geek_dz\.venv\Lib\site-packages\django\template\loader_tags.py", line 109, in find_template
    template, origin = context.template.engine.find_template(
                       ^^^^^^^^^^^^^^^^^^^^^^^^^^^^^^^^^^^^^^
  File "C:\Users\Ivan\PycharmProjects\Django_geek_dz\.venv\Lib\site-packages\django\template\engine.py", line 163, in find_template
    raise TemplateDoesNotExist(name, tried=tried)
django.template.exceptions.TemplateDoesNotExist: myproject/base.html

The above exception was the direct cause of the following exception:

Traceback (most recent call last):
  File "C:\Users\Ivan\PycharmProjects\Django_geek_dz\.venv\Lib\site-packages\django\core\handlers\exception.py", line 55, in inner
    response = get_response(request)
               ^^^^^^^^^^^^^^^^^^^^^
  File "C:\Users\Ivan\PycharmProjects\Django_geek_dz\.venv\Lib\site-packages\django\core\handlers\base.py", line 197, in _get_response
    response = wrapped_callback(request, *callback_args, **callback_kwargs)
               ^^^^^^^^^^^^^^^^^^^^^^^^^^^^^^^^^^^^^^^^^^^^^^^^^^^^^^^^^^^^
  File "C:\Users\Ivan\PycharmProjects\Django_geek_dz\myproject\myapp\views.py", line 13, in index
    return render(request, "myapp/index.html", context)
           ^^^^^^^^^^^^^^^^^^^^^^^^^^^^^^^^^^^^^^^^^^^^
  File "C:\Users\Ivan\PycharmProjects\Django_geek_dz\.venv\Lib\site-packages\django\shortcuts.py", line 25, in render
    content = loader.render_to_string(template_name, context, request, using=using)
              ^^^^^^^^^^^^^^^^^^^^^^^^^^^^^^^^^^^^^^^^^^^^^^^^^^^^^^^^^^^^^^^^^^^^^
  File "C:\Users\Ivan\PycharmProjects\Django_geek_dz\.venv\Lib\site-packages\django\template\loader.py", line 62, in render_to_string
    return template.render(context, request)
           ^^^^^^^^^^^^^^^^^^^^^^^^^^^^^^^^^
  File "C:\Users\Ivan\PycharmProjects\Django_geek_dz\.venv\Lib\site-packages\django\template\backends\django.py", line 63, in render
    reraise(exc, self.backend)
  File "C:\Users\Ivan\PycharmProjects\Django_geek_dz\.venv\Lib\site-packages\django\template\backends\django.py", line 84, in reraise
    raise new from exc
django.template.exceptions.TemplateDoesNotExist: myproject/base.html
ERROR 2024-06-11 13:44:07,908 basehttp 19056 12276 "GET / HTTP/1.1" 500 128637
INFO 2024-06-11 13:44:22,332 views 19056 12276 посещение страницы about в: 2024-06-11 13:44:22.332665
ERROR 2024-06-11 13:44:22,355 log 19056 12276 Internal Server Error: /
Traceback (most recent call last):
  File "C:\Users\Ivan\PycharmProjects\Django_geek_dz\.venv\Lib\site-packages\django\template\backends\django.py", line 61, in render
    return self.template.render(context)
           ^^^^^^^^^^^^^^^^^^^^^^^^^^^^^
  File "C:\Users\Ivan\PycharmProjects\Django_geek_dz\.venv\Lib\site-packages\django\template\base.py", line 171, in render
    return self._render(context)
           ^^^^^^^^^^^^^^^^^^^^^
  File "C:\Users\Ivan\PycharmProjects\Django_geek_dz\.venv\Lib\site-packages\django\template\base.py", line 163, in _render
    return self.nodelist.render(context)
           ^^^^^^^^^^^^^^^^^^^^^^^^^^^^^
  File "C:\Users\Ivan\PycharmProjects\Django_geek_dz\.venv\Lib\site-packages\django\template\base.py", line 1000, in render
    return SafeString("".join([node.render_annotated(context) for node in self]))
                               ^^^^^^^^^^^^^^^^^^^^^^^^^^^^^^
  File "C:\Users\Ivan\PycharmProjects\Django_geek_dz\.venv\Lib\site-packages\django\template\base.py", line 961, in render_annotated
    return self.render(context)
           ^^^^^^^^^^^^^^^^^^^^
  File "C:\Users\Ivan\PycharmProjects\Django_geek_dz\.venv\Lib\site-packages\django\template\loader_tags.py", line 134, in render
    compiled_parent = self.get_parent(context)
                      ^^^^^^^^^^^^^^^^^^^^^^^^
  File "C:\Users\Ivan\PycharmProjects\Django_geek_dz\.venv\Lib\site-packages\django\template\loader_tags.py", line 131, in get_parent
    return self.find_template(parent, context)
           ^^^^^^^^^^^^^^^^^^^^^^^^^^^^^^^^^^^
  File "C:\Users\Ivan\PycharmProjects\Django_geek_dz\.venv\Lib\site-packages\django\template\loader_tags.py", line 109, in find_template
    template, origin = context.template.engine.find_template(
                       ^^^^^^^^^^^^^^^^^^^^^^^^^^^^^^^^^^^^^^
  File "C:\Users\Ivan\PycharmProjects\Django_geek_dz\.venv\Lib\site-packages\django\template\engine.py", line 163, in find_template
    raise TemplateDoesNotExist(name, tried=tried)
django.template.exceptions.TemplateDoesNotExist: myproject/base.html

The above exception was the direct cause of the following exception:

Traceback (most recent call last):
  File "C:\Users\Ivan\PycharmProjects\Django_geek_dz\.venv\Lib\site-packages\django\core\handlers\exception.py", line 55, in inner
    response = get_response(request)
               ^^^^^^^^^^^^^^^^^^^^^
  File "C:\Users\Ivan\PycharmProjects\Django_geek_dz\.venv\Lib\site-packages\django\core\handlers\base.py", line 197, in _get_response
    response = wrapped_callback(request, *callback_args, **callback_kwargs)
               ^^^^^^^^^^^^^^^^^^^^^^^^^^^^^^^^^^^^^^^^^^^^^^^^^^^^^^^^^^^^
  File "C:\Users\Ivan\PycharmProjects\Django_geek_dz\myproject\myapp\views.py", line 13, in index
    return render(request, "myapp/index.html", context)
           ^^^^^^^^^^^^^^^^^^^^^^^^^^^^^^^^^^^^^^^^^^^^
  File "C:\Users\Ivan\PycharmProjects\Django_geek_dz\.venv\Lib\site-packages\django\shortcuts.py", line 25, in render
    content = loader.render_to_string(template_name, context, request, using=using)
              ^^^^^^^^^^^^^^^^^^^^^^^^^^^^^^^^^^^^^^^^^^^^^^^^^^^^^^^^^^^^^^^^^^^^^
  File "C:\Users\Ivan\PycharmProjects\Django_geek_dz\.venv\Lib\site-packages\django\template\loader.py", line 62, in render_to_string
    return template.render(context, request)
           ^^^^^^^^^^^^^^^^^^^^^^^^^^^^^^^^^
  File "C:\Users\Ivan\PycharmProjects\Django_geek_dz\.venv\Lib\site-packages\django\template\backends\django.py", line 63, in render
    reraise(exc, self.backend)
  File "C:\Users\Ivan\PycharmProjects\Django_geek_dz\.venv\Lib\site-packages\django\template\backends\django.py", line 84, in reraise
    raise new from exc
django.template.exceptions.TemplateDoesNotExist: myproject/base.html
ERROR 2024-06-11 13:44:22,357 basehttp 19056 12276 "GET / HTTP/1.1" 500 128637
INFO 2024-06-11 13:44:23,662 views 19056 12276 посещение страницы about в: 2024-06-11 13:44:23.662928
INFO 2024-06-11 13:44:23,664 basehttp 19056 12276 "GET / HTTP/1.1" 200 742
INFO 2024-06-11 13:45:28,200 views 19056 12276 посещение страницы about в: 2024-06-11 13:45:28.200493
INFO 2024-06-11 13:45:28,201 basehttp 19056 12276 "GET /about/ HTTP/1.1" 200 1009
INFO 2024-06-11 13:45:36,081 views 19056 12276 посещение страницы about в: 2024-06-11 13:45:36.081707
INFO 2024-06-11 13:45:36,084 basehttp 19056 12276 "GET / HTTP/1.1" 200 742
INFO 2024-06-11 13:48:59,999 autoreload 9572 5568 C:\Users\Ivan\PycharmProjects\Django_geek_dz\myproject\myapp\views.py changed, reloading.
INFO 2024-06-11 13:49:00,008 autoreload 19056 13740 C:\Users\Ivan\PycharmProjects\Django_geek_dz\myproject\myapp\views.py changed, reloading.
INFO 2024-06-11 13:49:00,497 autoreload 8152 17448 Watching for file changes with StatReloader
INFO 2024-06-11 13:49:00,510 autoreload 3728 19156 Watching for file changes with StatReloader
INFO 2024-06-11 13:53:59,985 autoreload 8152 17448 C:\Users\Ivan\PycharmProjects\Django_geek_dz\myproject\myproject\settings.py changed, reloading.
INFO 2024-06-11 13:53:59,986 autoreload 3728 19156 C:\Users\Ivan\PycharmProjects\Django_geek_dz\myproject\myproject\settings.py changed, reloading.
INFO 2024-06-11 13:54:00,473 autoreload 16776 17188 Watching for file changes with StatReloader
INFO 2024-06-11 13:54:00,473 autoreload 15012 4496 Watching for file changes with StatReloader
INFO 2024-06-11 13:55:22,873 autoreload 15012 4496 C:\Users\Ivan\PycharmProjects\Django_geek_dz\myproject\myapp\models.py changed, reloading.
INFO 2024-06-11 13:55:22,878 autoreload 16776 17188 C:\Users\Ivan\PycharmProjects\Django_geek_dz\myproject\myapp\models.py changed, reloading.
INFO 2024-06-11 13:55:23,460 autoreload 17136 18828 Watching for file changes with StatReloader
INFO 2024-06-11 13:55:23,461 autoreload 7824 18832 Watching for file changes with StatReloader
INFO 2024-06-11 13:57:51,999 autoreload 17136 18828 C:\Users\Ivan\PycharmProjects\Django_geek_dz\myproject\myapp\models.py changed, reloading.
INFO 2024-06-11 13:57:52,015 autoreload 7824 18832 C:\Users\Ivan\PycharmProjects\Django_geek_dz\myproject\myapp\models.py changed, reloading.
INFO 2024-06-11 13:57:52,501 autoreload 7944 11868 Watching for file changes with StatReloader
INFO 2024-06-11 13:57:52,507 autoreload 19936 10528 Watching for file changes with StatReloader
INFO 2024-06-11 13:59:28,631 autoreload 7944 11868 C:\Users\Ivan\PycharmProjects\Django_geek_dz\myproject\myapp\views.py changed, reloading.
INFO 2024-06-11 13:59:28,634 autoreload 19936 10528 C:\Users\Ivan\PycharmProjects\Django_geek_dz\myproject\myapp\views.py changed, reloading.
INFO 2024-06-11 13:59:29,141 autoreload 14572 17528 Watching for file changes with StatReloader
INFO 2024-06-11 13:59:29,141 autoreload 18256 10352 Watching for file changes with StatReloader
INFO 2024-06-11 13:59:53,009 autoreload 14572 17528 C:\Users\Ivan\PycharmProjects\Django_geek_dz\myproject\myapp\views.py changed, reloading.
INFO 2024-06-11 13:59:53,012 autoreload 18256 10352 C:\Users\Ivan\PycharmProjects\Django_geek_dz\myproject\myapp\views.py changed, reloading.
INFO 2024-06-11 13:59:53,499 autoreload 16240 12084 Watching for file changes with StatReloader
INFO 2024-06-11 13:59:53,499 autoreload 13936 10524 Watching for file changes with StatReloader
INFO 2024-06-11 14:01:32,388 autoreload 13936 10524 C:\Users\Ivan\PycharmProjects\Django_geek_dz\myproject\myapp\views.py changed, reloading.
INFO 2024-06-11 14:01:32,393 autoreload 16240 12084 C:\Users\Ivan\PycharmProjects\Django_geek_dz\myproject\myapp\views.py changed, reloading.
INFO 2024-06-11 14:01:32,901 autoreload 17800 8088 Watching for file changes with StatReloader
INFO 2024-06-11 14:01:32,901 autoreload 18260 8952 Watching for file changes with StatReloader
INFO 2024-06-11 14:03:08,699 autoreload 17800 8088 C:\Users\Ivan\PycharmProjects\Django_geek_dz\myproject\myapp\views.py changed, reloading.
INFO 2024-06-11 14:03:08,701 autoreload 18260 8952 C:\Users\Ivan\PycharmProjects\Django_geek_dz\myproject\myapp\views.py changed, reloading.
INFO 2024-06-11 14:03:09,236 autoreload 9000 16232 Watching for file changes with StatReloader
INFO 2024-06-11 14:03:09,236 autoreload 13556 19336 Watching for file changes with StatReloader
INFO 2024-06-11 14:03:38,364 autoreload 13556 19336 C:\Users\Ivan\PycharmProjects\Django_geek_dz\myproject\myapp\views.py changed, reloading.
INFO 2024-06-11 14:03:38,373 autoreload 9000 16232 C:\Users\Ivan\PycharmProjects\Django_geek_dz\myproject\myapp\views.py changed, reloading.
INFO 2024-06-11 14:03:38,859 autoreload 17288 3216 Watching for file changes with StatReloader
INFO 2024-06-11 14:03:38,869 autoreload 16652 16724 Watching for file changes with StatReloader
INFO 2024-06-11 14:04:56,535 autoreload 17288 3216 C:\Users\Ivan\PycharmProjects\Django_geek_dz\myproject\myapp\views.py changed, reloading.
INFO 2024-06-11 14:04:56,546 autoreload 16652 16724 C:\Users\Ivan\PycharmProjects\Django_geek_dz\myproject\myapp\views.py changed, reloading.
INFO 2024-06-11 14:04:57,077 autoreload 12828 16676 Watching for file changes with StatReloader
INFO 2024-06-11 14:04:57,088 autoreload 13632 8932 Watching for file changes with StatReloader
INFO 2024-06-11 14:05:52,798 autoreload 13632 8932 C:\Users\Ivan\PycharmProjects\Django_geek_dz\myproject\myapp\urls.py changed, reloading.
INFO 2024-06-11 14:05:52,802 autoreload 12828 16676 C:\Users\Ivan\PycharmProjects\Django_geek_dz\myproject\myapp\urls.py changed, reloading.
INFO 2024-06-11 14:05:53,340 autoreload 13660 16392 Watching for file changes with StatReloader
INFO 2024-06-11 14:05:53,342 autoreload 10964 6156 Watching for file changes with StatReloader
INFO 2024-06-11 14:06:19,332 autoreload 13660 16392 C:\Users\Ivan\PycharmProjects\Django_geek_dz\myproject\myapp\urls.py changed, reloading.
INFO 2024-06-11 14:06:19,340 autoreload 10964 6156 C:\Users\Ivan\PycharmProjects\Django_geek_dz\myproject\myapp\urls.py changed, reloading.
INFO 2024-06-11 14:06:19,824 autoreload 19508 16480 Watching for file changes with StatReloader
INFO 2024-06-11 14:06:19,829 autoreload 10260 9972 Watching for file changes with StatReloader
INFO 2024-06-11 14:10:04,609 autoreload 10260 9972 C:\Users\Ivan\PycharmProjects\Django_geek_dz\myproject\myapp\views.py changed, reloading.
INFO 2024-06-11 14:10:04,613 autoreload 19508 16480 C:\Users\Ivan\PycharmProjects\Django_geek_dz\myproject\myapp\views.py changed, reloading.
INFO 2024-06-11 14:10:05,175 autoreload 20100 9088 Watching for file changes with StatReloader
INFO 2024-06-11 14:10:05,175 autoreload 8724 8204 Watching for file changes with StatReloader
INFO 2024-06-11 14:13:06,681 autoreload 1896 10816 Watching for file changes with StatReloader
INFO 2024-06-11 14:13:10,936 views 1896 4112 посещение страницы about в: 2024-06-11 14:13:10.936958
INFO 2024-06-11 14:13:10,942 basehttp 1896 4112 "GET / HTTP/1.1" 200 742
INFO 2024-06-11 14:13:52,224 autoreload 1896 10816 C:\Users\Ivan\PycharmProjects\Django_geek_dz\myproject\myapp\views.py changed, reloading.
INFO 2024-06-11 14:13:52,723 autoreload 7236 9568 Watching for file changes with StatReloader
INFO 2024-06-11 14:14:09,417 autoreload 7236 9568 C:\Users\Ivan\PycharmProjects\Django_geek_dz\myproject\myapp\urls.py changed, reloading.
INFO 2024-06-11 14:14:09,889 autoreload 2428 13548 Watching for file changes with StatReloader
INFO 2024-06-11 14:14:17,654 basehttp 2428 10500 "GET /product/1 HTTP/1.1" 301 0
ERROR 2024-06-11 14:14:17,728 log 2428 17888 Internal Server Error: /product/1/
Traceback (most recent call last):
  File "C:\Users\Ivan\PycharmProjects\Django_geek_dz\.venv\Lib\site-packages\django\core\handlers\exception.py", line 55, in inner
    response = get_response(request)
               ^^^^^^^^^^^^^^^^^^^^^
  File "C:\Users\Ivan\PycharmProjects\Django_geek_dz\.venv\Lib\site-packages\django\core\handlers\base.py", line 197, in _get_response
    response = wrapped_callback(request, *callback_args, **callback_kwargs)
               ^^^^^^^^^^^^^^^^^^^^^^^^^^^^^^^^^^^^^^^^^^^^^^^^^^^^^^^^^^^^
  File "C:\Users\Ivan\PycharmProjects\Django_geek_dz\myproject\myapp\views.py", line 24, in user_products
    product = User.objects.filter(user=user).order_by('-id')[:7]
              ^^^^^^^^^^^^^^^^^^^^^^^^^^^^^^
  File "C:\Users\Ivan\PycharmProjects\Django_geek_dz\.venv\Lib\site-packages\django\db\models\manager.py", line 87, in manager_method
    return getattr(self.get_queryset(), name)(*args, **kwargs)
           ^^^^^^^^^^^^^^^^^^^^^^^^^^^^^^^^^^^^^^^^^^^^^^^^^^^
  File "C:\Users\Ivan\PycharmProjects\Django_geek_dz\.venv\Lib\site-packages\django\db\models\query.py", line 1476, in filter
    return self._filter_or_exclude(False, args, kwargs)
           ^^^^^^^^^^^^^^^^^^^^^^^^^^^^^^^^^^^^^^^^^^^^
  File "C:\Users\Ivan\PycharmProjects\Django_geek_dz\.venv\Lib\site-packages\django\db\models\query.py", line 1494, in _filter_or_exclude
    clone._filter_or_exclude_inplace(negate, args, kwargs)
  File "C:\Users\Ivan\PycharmProjects\Django_geek_dz\.venv\Lib\site-packages\django\db\models\query.py", line 1501, in _filter_or_exclude_inplace
    self._query.add_q(Q(*args, **kwargs))
  File "C:\Users\Ivan\PycharmProjects\Django_geek_dz\.venv\Lib\site-packages\django\db\models\sql\query.py", line 1613, in add_q
    clause, _ = self._add_q(q_object, self.used_aliases)
                ^^^^^^^^^^^^^^^^^^^^^^^^^^^^^^^^^^^^^^^^
  File "C:\Users\Ivan\PycharmProjects\Django_geek_dz\.venv\Lib\site-packages\django\db\models\sql\query.py", line 1645, in _add_q
    child_clause, needed_inner = self.build_filter(
                                 ^^^^^^^^^^^^^^^^^^
  File "C:\Users\Ivan\PycharmProjects\Django_geek_dz\.venv\Lib\site-packages\django\db\models\sql\query.py", line 1495, in build_filter
    lookups, parts, reffed_expression = self.solve_lookup_type(arg, summarize)
                                        ^^^^^^^^^^^^^^^^^^^^^^^^^^^^^^^^^^^^^^
  File "C:\Users\Ivan\PycharmProjects\Django_geek_dz\.venv\Lib\site-packages\django\db\models\sql\query.py", line 1307, in solve_lookup_type
    _, field, _, lookup_parts = self.names_to_path(lookup_splitted, self.get_meta())
                                ^^^^^^^^^^^^^^^^^^^^^^^^^^^^^^^^^^^^^^^^^^^^^^^^^^^^
  File "C:\Users\Ivan\PycharmProjects\Django_geek_dz\.venv\Lib\site-packages\django\db\models\sql\query.py", line 1772, in names_to_path
    raise FieldError(
django.core.exceptions.FieldError: Cannot resolve keyword 'user' into field. Choices are: adress, date, email, id, name, order, phone
ERROR 2024-06-11 14:14:17,731 basehttp 2428 17888 "GET /product/1/ HTTP/1.1" 500 118729
ERROR 2024-06-11 14:16:27,831 log 2428 17888 Internal Server Error: /product/1/
Traceback (most recent call last):
  File "C:\Users\Ivan\PycharmProjects\Django_geek_dz\.venv\Lib\site-packages\django\core\handlers\exception.py", line 55, in inner
    response = get_response(request)
               ^^^^^^^^^^^^^^^^^^^^^
  File "C:\Users\Ivan\PycharmProjects\Django_geek_dz\.venv\Lib\site-packages\django\core\handlers\base.py", line 197, in _get_response
    response = wrapped_callback(request, *callback_args, **callback_kwargs)
               ^^^^^^^^^^^^^^^^^^^^^^^^^^^^^^^^^^^^^^^^^^^^^^^^^^^^^^^^^^^^
  File "C:\Users\Ivan\PycharmProjects\Django_geek_dz\myproject\myapp\views.py", line 24, in user_products
    product = User.objects.filter(user=user).order_by('-id')[:7]
              ^^^^^^^^^^^^^^^^^^^^^^^^^^^^^^
  File "C:\Users\Ivan\PycharmProjects\Django_geek_dz\.venv\Lib\site-packages\django\db\models\manager.py", line 87, in manager_method
    return getattr(self.get_queryset(), name)(*args, **kwargs)
           ^^^^^^^^^^^^^^^^^^^^^^^^^^^^^^^^^^^^^^^^^^^^^^^^^^^
  File "C:\Users\Ivan\PycharmProjects\Django_geek_dz\.venv\Lib\site-packages\django\db\models\query.py", line 1476, in filter
    return self._filter_or_exclude(False, args, kwargs)
           ^^^^^^^^^^^^^^^^^^^^^^^^^^^^^^^^^^^^^^^^^^^^
  File "C:\Users\Ivan\PycharmProjects\Django_geek_dz\.venv\Lib\site-packages\django\db\models\query.py", line 1494, in _filter_or_exclude
    clone._filter_or_exclude_inplace(negate, args, kwargs)
  File "C:\Users\Ivan\PycharmProjects\Django_geek_dz\.venv\Lib\site-packages\django\db\models\query.py", line 1501, in _filter_or_exclude_inplace
    self._query.add_q(Q(*args, **kwargs))
  File "C:\Users\Ivan\PycharmProjects\Django_geek_dz\.venv\Lib\site-packages\django\db\models\sql\query.py", line 1613, in add_q
    clause, _ = self._add_q(q_object, self.used_aliases)
                ^^^^^^^^^^^^^^^^^^^^^^^^^^^^^^^^^^^^^^^^
  File "C:\Users\Ivan\PycharmProjects\Django_geek_dz\.venv\Lib\site-packages\django\db\models\sql\query.py", line 1645, in _add_q
    child_clause, needed_inner = self.build_filter(
                                 ^^^^^^^^^^^^^^^^^^
  File "C:\Users\Ivan\PycharmProjects\Django_geek_dz\.venv\Lib\site-packages\django\db\models\sql\query.py", line 1495, in build_filter
    lookups, parts, reffed_expression = self.solve_lookup_type(arg, summarize)
                                        ^^^^^^^^^^^^^^^^^^^^^^^^^^^^^^^^^^^^^^
  File "C:\Users\Ivan\PycharmProjects\Django_geek_dz\.venv\Lib\site-packages\django\db\models\sql\query.py", line 1307, in solve_lookup_type
    _, field, _, lookup_parts = self.names_to_path(lookup_splitted, self.get_meta())
                                ^^^^^^^^^^^^^^^^^^^^^^^^^^^^^^^^^^^^^^^^^^^^^^^^^^^^
  File "C:\Users\Ivan\PycharmProjects\Django_geek_dz\.venv\Lib\site-packages\django\db\models\sql\query.py", line 1772, in names_to_path
    raise FieldError(
django.core.exceptions.FieldError: Cannot resolve keyword 'user' into field. Choices are: adress, date, email, id, name, order, phone
ERROR 2024-06-11 14:16:27,833 basehttp 2428 17888 "GET /product/1/ HTTP/1.1" 500 118866
INFO 2024-06-11 14:17:32,582 autoreload 2428 13548 C:\Users\Ivan\PycharmProjects\Django_geek_dz\myproject\myapp\views.py changed, reloading.
INFO 2024-06-11 14:17:33,067 autoreload 10932 14996 Watching for file changes with StatReloader
ERROR 2024-06-11 14:17:33,303 log 10932 2180 Internal Server Error: /product/1/
Traceback (most recent call last):
  File "C:\Users\Ivan\PycharmProjects\Django_geek_dz\.venv\Lib\site-packages\django\core\handlers\exception.py", line 55, in inner
    response = get_response(request)
               ^^^^^^^^^^^^^^^^^^^^^
  File "C:\Users\Ivan\PycharmProjects\Django_geek_dz\.venv\Lib\site-packages\django\core\handlers\base.py", line 197, in _get_response
    response = wrapped_callback(request, *callback_args, **callback_kwargs)
               ^^^^^^^^^^^^^^^^^^^^^^^^^^^^^^^^^^^^^^^^^^^^^^^^^^^^^^^^^^^^
  File "C:\Users\Ivan\PycharmProjects\Django_geek_dz\myproject\myapp\views.py", line 25, in user_products
    return render(request, 'myapp/user_products.html', {'user': user, 'product': product})
           ^^^^^^^^^^^^^^^^^^^^^^^^^^^^^^^^^^^^^^^^^^^^^^^^^^^^^^^^^^^^^^^^^^^^^^^^^^^^^^^
  File "C:\Users\Ivan\PycharmProjects\Django_geek_dz\.venv\Lib\site-packages\django\shortcuts.py", line 25, in render
    content = loader.render_to_string(template_name, context, request, using=using)
              ^^^^^^^^^^^^^^^^^^^^^^^^^^^^^^^^^^^^^^^^^^^^^^^^^^^^^^^^^^^^^^^^^^^^^
  File "C:\Users\Ivan\PycharmProjects\Django_geek_dz\.venv\Lib\site-packages\django\template\loader.py", line 61, in render_to_string
    template = get_template(template_name, using=using)
               ^^^^^^^^^^^^^^^^^^^^^^^^^^^^^^^^^^^^^^^^
  File "C:\Users\Ivan\PycharmProjects\Django_geek_dz\.venv\Lib\site-packages\django\template\loader.py", line 19, in get_template
    raise TemplateDoesNotExist(template_name, chain=chain)
django.template.exceptions.TemplateDoesNotExist: myapp/user_products.html
ERROR 2024-06-11 14:17:33,309 basehttp 10932 2180 "GET /product/1/ HTTP/1.1" 500 82110
ERROR 2024-06-11 14:17:53,876 log 10932 2180 Internal Server Error: /product/1/
Traceback (most recent call last):
  File "C:\Users\Ivan\PycharmProjects\Django_geek_dz\.venv\Lib\site-packages\django\core\handlers\exception.py", line 55, in inner
    response = get_response(request)
               ^^^^^^^^^^^^^^^^^^^^^
  File "C:\Users\Ivan\PycharmProjects\Django_geek_dz\.venv\Lib\site-packages\django\core\handlers\base.py", line 197, in _get_response
    response = wrapped_callback(request, *callback_args, **callback_kwargs)
               ^^^^^^^^^^^^^^^^^^^^^^^^^^^^^^^^^^^^^^^^^^^^^^^^^^^^^^^^^^^^
  File "C:\Users\Ivan\PycharmProjects\Django_geek_dz\myproject\myapp\views.py", line 25, in user_products
    return render(request, 'myapp/user_products.html', {'name': user, 'product': product})
           ^^^^^^^^^^^^^^^^^^^^^^^^^^^^^^^^^^^^^^^^^^^^^^^^^^^^^^^^^^^^^^^^^^^^^^^^^^^^^^^
  File "C:\Users\Ivan\PycharmProjects\Django_geek_dz\.venv\Lib\site-packages\django\shortcuts.py", line 25, in render
    content = loader.render_to_string(template_name, context, request, using=using)
              ^^^^^^^^^^^^^^^^^^^^^^^^^^^^^^^^^^^^^^^^^^^^^^^^^^^^^^^^^^^^^^^^^^^^^
  File "C:\Users\Ivan\PycharmProjects\Django_geek_dz\.venv\Lib\site-packages\django\template\loader.py", line 61, in render_to_string
    template = get_template(template_name, using=using)
               ^^^^^^^^^^^^^^^^^^^^^^^^^^^^^^^^^^^^^^^^
  File "C:\Users\Ivan\PycharmProjects\Django_geek_dz\.venv\Lib\site-packages\django\template\loader.py", line 19, in get_template
    raise TemplateDoesNotExist(template_name, chain=chain)
django.template.exceptions.TemplateDoesNotExist: myapp/user_products.html
ERROR 2024-06-11 14:17:53,879 basehttp 10932 2180 "GET /product/1/ HTTP/1.1" 500 82110
INFO 2024-06-11 14:17:53,886 autoreload 10932 14996 C:\Users\Ivan\PycharmProjects\Django_geek_dz\myproject\myapp\views.py changed, reloading.
INFO 2024-06-11 14:17:54,390 autoreload 17932 14916 Watching for file changes with StatReloader
ERROR 2024-06-11 14:17:58,671 log 17932 10816 Internal Server Error: /product/1/
Traceback (most recent call last):
  File "C:\Users\Ivan\PycharmProjects\Django_geek_dz\.venv\Lib\site-packages\django\core\handlers\exception.py", line 55, in inner
    response = get_response(request)
               ^^^^^^^^^^^^^^^^^^^^^
  File "C:\Users\Ivan\PycharmProjects\Django_geek_dz\.venv\Lib\site-packages\django\core\handlers\base.py", line 197, in _get_response
    response = wrapped_callback(request, *callback_args, **callback_kwargs)
               ^^^^^^^^^^^^^^^^^^^^^^^^^^^^^^^^^^^^^^^^^^^^^^^^^^^^^^^^^^^^
  File "C:\Users\Ivan\PycharmProjects\Django_geek_dz\myproject\myapp\views.py", line 25, in user_products
    return render(request, 'myapp/user_products.html', {'name': user, 'product': product})
           ^^^^^^^^^^^^^^^^^^^^^^^^^^^^^^^^^^^^^^^^^^^^^^^^^^^^^^^^^^^^^^^^^^^^^^^^^^^^^^^
  File "C:\Users\Ivan\PycharmProjects\Django_geek_dz\.venv\Lib\site-packages\django\shortcuts.py", line 25, in render
    content = loader.render_to_string(template_name, context, request, using=using)
              ^^^^^^^^^^^^^^^^^^^^^^^^^^^^^^^^^^^^^^^^^^^^^^^^^^^^^^^^^^^^^^^^^^^^^
  File "C:\Users\Ivan\PycharmProjects\Django_geek_dz\.venv\Lib\site-packages\django\template\loader.py", line 61, in render_to_string
    template = get_template(template_name, using=using)
               ^^^^^^^^^^^^^^^^^^^^^^^^^^^^^^^^^^^^^^^^
  File "C:\Users\Ivan\PycharmProjects\Django_geek_dz\.venv\Lib\site-packages\django\template\loader.py", line 19, in get_template
    raise TemplateDoesNotExist(template_name, chain=chain)
django.template.exceptions.TemplateDoesNotExist: myapp/user_products.html
ERROR 2024-06-11 14:17:58,674 basehttp 17932 10816 "GET /product/1/ HTTP/1.1" 500 82110
INFO 2024-06-11 14:19:26,151 autoreload 17932 14916 C:\Users\Ivan\PycharmProjects\Django_geek_dz\myproject\myapp\views.py changed, reloading.
INFO 2024-06-11 14:19:26,628 autoreload 7760 14356 Watching for file changes with StatReloader
INFO 2024-06-11 14:20:07,961 autoreload 7760 14356 C:\Users\Ivan\PycharmProjects\Django_geek_dz\myproject\myapp\views.py changed, reloading.
INFO 2024-06-11 14:20:08,462 autoreload 8220 8444 Watching for file changes with StatReloader
INFO 2024-06-11 14:20:22,068 autoreload 8220 8444 C:\Users\Ivan\PycharmProjects\Django_geek_dz\myproject\myapp\views.py changed, reloading.
INFO 2024-06-11 14:20:22,531 autoreload 6048 11964 Watching for file changes with StatReloader
ERROR 2024-06-11 14:20:23,735 log 6048 17780 Internal Server Error: /product/1/
Traceback (most recent call last):
  File "C:\Users\Ivan\PycharmProjects\Django_geek_dz\.venv\Lib\site-packages\django\core\handlers\exception.py", line 55, in inner
    response = get_response(request)
               ^^^^^^^^^^^^^^^^^^^^^
  File "C:\Users\Ivan\PycharmProjects\Django_geek_dz\.venv\Lib\site-packages\django\core\handlers\base.py", line 197, in _get_response
    response = wrapped_callback(request, *callback_args, **callback_kwargs)
               ^^^^^^^^^^^^^^^^^^^^^^^^^^^^^^^^^^^^^^^^^^^^^^^^^^^^^^^^^^^^
  File "C:\Users\Ivan\PycharmProjects\Django_geek_dz\myproject\myapp\views.py", line 24, in user_products
    product = Product.objects.filter(user=user).order_by('-id')[:7]
              ^^^^^^^^^^^^^^^^^^^^^^^^^^^^^^^^^
  File "C:\Users\Ivan\PycharmProjects\Django_geek_dz\.venv\Lib\site-packages\django\db\models\manager.py", line 87, in manager_method
    return getattr(self.get_queryset(), name)(*args, **kwargs)
           ^^^^^^^^^^^^^^^^^^^^^^^^^^^^^^^^^^^^^^^^^^^^^^^^^^^
  File "C:\Users\Ivan\PycharmProjects\Django_geek_dz\.venv\Lib\site-packages\django\db\models\query.py", line 1476, in filter
    return self._filter_or_exclude(False, args, kwargs)
           ^^^^^^^^^^^^^^^^^^^^^^^^^^^^^^^^^^^^^^^^^^^^
  File "C:\Users\Ivan\PycharmProjects\Django_geek_dz\.venv\Lib\site-packages\django\db\models\query.py", line 1494, in _filter_or_exclude
    clone._filter_or_exclude_inplace(negate, args, kwargs)
  File "C:\Users\Ivan\PycharmProjects\Django_geek_dz\.venv\Lib\site-packages\django\db\models\query.py", line 1501, in _filter_or_exclude_inplace
    self._query.add_q(Q(*args, **kwargs))
  File "C:\Users\Ivan\PycharmProjects\Django_geek_dz\.venv\Lib\site-packages\django\db\models\sql\query.py", line 1613, in add_q
    clause, _ = self._add_q(q_object, self.used_aliases)
                ^^^^^^^^^^^^^^^^^^^^^^^^^^^^^^^^^^^^^^^^
  File "C:\Users\Ivan\PycharmProjects\Django_geek_dz\.venv\Lib\site-packages\django\db\models\sql\query.py", line 1645, in _add_q
    child_clause, needed_inner = self.build_filter(
                                 ^^^^^^^^^^^^^^^^^^
  File "C:\Users\Ivan\PycharmProjects\Django_geek_dz\.venv\Lib\site-packages\django\db\models\sql\query.py", line 1495, in build_filter
    lookups, parts, reffed_expression = self.solve_lookup_type(arg, summarize)
                                        ^^^^^^^^^^^^^^^^^^^^^^^^^^^^^^^^^^^^^^
  File "C:\Users\Ivan\PycharmProjects\Django_geek_dz\.venv\Lib\site-packages\django\db\models\sql\query.py", line 1307, in solve_lookup_type
    _, field, _, lookup_parts = self.names_to_path(lookup_splitted, self.get_meta())
                                ^^^^^^^^^^^^^^^^^^^^^^^^^^^^^^^^^^^^^^^^^^^^^^^^^^^^
  File "C:\Users\Ivan\PycharmProjects\Django_geek_dz\.venv\Lib\site-packages\django\db\models\sql\query.py", line 1772, in names_to_path
    raise FieldError(
django.core.exceptions.FieldError: Cannot resolve keyword 'user' into field. Choices are: count, date, descriptions, id, name, order, price
ERROR 2024-06-11 14:20:23,738 basehttp 6048 17780 "GET /product/1/ HTTP/1.1" 500 114223
INFO 2024-06-11 14:23:43,152 autoreload 6048 11964 C:\Users\Ivan\PycharmProjects\Django_geek_dz\myproject\myapp\views.py changed, reloading.
INFO 2024-06-11 14:23:43,629 autoreload 13628 184 Watching for file changes with StatReloader
INFO 2024-06-11 14:24:43,427 autoreload 13628 184 C:\Users\Ivan\PycharmProjects\Django_geek_dz\myproject\myapp\views.py changed, reloading.
INFO 2024-06-11 14:24:43,893 autoreload 17136 15656 Watching for file changes with StatReloader
INFO 2024-06-11 14:24:54,436 autoreload 17136 15656 C:\Users\Ivan\PycharmProjects\Django_geek_dz\myproject\myapp\views.py changed, reloading.
INFO 2024-06-11 14:24:54,944 autoreload 15644 8164 Watching for file changes with StatReloader
ERROR 2024-06-11 14:24:55,651 log 15644 2384 Internal Server Error: /product/1/
Traceback (most recent call last):
  File "C:\Users\Ivan\PycharmProjects\Django_geek_dz\.venv\Lib\site-packages\django\core\handlers\exception.py", line 55, in inner
    response = get_response(request)
               ^^^^^^^^^^^^^^^^^^^^^
  File "C:\Users\Ivan\PycharmProjects\Django_geek_dz\.venv\Lib\site-packages\django\core\handlers\base.py", line 197, in _get_response
    response = wrapped_callback(request, *callback_args, **callback_kwargs)
               ^^^^^^^^^^^^^^^^^^^^^^^^^^^^^^^^^^^^^^^^^^^^^^^^^^^^^^^^^^^^
  File "C:\Users\Ivan\PycharmProjects\Django_geek_dz\myproject\myapp\views.py", line 25, in user_products
    return render(request, 'myapp/user_products.html', {'customer': customer, 'product': product})
           ^^^^^^^^^^^^^^^^^^^^^^^^^^^^^^^^^^^^^^^^^^^^^^^^^^^^^^^^^^^^^^^^^^^^^^^^^^^^^^^^^^^^^^^
  File "C:\Users\Ivan\PycharmProjects\Django_geek_dz\.venv\Lib\site-packages\django\shortcuts.py", line 25, in render
    content = loader.render_to_string(template_name, context, request, using=using)
              ^^^^^^^^^^^^^^^^^^^^^^^^^^^^^^^^^^^^^^^^^^^^^^^^^^^^^^^^^^^^^^^^^^^^^
  File "C:\Users\Ivan\PycharmProjects\Django_geek_dz\.venv\Lib\site-packages\django\template\loader.py", line 61, in render_to_string
    template = get_template(template_name, using=using)
               ^^^^^^^^^^^^^^^^^^^^^^^^^^^^^^^^^^^^^^^^
  File "C:\Users\Ivan\PycharmProjects\Django_geek_dz\.venv\Lib\site-packages\django\template\loader.py", line 19, in get_template
    raise TemplateDoesNotExist(template_name, chain=chain)
django.template.exceptions.TemplateDoesNotExist: myapp/user_products.html
ERROR 2024-06-11 14:24:55,654 basehttp 15644 2384 "GET /product/1/ HTTP/1.1" 500 82167
ERROR 2024-06-11 14:24:57,982 log 15644 2384 Internal Server Error: /product/1/
Traceback (most recent call last):
  File "C:\Users\Ivan\PycharmProjects\Django_geek_dz\.venv\Lib\site-packages\django\core\handlers\exception.py", line 55, in inner
    response = get_response(request)
               ^^^^^^^^^^^^^^^^^^^^^
  File "C:\Users\Ivan\PycharmProjects\Django_geek_dz\.venv\Lib\site-packages\django\core\handlers\base.py", line 197, in _get_response
    response = wrapped_callback(request, *callback_args, **callback_kwargs)
               ^^^^^^^^^^^^^^^^^^^^^^^^^^^^^^^^^^^^^^^^^^^^^^^^^^^^^^^^^^^^
  File "C:\Users\Ivan\PycharmProjects\Django_geek_dz\myproject\myapp\views.py", line 25, in user_products
    return render(request, 'myapp/user_products.html', {'customer': customer, 'product': product})
           ^^^^^^^^^^^^^^^^^^^^^^^^^^^^^^^^^^^^^^^^^^^^^^^^^^^^^^^^^^^^^^^^^^^^^^^^^^^^^^^^^^^^^^^
  File "C:\Users\Ivan\PycharmProjects\Django_geek_dz\.venv\Lib\site-packages\django\shortcuts.py", line 25, in render
    content = loader.render_to_string(template_name, context, request, using=using)
              ^^^^^^^^^^^^^^^^^^^^^^^^^^^^^^^^^^^^^^^^^^^^^^^^^^^^^^^^^^^^^^^^^^^^^
  File "C:\Users\Ivan\PycharmProjects\Django_geek_dz\.venv\Lib\site-packages\django\template\loader.py", line 61, in render_to_string
    template = get_template(template_name, using=using)
               ^^^^^^^^^^^^^^^^^^^^^^^^^^^^^^^^^^^^^^^^
  File "C:\Users\Ivan\PycharmProjects\Django_geek_dz\.venv\Lib\site-packages\django\template\loader.py", line 19, in get_template
    raise TemplateDoesNotExist(template_name, chain=chain)
django.template.exceptions.TemplateDoesNotExist: myapp/user_products.html
ERROR 2024-06-11 14:24:57,983 basehttp 15644 2384 "GET /product/1/ HTTP/1.1" 500 82167
INFO 2024-06-11 14:28:19,657 autoreload 9016 4460 Watching for file changes with StatReloader
ERROR 2024-06-11 14:28:30,651 log 9016 11708 Internal Server Error: /product/1/
Traceback (most recent call last):
  File "C:\Users\Ivan\PycharmProjects\Django_geek_dz\.venv\Lib\site-packages\django\core\handlers\exception.py", line 55, in inner
    response = get_response(request)
               ^^^^^^^^^^^^^^^^^^^^^
  File "C:\Users\Ivan\PycharmProjects\Django_geek_dz\.venv\Lib\site-packages\django\core\handlers\base.py", line 197, in _get_response
    response = wrapped_callback(request, *callback_args, **callback_kwargs)
               ^^^^^^^^^^^^^^^^^^^^^^^^^^^^^^^^^^^^^^^^^^^^^^^^^^^^^^^^^^^^
  File "C:\Users\Ivan\PycharmProjects\Django_geek_dz\myproject\myapp\views.py", line 25, in user_products
    return render(request, 'myapp/user_products.html', {'customer': customer, 'product': product})
           ^^^^^^^^^^^^^^^^^^^^^^^^^^^^^^^^^^^^^^^^^^^^^^^^^^^^^^^^^^^^^^^^^^^^^^^^^^^^^^^^^^^^^^^
  File "C:\Users\Ivan\PycharmProjects\Django_geek_dz\.venv\Lib\site-packages\django\shortcuts.py", line 25, in render
    content = loader.render_to_string(template_name, context, request, using=using)
              ^^^^^^^^^^^^^^^^^^^^^^^^^^^^^^^^^^^^^^^^^^^^^^^^^^^^^^^^^^^^^^^^^^^^^
  File "C:\Users\Ivan\PycharmProjects\Django_geek_dz\.venv\Lib\site-packages\django\template\loader.py", line 61, in render_to_string
    template = get_template(template_name, using=using)
               ^^^^^^^^^^^^^^^^^^^^^^^^^^^^^^^^^^^^^^^^
  File "C:\Users\Ivan\PycharmProjects\Django_geek_dz\.venv\Lib\site-packages\django\template\loader.py", line 19, in get_template
    raise TemplateDoesNotExist(template_name, chain=chain)
django.template.exceptions.TemplateDoesNotExist: myapp/user_products.html
ERROR 2024-06-11 14:28:30,653 basehttp 9016 11708 "GET /product/1/ HTTP/1.1" 500 82167
INFO 2024-06-11 14:29:39,094 autoreload 9016 4460 C:\Users\Ivan\PycharmProjects\Django_geek_dz\myproject\myapp\views.py changed, reloading.
INFO 2024-06-11 14:29:39,582 autoreload 17036 11800 Watching for file changes with StatReloader
ERROR 2024-06-11 14:29:43,234 log 17036 13504 Internal Server Error: /product/1/
Traceback (most recent call last):
  File "C:\Users\Ivan\PycharmProjects\Django_geek_dz\.venv\Lib\site-packages\django\core\handlers\exception.py", line 55, in inner
    response = get_response(request)
               ^^^^^^^^^^^^^^^^^^^^^
  File "C:\Users\Ivan\PycharmProjects\Django_geek_dz\.venv\Lib\site-packages\django\core\handlers\base.py", line 197, in _get_response
    response = wrapped_callback(request, *callback_args, **callback_kwargs)
               ^^^^^^^^^^^^^^^^^^^^^^^^^^^^^^^^^^^^^^^^^^^^^^^^^^^^^^^^^^^^
  File "C:\Users\Ivan\PycharmProjects\Django_geek_dz\myproject\myapp\views.py", line 25, in user_products
    return render(request, 'myapp/user_products.html', {'customer': customer, 'products': products})
           ^^^^^^^^^^^^^^^^^^^^^^^^^^^^^^^^^^^^^^^^^^^^^^^^^^^^^^^^^^^^^^^^^^^^^^^^^^^^^^^^^^^^^^^^^
  File "C:\Users\Ivan\PycharmProjects\Django_geek_dz\.venv\Lib\site-packages\django\shortcuts.py", line 25, in render
    content = loader.render_to_string(template_name, context, request, using=using)
              ^^^^^^^^^^^^^^^^^^^^^^^^^^^^^^^^^^^^^^^^^^^^^^^^^^^^^^^^^^^^^^^^^^^^^
  File "C:\Users\Ivan\PycharmProjects\Django_geek_dz\.venv\Lib\site-packages\django\template\loader.py", line 61, in render_to_string
    template = get_template(template_name, using=using)
               ^^^^^^^^^^^^^^^^^^^^^^^^^^^^^^^^^^^^^^^^
  File "C:\Users\Ivan\PycharmProjects\Django_geek_dz\.venv\Lib\site-packages\django\template\loader.py", line 19, in get_template
    raise TemplateDoesNotExist(template_name, chain=chain)
django.template.exceptions.TemplateDoesNotExist: myapp/user_products.html
ERROR 2024-06-11 14:29:43,235 basehttp 17036 13504 "GET /product/1/ HTTP/1.1" 500 82179
ERROR 2024-06-11 14:30:52,518 log 17036 13504 Internal Server Error: /product/1/
Traceback (most recent call last):
  File "C:\Users\Ivan\PycharmProjects\Django_geek_dz\.venv\Lib\site-packages\django\core\handlers\exception.py", line 55, in inner
    response = get_response(request)
               ^^^^^^^^^^^^^^^^^^^^^
  File "C:\Users\Ivan\PycharmProjects\Django_geek_dz\.venv\Lib\site-packages\django\core\handlers\base.py", line 197, in _get_response
    response = wrapped_callback(request, *callback_args, **callback_kwargs)
               ^^^^^^^^^^^^^^^^^^^^^^^^^^^^^^^^^^^^^^^^^^^^^^^^^^^^^^^^^^^^
  File "C:\Users\Ivan\PycharmProjects\Django_geek_dz\myproject\myapp\views.py", line 25, in user_products
    return render(request, 'myapp/user_products.html', {'customer': customer, 'products': products})
           ^^^^^^^^^^^^^^^^^^^^^^^^^^^^^^^^^^^^^^^^^^^^^^^^^^^^^^^^^^^^^^^^^^^^^^^^^^^^^^^^^^^^^^^^^
  File "C:\Users\Ivan\PycharmProjects\Django_geek_dz\.venv\Lib\site-packages\django\shortcuts.py", line 25, in render
    content = loader.render_to_string(template_name, context, request, using=using)
              ^^^^^^^^^^^^^^^^^^^^^^^^^^^^^^^^^^^^^^^^^^^^^^^^^^^^^^^^^^^^^^^^^^^^^
  File "C:\Users\Ivan\PycharmProjects\Django_geek_dz\.venv\Lib\site-packages\django\template\loader.py", line 61, in render_to_string
    template = get_template(template_name, using=using)
               ^^^^^^^^^^^^^^^^^^^^^^^^^^^^^^^^^^^^^^^^
  File "C:\Users\Ivan\PycharmProjects\Django_geek_dz\.venv\Lib\site-packages\django\template\loader.py", line 19, in get_template
    raise TemplateDoesNotExist(template_name, chain=chain)
django.template.exceptions.TemplateDoesNotExist: myapp/user_products.html
ERROR 2024-06-11 14:30:52,520 basehttp 17036 13504 "GET /product/1/ HTTP/1.1" 500 82179
ERROR 2024-06-11 14:30:58,785 log 17036 13504 Internal Server Error: /product/1/
Traceback (most recent call last):
  File "C:\Users\Ivan\PycharmProjects\Django_geek_dz\.venv\Lib\site-packages\django\core\handlers\exception.py", line 55, in inner
    response = get_response(request)
               ^^^^^^^^^^^^^^^^^^^^^
  File "C:\Users\Ivan\PycharmProjects\Django_geek_dz\.venv\Lib\site-packages\django\core\handlers\base.py", line 197, in _get_response
    response = wrapped_callback(request, *callback_args, **callback_kwargs)
               ^^^^^^^^^^^^^^^^^^^^^^^^^^^^^^^^^^^^^^^^^^^^^^^^^^^^^^^^^^^^
  File "C:\Users\Ivan\PycharmProjects\Django_geek_dz\myproject\myapp\views.py", line 25, in user_products
    return render(request, 'myapp/user_products.html', {'customer': customer, 'products': products})
           ^^^^^^^^^^^^^^^^^^^^^^^^^^^^^^^^^^^^^^^^^^^^^^^^^^^^^^^^^^^^^^^^^^^^^^^^^^^^^^^^^^^^^^^^^
  File "C:\Users\Ivan\PycharmProjects\Django_geek_dz\.venv\Lib\site-packages\django\shortcuts.py", line 25, in render
    content = loader.render_to_string(template_name, context, request, using=using)
              ^^^^^^^^^^^^^^^^^^^^^^^^^^^^^^^^^^^^^^^^^^^^^^^^^^^^^^^^^^^^^^^^^^^^^
  File "C:\Users\Ivan\PycharmProjects\Django_geek_dz\.venv\Lib\site-packages\django\template\loader.py", line 61, in render_to_string
    template = get_template(template_name, using=using)
               ^^^^^^^^^^^^^^^^^^^^^^^^^^^^^^^^^^^^^^^^
  File "C:\Users\Ivan\PycharmProjects\Django_geek_dz\.venv\Lib\site-packages\django\template\loader.py", line 19, in get_template
    raise TemplateDoesNotExist(template_name, chain=chain)
django.template.exceptions.TemplateDoesNotExist: myapp/user_products.html
ERROR 2024-06-11 14:30:58,786 basehttp 17036 13504 "GET /product/1/ HTTP/1.1" 500 82179
ERROR 2024-06-11 14:30:59,417 log 17036 13504 Internal Server Error: /product/1/
Traceback (most recent call last):
  File "C:\Users\Ivan\PycharmProjects\Django_geek_dz\.venv\Lib\site-packages\django\core\handlers\exception.py", line 55, in inner
    response = get_response(request)
               ^^^^^^^^^^^^^^^^^^^^^
  File "C:\Users\Ivan\PycharmProjects\Django_geek_dz\.venv\Lib\site-packages\django\core\handlers\base.py", line 197, in _get_response
    response = wrapped_callback(request, *callback_args, **callback_kwargs)
               ^^^^^^^^^^^^^^^^^^^^^^^^^^^^^^^^^^^^^^^^^^^^^^^^^^^^^^^^^^^^
  File "C:\Users\Ivan\PycharmProjects\Django_geek_dz\myproject\myapp\views.py", line 25, in user_products
    return render(request, 'myapp/user_products.html', {'customer': customer, 'products': products})
           ^^^^^^^^^^^^^^^^^^^^^^^^^^^^^^^^^^^^^^^^^^^^^^^^^^^^^^^^^^^^^^^^^^^^^^^^^^^^^^^^^^^^^^^^^
  File "C:\Users\Ivan\PycharmProjects\Django_geek_dz\.venv\Lib\site-packages\django\shortcuts.py", line 25, in render
    content = loader.render_to_string(template_name, context, request, using=using)
              ^^^^^^^^^^^^^^^^^^^^^^^^^^^^^^^^^^^^^^^^^^^^^^^^^^^^^^^^^^^^^^^^^^^^^
  File "C:\Users\Ivan\PycharmProjects\Django_geek_dz\.venv\Lib\site-packages\django\template\loader.py", line 61, in render_to_string
    template = get_template(template_name, using=using)
               ^^^^^^^^^^^^^^^^^^^^^^^^^^^^^^^^^^^^^^^^
  File "C:\Users\Ivan\PycharmProjects\Django_geek_dz\.venv\Lib\site-packages\django\template\loader.py", line 19, in get_template
    raise TemplateDoesNotExist(template_name, chain=chain)
django.template.exceptions.TemplateDoesNotExist: myapp/user_products.html
ERROR 2024-06-11 14:30:59,418 basehttp 17036 13504 "GET /product/1/ HTTP/1.1" 500 82179
INFO 2024-06-11 14:31:14,241 autoreload 19832 15100 Watching for file changes with StatReloader
ERROR 2024-06-11 14:31:17,138 log 19832 3208 Internal Server Error: /product/1/
Traceback (most recent call last):
  File "C:\Users\Ivan\PycharmProjects\Django_geek_dz\.venv\Lib\site-packages\django\core\handlers\exception.py", line 55, in inner
    response = get_response(request)
               ^^^^^^^^^^^^^^^^^^^^^
  File "C:\Users\Ivan\PycharmProjects\Django_geek_dz\.venv\Lib\site-packages\django\core\handlers\base.py", line 197, in _get_response
    response = wrapped_callback(request, *callback_args, **callback_kwargs)
               ^^^^^^^^^^^^^^^^^^^^^^^^^^^^^^^^^^^^^^^^^^^^^^^^^^^^^^^^^^^^
  File "C:\Users\Ivan\PycharmProjects\Django_geek_dz\myproject\myapp\views.py", line 25, in user_products
    return render(request, 'myapp/user_products.html', {'customer': customer, 'products': products})
           ^^^^^^^^^^^^^^^^^^^^^^^^^^^^^^^^^^^^^^^^^^^^^^^^^^^^^^^^^^^^^^^^^^^^^^^^^^^^^^^^^^^^^^^^^
  File "C:\Users\Ivan\PycharmProjects\Django_geek_dz\.venv\Lib\site-packages\django\shortcuts.py", line 25, in render
    content = loader.render_to_string(template_name, context, request, using=using)
              ^^^^^^^^^^^^^^^^^^^^^^^^^^^^^^^^^^^^^^^^^^^^^^^^^^^^^^^^^^^^^^^^^^^^^
  File "C:\Users\Ivan\PycharmProjects\Django_geek_dz\.venv\Lib\site-packages\django\template\loader.py", line 61, in render_to_string
    template = get_template(template_name, using=using)
               ^^^^^^^^^^^^^^^^^^^^^^^^^^^^^^^^^^^^^^^^
  File "C:\Users\Ivan\PycharmProjects\Django_geek_dz\.venv\Lib\site-packages\django\template\loader.py", line 19, in get_template
    raise TemplateDoesNotExist(template_name, chain=chain)
django.template.exceptions.TemplateDoesNotExist: myapp/user_products.html
ERROR 2024-06-11 14:31:17,140 basehttp 19832 3208 "GET /product/1/ HTTP/1.1" 500 82179
INFO 2024-06-11 14:53:26,751 autoreload 19832 15100 C:\Users\Ivan\PycharmProjects\Django_geek_dz\myproject\myapp\models.py changed, reloading.
INFO 2024-06-11 14:53:27,237 autoreload 12724 14704 Watching for file changes with StatReloader
INFO 2024-06-11 14:54:57,795 autoreload 12724 14704 C:\Users\Ivan\PycharmProjects\Django_geek_dz\myproject\myapp\models.py changed, reloading.
INFO 2024-06-11 14:54:58,273 autoreload 912 9624 Watching for file changes with StatReloader
INFO 2024-06-11 14:55:18,028 autoreload 912 9624 C:\Users\Ivan\PycharmProjects\Django_geek_dz\myproject\myapp\models.py changed, reloading.
INFO 2024-06-11 14:55:18,497 autoreload 10356 19556 Watching for file changes with StatReloader
INFO 2024-06-11 14:56:07,011 autoreload 10356 19556 C:\Users\Ivan\PycharmProjects\Django_geek_dz\myproject\myapp\models.py changed, reloading.
INFO 2024-06-11 14:56:07,466 autoreload 19860 5716 Watching for file changes with StatReloader
INFO 2024-06-11 14:56:26,188 autoreload 19860 5716 C:\Users\Ivan\PycharmProjects\Django_geek_dz\myproject\myapp\models.py changed, reloading.
INFO 2024-06-11 14:56:26,665 autoreload 836 11144 Watching for file changes with StatReloader
INFO 2024-06-11 15:25:33,903 autoreload 836 11144 C:\Users\Ivan\PycharmProjects\Django_geek_dz\myproject\myapp\models.py changed, reloading.
INFO 2024-06-11 15:25:34,373 autoreload 7548 8836 Watching for file changes with StatReloader
INFO 2024-06-11 15:26:22,462 autoreload 15028 19144 Watching for file changes with StatReloader
ERROR 2024-06-11 15:26:25,443 log 15028 692 Internal Server Error: /product/1/
Traceback (most recent call last):
  File "C:\Users\Ivan\PycharmProjects\Django_geek_dz\.venv\Lib\site-packages\django\core\handlers\exception.py", line 55, in inner
    response = get_response(request)
               ^^^^^^^^^^^^^^^^^^^^^
  File "C:\Users\Ivan\PycharmProjects\Django_geek_dz\.venv\Lib\site-packages\django\core\handlers\base.py", line 197, in _get_response
    response = wrapped_callback(request, *callback_args, **callback_kwargs)
               ^^^^^^^^^^^^^^^^^^^^^^^^^^^^^^^^^^^^^^^^^^^^^^^^^^^^^^^^^^^^
  File "C:\Users\Ivan\PycharmProjects\Django_geek_dz\myproject\myapp\views.py", line 25, in user_products
    return render(request, 'myapp/user_products.html', {'customer': customer, 'products': products})
           ^^^^^^^^^^^^^^^^^^^^^^^^^^^^^^^^^^^^^^^^^^^^^^^^^^^^^^^^^^^^^^^^^^^^^^^^^^^^^^^^^^^^^^^^^
  File "C:\Users\Ivan\PycharmProjects\Django_geek_dz\.venv\Lib\site-packages\django\shortcuts.py", line 25, in render
    content = loader.render_to_string(template_name, context, request, using=using)
              ^^^^^^^^^^^^^^^^^^^^^^^^^^^^^^^^^^^^^^^^^^^^^^^^^^^^^^^^^^^^^^^^^^^^^
  File "C:\Users\Ivan\PycharmProjects\Django_geek_dz\.venv\Lib\site-packages\django\template\loader.py", line 61, in render_to_string
    template = get_template(template_name, using=using)
               ^^^^^^^^^^^^^^^^^^^^^^^^^^^^^^^^^^^^^^^^
  File "C:\Users\Ivan\PycharmProjects\Django_geek_dz\.venv\Lib\site-packages\django\template\loader.py", line 19, in get_template
    raise TemplateDoesNotExist(template_name, chain=chain)
django.template.exceptions.TemplateDoesNotExist: myapp/user_products.html
ERROR 2024-06-11 15:26:25,445 basehttp 15028 692 "GET /product/1/ HTTP/1.1" 500 82179
INFO 2024-06-11 15:28:37,410 autoreload 15028 19144 C:\Users\Ivan\PycharmProjects\Django_geek_dz\myproject\myapp\views.py changed, reloading.
INFO 2024-06-11 15:28:37,893 autoreload 2492 6468 Watching for file changes with StatReloader
INFO 2024-06-11 15:28:56,635 autoreload 2492 6468 C:\Users\Ivan\PycharmProjects\Django_geek_dz\myproject\myapp\views.py changed, reloading.
INFO 2024-06-11 15:28:57,115 autoreload 16632 17476 Watching for file changes with StatReloader
INFO 2024-06-11 15:29:33,301 autoreload 16632 17476 C:\Users\Ivan\PycharmProjects\Django_geek_dz\myproject\myapp\views.py changed, reloading.
INFO 2024-06-11 15:29:33,763 autoreload 11496 3292 Watching for file changes with StatReloader
INFO 2024-06-11 15:30:24,331 autoreload 11496 3292 C:\Users\Ivan\PycharmProjects\Django_geek_dz\myproject\myapp\views.py changed, reloading.
INFO 2024-06-11 15:30:24,780 autoreload 11200 6048 Watching for file changes with StatReloader
INFO 2024-06-11 15:31:03,022 autoreload 11200 6048 C:\Users\Ivan\PycharmProjects\Django_geek_dz\myproject\myapp\views.py changed, reloading.
INFO 2024-06-11 15:31:03,474 autoreload 17840 9248 Watching for file changes with StatReloader
INFO 2024-06-11 15:32:07,374 autoreload 17840 9248 C:\Users\Ivan\PycharmProjects\Django_geek_dz\myproject\myapp\views.py changed, reloading.
INFO 2024-06-11 15:32:07,861 autoreload 3212 16836 Watching for file changes with StatReloader
INFO 2024-06-11 15:32:52,242 autoreload 3212 16836 C:\Users\Ivan\PycharmProjects\Django_geek_dz\myproject\myapp\views.py changed, reloading.
INFO 2024-06-11 15:32:52,782 autoreload 14548 4568 Watching for file changes with StatReloader
INFO 2024-06-11 15:33:09,477 autoreload 14548 4568 C:\Users\Ivan\PycharmProjects\Django_geek_dz\myproject\myapp\views.py changed, reloading.
INFO 2024-06-11 15:33:09,968 autoreload 16020 8132 Watching for file changes with StatReloader
ERROR 2024-06-11 15:33:10,130 log 16020 10596 Internal Server Error: /product/1/
Traceback (most recent call last):
  File "C:\Users\Ivan\PycharmProjects\Django_geek_dz\.venv\Lib\site-packages\django\core\handlers\exception.py", line 55, in inner
    response = get_response(request)
               ^^^^^^^^^^^^^^^^^^^^^
  File "C:\Users\Ivan\PycharmProjects\Django_geek_dz\.venv\Lib\site-packages\django\core\handlers\base.py", line 197, in _get_response
    response = wrapped_callback(request, *callback_args, **callback_kwargs)
               ^^^^^^^^^^^^^^^^^^^^^^^^^^^^^^^^^^^^^^^^^^^^^^^^^^^^^^^^^^^^
TypeError: user_products() got an unexpected keyword argument 'user_id'
ERROR 2024-06-11 15:33:10,131 basehttp 16020 10596 "GET /product/1/ HTTP/1.1" 500 62758
WARNING 2024-06-11 15:33:14,402 log 16020 10596 Not Found: /product/1/2
WARNING 2024-06-11 15:33:14,403 basehttp 16020 10596 "GET /product/1/2 HTTP/1.1" 404 2638
INFO 2024-06-11 15:34:42,687 autoreload 16020 8132 C:\Users\Ivan\PycharmProjects\Django_geek_dz\myproject\myapp\urls.py changed, reloading.
INFO 2024-06-11 15:34:43,198 autoreload 8088 19908 Watching for file changes with StatReloader
WARNING 2024-06-11 15:35:22,228 log 8088 6208 Not Found: /product/1/2
WARNING 2024-06-11 15:35:22,229 basehttp 8088 6208 "GET /product/1/2 HTTP/1.1" 404 2673
WARNING 2024-06-11 15:35:23,204 log 8088 6208 Not Found: /product/1/2
WARNING 2024-06-11 15:35:23,205 basehttp 8088 6208 "GET /product/1/2 HTTP/1.1" 404 2673
WARNING 2024-06-11 15:35:33,615 log 8088 6208 Not Found: /products/1/2
WARNING 2024-06-11 15:35:33,615 basehttp 8088 6208 "GET /products/1/2 HTTP/1.1" 404 2676
WARNING 2024-06-11 15:35:39,908 log 8088 6208 Not Found: /products/1/40
WARNING 2024-06-11 15:35:39,908 basehttp 8088 6208 "GET /products/1/40 HTTP/1.1" 404 2679
WARNING 2024-06-11 15:35:42,548 log 8088 6208 Not Found: /products/1
WARNING 2024-06-11 15:35:42,549 basehttp 8088 6208 "GET /products/1 HTTP/1.1" 404 2670
ERROR 2024-06-11 15:35:59,629 log 8088 6208 Internal Server Error: /clients/products/1/2
Traceback (most recent call last):
  File "C:\Users\Ivan\PycharmProjects\Django_geek_dz\.venv\Lib\site-packages\django\core\handlers\exception.py", line 55, in inner
    response = get_response(request)
               ^^^^^^^^^^^^^^^^^^^^^
  File "C:\Users\Ivan\PycharmProjects\Django_geek_dz\.venv\Lib\site-packages\django\core\handlers\base.py", line 197, in _get_response
    response = wrapped_callback(request, *callback_args, **callback_kwargs)
               ^^^^^^^^^^^^^^^^^^^^^^^^^^^^^^^^^^^^^^^^^^^^^^^^^^^^^^^^^^^^
TypeError: user_products() got an unexpected keyword argument 'client_id'
ERROR 2024-06-11 15:35:59,630 basehttp 8088 6208 "GET /clients/products/1/2 HTTP/1.1" 500 62750
INFO 2024-06-11 15:38:02,936 autoreload 8088 19908 C:\Users\Ivan\PycharmProjects\Django_geek_dz\myproject\myapp\views.py changed, reloading.
INFO 2024-06-11 15:38:03,429 autoreload 6516 20268 Watching for file changes with StatReloader
ERROR 2024-06-11 15:38:03,775 log 6516 7588 Internal Server Error: /clients/products/1/2
Traceback (most recent call last):
  File "C:\Users\Ivan\PycharmProjects\Django_geek_dz\.venv\Lib\site-packages\django\core\handlers\exception.py", line 55, in inner
    response = get_response(request)
               ^^^^^^^^^^^^^^^^^^^^^
  File "C:\Users\Ivan\PycharmProjects\Django_geek_dz\.venv\Lib\site-packages\django\core\handlers\base.py", line 197, in _get_response
    response = wrapped_callback(request, *callback_args, **callback_kwargs)
               ^^^^^^^^^^^^^^^^^^^^^^^^^^^^^^^^^^^^^^^^^^^^^^^^^^^^^^^^^^^^
TypeError: user_products() got an unexpected keyword argument 'client_id'
ERROR 2024-06-11 15:38:03,776 basehttp 6516 7588 "GET /clients/products/1/2 HTTP/1.1" 500 62887
ERROR 2024-06-11 15:38:04,633 log 6516 7588 Internal Server Error: /clients/products/1/2
Traceback (most recent call last):
  File "C:\Users\Ivan\PycharmProjects\Django_geek_dz\.venv\Lib\site-packages\django\core\handlers\exception.py", line 55, in inner
    response = get_response(request)
               ^^^^^^^^^^^^^^^^^^^^^
  File "C:\Users\Ivan\PycharmProjects\Django_geek_dz\.venv\Lib\site-packages\django\core\handlers\base.py", line 197, in _get_response
    response = wrapped_callback(request, *callback_args, **callback_kwargs)
               ^^^^^^^^^^^^^^^^^^^^^^^^^^^^^^^^^^^^^^^^^^^^^^^^^^^^^^^^^^^^
TypeError: user_products() got an unexpected keyword argument 'client_id'
ERROR 2024-06-11 15:38:04,635 basehttp 6516 7588 "GET /clients/products/1/2 HTTP/1.1" 500 62887
ERROR 2024-06-11 15:38:05,410 log 6516 7588 Internal Server Error: /clients/products/1/2
Traceback (most recent call last):
  File "C:\Users\Ivan\PycharmProjects\Django_geek_dz\.venv\Lib\site-packages\django\core\handlers\exception.py", line 55, in inner
    response = get_response(request)
               ^^^^^^^^^^^^^^^^^^^^^
  File "C:\Users\Ivan\PycharmProjects\Django_geek_dz\.venv\Lib\site-packages\django\core\handlers\base.py", line 197, in _get_response
    response = wrapped_callback(request, *callback_args, **callback_kwargs)
               ^^^^^^^^^^^^^^^^^^^^^^^^^^^^^^^^^^^^^^^^^^^^^^^^^^^^^^^^^^^^
TypeError: user_products() got an unexpected keyword argument 'client_id'
ERROR 2024-06-11 15:38:05,411 basehttp 6516 7588 "GET /clients/products/1/2 HTTP/1.1" 500 62887
ERROR 2024-06-11 15:38:06,388 log 6516 7588 Internal Server Error: /clients/products/1/2
Traceback (most recent call last):
  File "C:\Users\Ivan\PycharmProjects\Django_geek_dz\.venv\Lib\site-packages\django\core\handlers\exception.py", line 55, in inner
    response = get_response(request)
               ^^^^^^^^^^^^^^^^^^^^^
  File "C:\Users\Ivan\PycharmProjects\Django_geek_dz\.venv\Lib\site-packages\django\core\handlers\base.py", line 197, in _get_response
    response = wrapped_callback(request, *callback_args, **callback_kwargs)
               ^^^^^^^^^^^^^^^^^^^^^^^^^^^^^^^^^^^^^^^^^^^^^^^^^^^^^^^^^^^^
TypeError: user_products() got an unexpected keyword argument 'client_id'
ERROR 2024-06-11 15:38:06,390 basehttp 6516 7588 "GET /clients/products/1/2 HTTP/1.1" 500 62887
INFO 2024-06-11 15:39:24,839 autoreload 6516 20268 C:\Users\Ivan\PycharmProjects\Django_geek_dz\myproject\myapp\views.py changed, reloading.
INFO 2024-06-11 15:39:25,325 autoreload 11200 18216 Watching for file changes with StatReloader
INFO 2024-06-11 15:39:33,602 autoreload 9988 18024 Watching for file changes with StatReloader
ERROR 2024-06-11 15:39:36,040 log 9988 17840 Internal Server Error: /clients/products/1/2
Traceback (most recent call last):
  File "C:\Users\Ivan\PycharmProjects\Django_geek_dz\.venv\Lib\site-packages\django\core\handlers\exception.py", line 55, in inner
    response = get_response(request)
               ^^^^^^^^^^^^^^^^^^^^^
  File "C:\Users\Ivan\PycharmProjects\Django_geek_dz\.venv\Lib\site-packages\django\core\handlers\base.py", line 197, in _get_response
    response = wrapped_callback(request, *callback_args, **callback_kwargs)
               ^^^^^^^^^^^^^^^^^^^^^^^^^^^^^^^^^^^^^^^^^^^^^^^^^^^^^^^^^^^^
TypeError: user_products() got an unexpected keyword argument 'client_id'
ERROR 2024-06-11 15:39:36,041 basehttp 9988 17840 "GET /clients/products/1/2 HTTP/1.1" 500 62887
INFO 2024-06-11 15:40:23,245 autoreload 9988 18024 C:\Users\Ivan\PycharmProjects\Django_geek_dz\myproject\myapp\urls.py changed, reloading.
INFO 2024-06-11 15:40:23,748 autoreload 15520 3744 Watching for file changes with StatReloader
ERROR 2024-06-11 15:40:24,025 log 15520 9864 Internal Server Error: /clients/products/1/2
Traceback (most recent call last):
  File "C:\Users\Ivan\PycharmProjects\Django_geek_dz\.venv\Lib\site-packages\django\core\handlers\exception.py", line 55, in inner
    response = get_response(request)
               ^^^^^^^^^^^^^^^^^^^^^
  File "C:\Users\Ivan\PycharmProjects\Django_geek_dz\.venv\Lib\site-packages\django\core\handlers\base.py", line 197, in _get_response
    response = wrapped_callback(request, *callback_args, **callback_kwargs)
               ^^^^^^^^^^^^^^^^^^^^^^^^^^^^^^^^^^^^^^^^^^^^^^^^^^^^^^^^^^^^
  File "C:\Users\Ivan\PycharmProjects\Django_geek_dz\myproject\myapp\views.py", line 26, in user_products
    products = OrderProducts.objects.select_related('product').select_related('orders').filter(
               ^^^^^^^^^^^^^^^^^^^^^^^^^^^^^^^^^^^^^^^^^^^^^^^^^^^^^^^^^^^^^^^^^^^^^^^^^^^^^^^^
  File "C:\Users\Ivan\PycharmProjects\Django_geek_dz\.venv\Lib\site-packages\django\db\models\query.py", line 1476, in filter
    return self._filter_or_exclude(False, args, kwargs)
           ^^^^^^^^^^^^^^^^^^^^^^^^^^^^^^^^^^^^^^^^^^^^
  File "C:\Users\Ivan\PycharmProjects\Django_geek_dz\.venv\Lib\site-packages\django\db\models\query.py", line 1494, in _filter_or_exclude
    clone._filter_or_exclude_inplace(negate, args, kwargs)
  File "C:\Users\Ivan\PycharmProjects\Django_geek_dz\.venv\Lib\site-packages\django\db\models\query.py", line 1501, in _filter_or_exclude_inplace
    self._query.add_q(Q(*args, **kwargs))
  File "C:\Users\Ivan\PycharmProjects\Django_geek_dz\.venv\Lib\site-packages\django\db\models\sql\query.py", line 1613, in add_q
    clause, _ = self._add_q(q_object, self.used_aliases)
                ^^^^^^^^^^^^^^^^^^^^^^^^^^^^^^^^^^^^^^^^
  File "C:\Users\Ivan\PycharmProjects\Django_geek_dz\.venv\Lib\site-packages\django\db\models\sql\query.py", line 1645, in _add_q
    child_clause, needed_inner = self.build_filter(
                                 ^^^^^^^^^^^^^^^^^^
  File "C:\Users\Ivan\PycharmProjects\Django_geek_dz\.venv\Lib\site-packages\django\db\models\sql\query.py", line 1559, in build_filter
    condition = self.build_lookup(lookups, col, value)
                ^^^^^^^^^^^^^^^^^^^^^^^^^^^^^^^^^^^^^^
  File "C:\Users\Ivan\PycharmProjects\Django_geek_dz\.venv\Lib\site-packages\django\db\models\sql\query.py", line 1376, in build_lookup
    lhs = self.try_transform(lhs, name)
          ^^^^^^^^^^^^^^^^^^^^^^^^^^^^^
  File "C:\Users\Ivan\PycharmProjects\Django_geek_dz\.venv\Lib\site-packages\django\db\models\sql\query.py", line 1427, in try_transform
    raise FieldError(
django.core.exceptions.FieldError: Unsupported lookup 'order_date' for ForeignKey or join on the field not permitted.
ERROR 2024-06-11 15:40:24,028 basehttp 15520 9864 "GET /clients/products/1/2 HTTP/1.1" 500 111226
INFO 2024-06-11 15:42:14,920 autoreload 15520 3744 C:\Users\Ivan\PycharmProjects\Django_geek_dz\myproject\myapp\views.py changed, reloading.
INFO 2024-06-11 15:42:15,394 autoreload 11688 15580 Watching for file changes with StatReloader
ERROR 2024-06-11 15:42:17,975 log 11688 8976 Internal Server Error: /clients/products/1/2
Traceback (most recent call last):
  File "C:\Users\Ivan\PycharmProjects\Django_geek_dz\.venv\Lib\site-packages\django\db\models\sql\query.py", line 1890, in transform
    return self.try_transform(wrapped, name)
           ^^^^^^^^^^^^^^^^^^^^^^^^^^^^^^^^^
  File "C:\Users\Ivan\PycharmProjects\Django_geek_dz\.venv\Lib\site-packages\django\db\models\sql\query.py", line 1427, in try_transform
    raise FieldError(
django.core.exceptions.FieldError: Unsupported lookup 'prod_name' for BigAutoField or join on the field not permitted.

During handling of the above exception, another exception occurred:

Traceback (most recent call last):
  File "C:\Users\Ivan\PycharmProjects\Django_geek_dz\.venv\Lib\site-packages\django\core\handlers\exception.py", line 55, in inner
    response = get_response(request)
               ^^^^^^^^^^^^^^^^^^^^^
  File "C:\Users\Ivan\PycharmProjects\Django_geek_dz\.venv\Lib\site-packages\django\core\handlers\base.py", line 197, in _get_response
    response = wrapped_callback(request, *callback_args, **callback_kwargs)
               ^^^^^^^^^^^^^^^^^^^^^^^^^^^^^^^^^^^^^^^^^^^^^^^^^^^^^^^^^^^^
  File "C:\Users\Ivan\PycharmProjects\Django_geek_dz\myproject\myapp\views.py", line 28, in user_products
    products = products.values('product__prod_name', 'product__price').annotate(count_prod=Sum('product_count'))
               ^^^^^^^^^^^^^^^^^^^^^^^^^^^^^^^^^^^^^^^^^^^^^^^^^^^^^^^
  File "C:\Users\Ivan\PycharmProjects\Django_geek_dz\.venv\Lib\site-packages\django\db\models\query.py", line 1360, in values
    clone = self._values(*fields, **expressions)
            ^^^^^^^^^^^^^^^^^^^^^^^^^^^^^^^^^^^^
  File "C:\Users\Ivan\PycharmProjects\Django_geek_dz\.venv\Lib\site-packages\django\db\models\query.py", line 1355, in _values
    clone.query.set_values(fields)
  File "C:\Users\Ivan\PycharmProjects\Django_geek_dz\.venv\Lib\site-packages\django\db\models\sql\query.py", line 2502, in set_values
    self.add_fields(field_names, True)
  File "C:\Users\Ivan\PycharmProjects\Django_geek_dz\.venv\Lib\site-packages\django\db\models\sql\query.py", line 2208, in add_fields
    cols.append(join_info.transform_function(target, final_alias))
                ^^^^^^^^^^^^^^^^^^^^^^^^^^^^^^^^^^^^^^^^^^^^^^^^^
  File "C:\Users\Ivan\PycharmProjects\Django_geek_dz\.venv\Lib\site-packages\django\db\models\sql\query.py", line 1894, in transform
    raise last_field_exception
  File "C:\Users\Ivan\PycharmProjects\Django_geek_dz\.venv\Lib\site-packages\django\db\models\sql\query.py", line 1867, in setup_joins
    path, final_field, targets, rest = self.names_to_path(
                                       ^^^^^^^^^^^^^^^^^^^
  File "C:\Users\Ivan\PycharmProjects\Django_geek_dz\.venv\Lib\site-packages\django\db\models\sql\query.py", line 1772, in names_to_path
    raise FieldError(
django.core.exceptions.FieldError: Cannot resolve keyword 'prod_name' into field. Choices are: count, date, descriptions, id, name, order, orderproducts, price
ERROR 2024-06-11 15:42:17,978 basehttp 11688 8976 "GET /clients/products/1/2 HTTP/1.1" 500 121271
INFO 2024-06-11 15:42:41,461 autoreload 11688 15580 C:\Users\Ivan\PycharmProjects\Django_geek_dz\myproject\myapp\views.py changed, reloading.
INFO 2024-06-11 15:42:41,925 autoreload 4280 1708 Watching for file changes with StatReloader
ERROR 2024-06-11 15:42:45,587 log 4280 8412 Internal Server Error: /clients/products/1/2
Traceback (most recent call last):
  File "C:\Users\Ivan\PycharmProjects\Django_geek_dz\.venv\Lib\site-packages\django\core\handlers\exception.py", line 55, in inner
    response = get_response(request)
               ^^^^^^^^^^^^^^^^^^^^^
  File "C:\Users\Ivan\PycharmProjects\Django_geek_dz\.venv\Lib\site-packages\django\core\handlers\base.py", line 197, in _get_response
    response = wrapped_callback(request, *callback_args, **callback_kwargs)
               ^^^^^^^^^^^^^^^^^^^^^^^^^^^^^^^^^^^^^^^^^^^^^^^^^^^^^^^^^^^^
  File "C:\Users\Ivan\PycharmProjects\Django_geek_dz\myproject\myapp\views.py", line 32, in user_products
    'client_name': customer.client_name,
                   ^^^^^^^^^^^^^^^^^^^^
AttributeError: 'User' object has no attribute 'client_name'
ERROR 2024-06-11 15:42:45,589 basehttp 4280 8412 "GET /clients/products/1/2 HTTP/1.1" 500 67717
INFO 2024-06-11 15:43:10,020 autoreload 4280 1708 C:\Users\Ivan\PycharmProjects\Django_geek_dz\myproject\myapp\views.py changed, reloading.
INFO 2024-06-11 15:43:10,487 autoreload 17676 14964 Watching for file changes with StatReloader
ERROR 2024-06-11 15:43:12,724 log 17676 6256 Internal Server Error: /clients/products/1/2
Traceback (most recent call last):
  File "C:\Users\Ivan\PycharmProjects\Django_geek_dz\.venv\Lib\site-packages\django\core\handlers\exception.py", line 55, in inner
    response = get_response(request)
               ^^^^^^^^^^^^^^^^^^^^^
  File "C:\Users\Ivan\PycharmProjects\Django_geek_dz\.venv\Lib\site-packages\django\core\handlers\base.py", line 197, in _get_response
    response = wrapped_callback(request, *callback_args, **callback_kwargs)
               ^^^^^^^^^^^^^^^^^^^^^^^^^^^^^^^^^^^^^^^^^^^^^^^^^^^^^^^^^^^^
  File "C:\Users\Ivan\PycharmProjects\Django_geek_dz\myproject\myapp\views.py", line 37, in user_products
    return render(request, 'myapp/user_products.html', context)
           ^^^^^^^^^^^^^^^^^^^^^^^^^^^^^^^^^^^^^^^^^^^^^^^^^^^^
  File "C:\Users\Ivan\PycharmProjects\Django_geek_dz\.venv\Lib\site-packages\django\shortcuts.py", line 25, in render
    content = loader.render_to_string(template_name, context, request, using=using)
              ^^^^^^^^^^^^^^^^^^^^^^^^^^^^^^^^^^^^^^^^^^^^^^^^^^^^^^^^^^^^^^^^^^^^^
  File "C:\Users\Ivan\PycharmProjects\Django_geek_dz\.venv\Lib\site-packages\django\template\loader.py", line 61, in render_to_string
    template = get_template(template_name, using=using)
               ^^^^^^^^^^^^^^^^^^^^^^^^^^^^^^^^^^^^^^^^
  File "C:\Users\Ivan\PycharmProjects\Django_geek_dz\.venv\Lib\site-packages\django\template\loader.py", line 19, in get_template
    raise TemplateDoesNotExist(template_name, chain=chain)
django.template.exceptions.TemplateDoesNotExist: myapp/user_products.html
ERROR 2024-06-11 15:43:12,726 basehttp 17676 6256 "GET /clients/products/1/2 HTTP/1.1" 500 83555
INFO 2024-06-11 15:43:28,322 autoreload 17676 14964 C:\Users\Ivan\PycharmProjects\Django_geek_dz\myproject\myapp\views.py changed, reloading.
INFO 2024-06-11 15:43:28,805 autoreload 10800 17964 Watching for file changes with StatReloader
ERROR 2024-06-11 15:43:31,052 log 10800 19648 Internal Server Error: /clients/products/1/2
Traceback (most recent call last):
  File "C:\Users\Ivan\PycharmProjects\Django_geek_dz\.venv\Lib\site-packages\django\core\handlers\exception.py", line 55, in inner
    response = get_response(request)
               ^^^^^^^^^^^^^^^^^^^^^
  File "C:\Users\Ivan\PycharmProjects\Django_geek_dz\.venv\Lib\site-packages\django\core\handlers\base.py", line 197, in _get_response
    response = wrapped_callback(request, *callback_args, **callback_kwargs)
               ^^^^^^^^^^^^^^^^^^^^^^^^^^^^^^^^^^^^^^^^^^^^^^^^^^^^^^^^^^^^
  File "C:\Users\Ivan\PycharmProjects\Django_geek_dz\myproject\myapp\views.py", line 37, in user_products
    return render(request, 'user_products.html', context)
           ^^^^^^^^^^^^^^^^^^^^^^^^^^^^^^^^^^^^^^^^^^^^^^
  File "C:\Users\Ivan\PycharmProjects\Django_geek_dz\.venv\Lib\site-packages\django\shortcuts.py", line 25, in render
    content = loader.render_to_string(template_name, context, request, using=using)
              ^^^^^^^^^^^^^^^^^^^^^^^^^^^^^^^^^^^^^^^^^^^^^^^^^^^^^^^^^^^^^^^^^^^^^
  File "C:\Users\Ivan\PycharmProjects\Django_geek_dz\.venv\Lib\site-packages\django\template\loader.py", line 61, in render_to_string
    template = get_template(template_name, using=using)
               ^^^^^^^^^^^^^^^^^^^^^^^^^^^^^^^^^^^^^^^^
  File "C:\Users\Ivan\PycharmProjects\Django_geek_dz\.venv\Lib\site-packages\django\template\loader.py", line 19, in get_template
    raise TemplateDoesNotExist(template_name, chain=chain)
django.template.exceptions.TemplateDoesNotExist: user_products.html
ERROR 2024-06-11 15:43:31,054 basehttp 10800 19648 "GET /clients/products/1/2 HTTP/1.1" 500 83435
INFO 2024-06-11 15:44:22,601 autoreload 10800 17964 C:\Users\Ivan\PycharmProjects\Django_geek_dz\myproject\myapp\views.py changed, reloading.
INFO 2024-06-11 15:44:23,067 autoreload 15476 13124 Watching for file changes with StatReloader
ERROR 2024-06-11 15:44:25,719 log 15476 9680 Internal Server Error: /clients/products/1/2
Traceback (most recent call last):
  File "C:\Users\Ivan\PycharmProjects\Django_geek_dz\.venv\Lib\site-packages\django\core\handlers\exception.py", line 55, in inner
    response = get_response(request)
               ^^^^^^^^^^^^^^^^^^^^^
  File "C:\Users\Ivan\PycharmProjects\Django_geek_dz\.venv\Lib\site-packages\django\core\handlers\base.py", line 197, in _get_response
    response = wrapped_callback(request, *callback_args, **callback_kwargs)
               ^^^^^^^^^^^^^^^^^^^^^^^^^^^^^^^^^^^^^^^^^^^^^^^^^^^^^^^^^^^^
  File "C:\Users\Ivan\PycharmProjects\Django_geek_dz\myproject\myapp\views.py", line 37, in user_products
    return render(request, 'myapp/user_products.html', context)
           ^^^^^^^^^^^^^^^^^^^^^^^^^^^^^^^^^^^^^^^^^^^^^^^^^^^^
  File "C:\Users\Ivan\PycharmProjects\Django_geek_dz\.venv\Lib\site-packages\django\shortcuts.py", line 25, in render
    content = loader.render_to_string(template_name, context, request, using=using)
              ^^^^^^^^^^^^^^^^^^^^^^^^^^^^^^^^^^^^^^^^^^^^^^^^^^^^^^^^^^^^^^^^^^^^^
  File "C:\Users\Ivan\PycharmProjects\Django_geek_dz\.venv\Lib\site-packages\django\template\loader.py", line 61, in render_to_string
    template = get_template(template_name, using=using)
               ^^^^^^^^^^^^^^^^^^^^^^^^^^^^^^^^^^^^^^^^
  File "C:\Users\Ivan\PycharmProjects\Django_geek_dz\.venv\Lib\site-packages\django\template\loader.py", line 19, in get_template
    raise TemplateDoesNotExist(template_name, chain=chain)
django.template.exceptions.TemplateDoesNotExist: myapp/user_products.html
ERROR 2024-06-11 15:44:25,721 basehttp 15476 9680 "GET /clients/products/1/2 HTTP/1.1" 500 83555
INFO 2024-06-11 15:45:05,563 autoreload 15476 13124 C:\Users\Ivan\PycharmProjects\Django_geek_dz\myproject\myapp\urls.py changed, reloading.
INFO 2024-06-11 15:45:06,054 autoreload 14816 13924 Watching for file changes with StatReloader
ERROR 2024-06-11 15:45:07,907 log 14816 1464 Internal Server Error: /clients/products/1/2
Traceback (most recent call last):
  File "C:\Users\Ivan\PycharmProjects\Django_geek_dz\.venv\Lib\site-packages\django\core\handlers\exception.py", line 55, in inner
    response = get_response(request)
               ^^^^^^^^^^^^^^^^^^^^^
  File "C:\Users\Ivan\PycharmProjects\Django_geek_dz\.venv\Lib\site-packages\django\core\handlers\base.py", line 197, in _get_response
    response = wrapped_callback(request, *callback_args, **callback_kwargs)
               ^^^^^^^^^^^^^^^^^^^^^^^^^^^^^^^^^^^^^^^^^^^^^^^^^^^^^^^^^^^^
  File "C:\Users\Ivan\PycharmProjects\Django_geek_dz\myproject\myapp\views.py", line 37, in user_products
    return render(request, 'myapp/user_products.html', context)
           ^^^^^^^^^^^^^^^^^^^^^^^^^^^^^^^^^^^^^^^^^^^^^^^^^^^^
  File "C:\Users\Ivan\PycharmProjects\Django_geek_dz\.venv\Lib\site-packages\django\shortcuts.py", line 25, in render
    content = loader.render_to_string(template_name, context, request, using=using)
              ^^^^^^^^^^^^^^^^^^^^^^^^^^^^^^^^^^^^^^^^^^^^^^^^^^^^^^^^^^^^^^^^^^^^^
  File "C:\Users\Ivan\PycharmProjects\Django_geek_dz\.venv\Lib\site-packages\django\template\loader.py", line 61, in render_to_string
    template = get_template(template_name, using=using)
               ^^^^^^^^^^^^^^^^^^^^^^^^^^^^^^^^^^^^^^^^
  File "C:\Users\Ivan\PycharmProjects\Django_geek_dz\.venv\Lib\site-packages\django\template\loader.py", line 19, in get_template
    raise TemplateDoesNotExist(template_name, chain=chain)
django.template.exceptions.TemplateDoesNotExist: myapp/user_products.html
ERROR 2024-06-11 15:45:07,908 basehttp 14816 1464 "GET /clients/products/1/2 HTTP/1.1" 500 83555
ERROR 2024-06-11 15:47:42,132 log 14816 1464 Internal Server Error: /clients/products/1/2
Traceback (most recent call last):
  File "C:\Users\Ivan\PycharmProjects\Django_geek_dz\.venv\Lib\site-packages\django\core\handlers\exception.py", line 55, in inner
    response = get_response(request)
               ^^^^^^^^^^^^^^^^^^^^^
  File "C:\Users\Ivan\PycharmProjects\Django_geek_dz\.venv\Lib\site-packages\django\core\handlers\base.py", line 197, in _get_response
    response = wrapped_callback(request, *callback_args, **callback_kwargs)
               ^^^^^^^^^^^^^^^^^^^^^^^^^^^^^^^^^^^^^^^^^^^^^^^^^^^^^^^^^^^^
  File "C:\Users\Ivan\PycharmProjects\Django_geek_dz\myproject\myapp\views.py", line 37, in user_products
    return render(request, 'myapp/user_products.html', context)
           ^^^^^^^^^^^^^^^^^^^^^^^^^^^^^^^^^^^^^^^^^^^^^^^^^^^^
  File "C:\Users\Ivan\PycharmProjects\Django_geek_dz\.venv\Lib\site-packages\django\shortcuts.py", line 25, in render
    content = loader.render_to_string(template_name, context, request, using=using)
              ^^^^^^^^^^^^^^^^^^^^^^^^^^^^^^^^^^^^^^^^^^^^^^^^^^^^^^^^^^^^^^^^^^^^^
  File "C:\Users\Ivan\PycharmProjects\Django_geek_dz\.venv\Lib\site-packages\django\template\loader.py", line 61, in render_to_string
    template = get_template(template_name, using=using)
               ^^^^^^^^^^^^^^^^^^^^^^^^^^^^^^^^^^^^^^^^
  File "C:\Users\Ivan\PycharmProjects\Django_geek_dz\.venv\Lib\site-packages\django\template\loader.py", line 19, in get_template
    raise TemplateDoesNotExist(template_name, chain=chain)
django.template.exceptions.TemplateDoesNotExist: myapp/user_products.html
ERROR 2024-06-11 15:47:42,133 basehttp 14816 1464 "GET /clients/products/1/2 HTTP/1.1" 500 83555
INFO 2024-06-11 15:48:20,608 autoreload 16392 18256 Watching for file changes with StatReloader
ERROR 2024-06-11 15:48:23,735 log 16392 12348 Internal Server Error: /clients/products/1/2
Traceback (most recent call last):
  File "C:\Users\Ivan\PycharmProjects\Django_geek_dz\.venv\Lib\site-packages\django\core\handlers\exception.py", line 55, in inner
    response = get_response(request)
               ^^^^^^^^^^^^^^^^^^^^^
  File "C:\Users\Ivan\PycharmProjects\Django_geek_dz\.venv\Lib\site-packages\django\core\handlers\base.py", line 197, in _get_response
    response = wrapped_callback(request, *callback_args, **callback_kwargs)
               ^^^^^^^^^^^^^^^^^^^^^^^^^^^^^^^^^^^^^^^^^^^^^^^^^^^^^^^^^^^^
  File "C:\Users\Ivan\PycharmProjects\Django_geek_dz\myproject\myapp\views.py", line 37, in user_products
    return render(request, 'myapp/user_products.html', context)
           ^^^^^^^^^^^^^^^^^^^^^^^^^^^^^^^^^^^^^^^^^^^^^^^^^^^^
  File "C:\Users\Ivan\PycharmProjects\Django_geek_dz\.venv\Lib\site-packages\django\shortcuts.py", line 25, in render
    content = loader.render_to_string(template_name, context, request, using=using)
              ^^^^^^^^^^^^^^^^^^^^^^^^^^^^^^^^^^^^^^^^^^^^^^^^^^^^^^^^^^^^^^^^^^^^^
  File "C:\Users\Ivan\PycharmProjects\Django_geek_dz\.venv\Lib\site-packages\django\template\loader.py", line 61, in render_to_string
    template = get_template(template_name, using=using)
               ^^^^^^^^^^^^^^^^^^^^^^^^^^^^^^^^^^^^^^^^
  File "C:\Users\Ivan\PycharmProjects\Django_geek_dz\.venv\Lib\site-packages\django\template\loader.py", line 19, in get_template
    raise TemplateDoesNotExist(template_name, chain=chain)
django.template.exceptions.TemplateDoesNotExist: myapp/user_products.html
ERROR 2024-06-11 15:48:23,736 basehttp 16392 12348 "GET /clients/products/1/2 HTTP/1.1" 500 83555
ERROR 2024-06-11 15:54:45,373 log 16392 17392 Internal Server Error: /clients/products/1/2
Traceback (most recent call last):
  File "C:\Users\Ivan\PycharmProjects\Django_geek_dz\.venv\Lib\site-packages\django\core\handlers\exception.py", line 55, in inner
    response = get_response(request)
               ^^^^^^^^^^^^^^^^^^^^^
  File "C:\Users\Ivan\PycharmProjects\Django_geek_dz\.venv\Lib\site-packages\django\core\handlers\base.py", line 197, in _get_response
    response = wrapped_callback(request, *callback_args, **callback_kwargs)
               ^^^^^^^^^^^^^^^^^^^^^^^^^^^^^^^^^^^^^^^^^^^^^^^^^^^^^^^^^^^^
  File "C:\Users\Ivan\PycharmProjects\Django_geek_dz\myproject\myapp\views.py", line 37, in user_products
    return render(request, 'myapp/user_products.html', context)
           ^^^^^^^^^^^^^^^^^^^^^^^^^^^^^^^^^^^^^^^^^^^^^^^^^^^^
  File "C:\Users\Ivan\PycharmProjects\Django_geek_dz\.venv\Lib\site-packages\django\shortcuts.py", line 25, in render
    content = loader.render_to_string(template_name, context, request, using=using)
              ^^^^^^^^^^^^^^^^^^^^^^^^^^^^^^^^^^^^^^^^^^^^^^^^^^^^^^^^^^^^^^^^^^^^^
  File "C:\Users\Ivan\PycharmProjects\Django_geek_dz\.venv\Lib\site-packages\django\template\loader.py", line 61, in render_to_string
    template = get_template(template_name, using=using)
               ^^^^^^^^^^^^^^^^^^^^^^^^^^^^^^^^^^^^^^^^
  File "C:\Users\Ivan\PycharmProjects\Django_geek_dz\.venv\Lib\site-packages\django\template\loader.py", line 19, in get_template
    raise TemplateDoesNotExist(template_name, chain=chain)
django.template.exceptions.TemplateDoesNotExist: myapp/user_products.html
ERROR 2024-06-11 15:54:45,374 basehttp 16392 17392 "GET /clients/products/1/2 HTTP/1.1" 500 83555
WARNING 2024-06-11 15:56:42,306 log 16392 17392 Not Found: /clients/products/3.
WARNING 2024-06-11 15:56:42,306 basehttp 16392 17392 "GET /clients/products/3. HTTP/1.1" 404 2699
ERROR 2024-06-11 15:56:47,105 log 16392 17392 Internal Server Error: /clients/products/3/3
Traceback (most recent call last):
  File "C:\Users\Ivan\PycharmProjects\Django_geek_dz\.venv\Lib\site-packages\django\core\handlers\exception.py", line 55, in inner
    response = get_response(request)
               ^^^^^^^^^^^^^^^^^^^^^
  File "C:\Users\Ivan\PycharmProjects\Django_geek_dz\.venv\Lib\site-packages\django\core\handlers\base.py", line 197, in _get_response
    response = wrapped_callback(request, *callback_args, **callback_kwargs)
               ^^^^^^^^^^^^^^^^^^^^^^^^^^^^^^^^^^^^^^^^^^^^^^^^^^^^^^^^^^^^
  File "C:\Users\Ivan\PycharmProjects\Django_geek_dz\myproject\myapp\views.py", line 37, in user_products
    return render(request, 'myapp/user_products.html', context)
           ^^^^^^^^^^^^^^^^^^^^^^^^^^^^^^^^^^^^^^^^^^^^^^^^^^^^
  File "C:\Users\Ivan\PycharmProjects\Django_geek_dz\.venv\Lib\site-packages\django\shortcuts.py", line 25, in render
    content = loader.render_to_string(template_name, context, request, using=using)
              ^^^^^^^^^^^^^^^^^^^^^^^^^^^^^^^^^^^^^^^^^^^^^^^^^^^^^^^^^^^^^^^^^^^^^
  File "C:\Users\Ivan\PycharmProjects\Django_geek_dz\.venv\Lib\site-packages\django\template\loader.py", line 61, in render_to_string
    template = get_template(template_name, using=using)
               ^^^^^^^^^^^^^^^^^^^^^^^^^^^^^^^^^^^^^^^^
  File "C:\Users\Ivan\PycharmProjects\Django_geek_dz\.venv\Lib\site-packages\django\template\loader.py", line 19, in get_template
    raise TemplateDoesNotExist(template_name, chain=chain)
django.template.exceptions.TemplateDoesNotExist: myapp/user_products.html
ERROR 2024-06-11 15:56:47,107 basehttp 16392 17392 "GET /clients/products/3/3 HTTP/1.1" 500 83418
INFO 2024-06-11 15:57:37,418 views 16392 17392 посещение страницы about в: 2024-06-11 15:57:37.418728
INFO 2024-06-11 15:57:37,422 basehttp 16392 17392 "GET / HTTP/1.1" 200 742
INFO 2024-06-11 15:57:41,934 views 16392 17392 посещение страницы about в: 2024-06-11 15:57:41.934180
INFO 2024-06-11 15:57:41,935 basehttp 16392 17392 "GET /about/ HTTP/1.1" 200 1009
WARNING 2024-06-11 15:57:49,639 log 16392 17392 Not Found: /clients/5/5
WARNING 2024-06-11 15:57:49,639 basehttp 16392 17392 "GET /clients/5/5 HTTP/1.1" 404 2675
ERROR 2024-06-11 15:58:00,120 log 16392 17392 Internal Server Error: /clients/products/2/5
Traceback (most recent call last):
  File "C:\Users\Ivan\PycharmProjects\Django_geek_dz\.venv\Lib\site-packages\django\core\handlers\exception.py", line 55, in inner
    response = get_response(request)
               ^^^^^^^^^^^^^^^^^^^^^
  File "C:\Users\Ivan\PycharmProjects\Django_geek_dz\.venv\Lib\site-packages\django\core\handlers\base.py", line 197, in _get_response
    response = wrapped_callback(request, *callback_args, **callback_kwargs)
               ^^^^^^^^^^^^^^^^^^^^^^^^^^^^^^^^^^^^^^^^^^^^^^^^^^^^^^^^^^^^
  File "C:\Users\Ivan\PycharmProjects\Django_geek_dz\myproject\myapp\views.py", line 37, in user_products
    return render(request, 'myapp/user_products.html', context)
           ^^^^^^^^^^^^^^^^^^^^^^^^^^^^^^^^^^^^^^^^^^^^^^^^^^^^
  File "C:\Users\Ivan\PycharmProjects\Django_geek_dz\.venv\Lib\site-packages\django\shortcuts.py", line 25, in render
    content = loader.render_to_string(template_name, context, request, using=using)
              ^^^^^^^^^^^^^^^^^^^^^^^^^^^^^^^^^^^^^^^^^^^^^^^^^^^^^^^^^^^^^^^^^^^^^
  File "C:\Users\Ivan\PycharmProjects\Django_geek_dz\.venv\Lib\site-packages\django\template\loader.py", line 61, in render_to_string
    template = get_template(template_name, using=using)
               ^^^^^^^^^^^^^^^^^^^^^^^^^^^^^^^^^^^^^^^^
  File "C:\Users\Ivan\PycharmProjects\Django_geek_dz\.venv\Lib\site-packages\django\template\loader.py", line 19, in get_template
    raise TemplateDoesNotExist(template_name, chain=chain)
django.template.exceptions.TemplateDoesNotExist: myapp/user_products.html
ERROR 2024-06-11 15:58:00,121 basehttp 16392 17392 "GET /clients/products/2/5 HTTP/1.1" 500 83418
INFO 2024-06-11 16:02:48,322 autoreload 16392 18256 C:\Users\Ivan\PycharmProjects\Django_geek_dz\myproject\myapp\views.py changed, reloading.
INFO 2024-06-11 16:02:48,836 autoreload 1172 3640 Watching for file changes with StatReloader
INFO 2024-06-11 16:06:45,037 autoreload 1172 3640 C:\Users\Ivan\PycharmProjects\Django_geek_dz\myproject\myapp\views.py changed, reloading.
INFO 2024-06-11 16:06:45,522 autoreload 16852 16380 Watching for file changes with StatReloader
INFO 2024-06-11 16:06:53,277 autoreload 12944 15580 Watching for file changes with StatReloader
ERROR 2024-06-11 16:06:55,947 log 16852 17364 Internal Server Error: /clients/products/2/5
Traceback (most recent call last):
  File "C:\Users\Ivan\PycharmProjects\Django_geek_dz\.venv\Lib\site-packages\django\core\handlers\exception.py", line 55, in inner
    response = get_response(request)
               ^^^^^^^^^^^^^^^^^^^^^
  File "C:\Users\Ivan\PycharmProjects\Django_geek_dz\.venv\Lib\site-packages\django\core\handlers\base.py", line 197, in _get_response
    response = wrapped_callback(request, *callback_args, **callback_kwargs)
               ^^^^^^^^^^^^^^^^^^^^^^^^^^^^^^^^^^^^^^^^^^^^^^^^^^^^^^^^^^^^
  File "C:\Users\Ivan\PycharmProjects\Django_geek_dz\myproject\myapp\views.py", line 37, in user_products
    return render(request, 'myapp/user_products.html', context)
           ^^^^^^^^^^^^^^^^^^^^^^^^^^^^^^^^^^^^^^^^^^^^^^^^^^^^
  File "C:\Users\Ivan\PycharmProjects\Django_geek_dz\.venv\Lib\site-packages\django\shortcuts.py", line 25, in render
    content = loader.render_to_string(template_name, context, request, using=using)
              ^^^^^^^^^^^^^^^^^^^^^^^^^^^^^^^^^^^^^^^^^^^^^^^^^^^^^^^^^^^^^^^^^^^^^
  File "C:\Users\Ivan\PycharmProjects\Django_geek_dz\.venv\Lib\site-packages\django\template\loader.py", line 61, in render_to_string
    template = get_template(template_name, using=using)
               ^^^^^^^^^^^^^^^^^^^^^^^^^^^^^^^^^^^^^^^^
  File "C:\Users\Ivan\PycharmProjects\Django_geek_dz\.venv\Lib\site-packages\django\template\loader.py", line 19, in get_template
    raise TemplateDoesNotExist(template_name, chain=chain)
django.template.exceptions.TemplateDoesNotExist: myapp/user_products.html
ERROR 2024-06-11 16:06:55,948 basehttp 16852 17364 "GET /clients/products/2/5 HTTP/1.1" 500 83555
ERROR 2024-06-11 16:06:56,952 log 16852 17364 Internal Server Error: /clients/products/2/5
Traceback (most recent call last):
  File "C:\Users\Ivan\PycharmProjects\Django_geek_dz\.venv\Lib\site-packages\django\core\handlers\exception.py", line 55, in inner
    response = get_response(request)
               ^^^^^^^^^^^^^^^^^^^^^
  File "C:\Users\Ivan\PycharmProjects\Django_geek_dz\.venv\Lib\site-packages\django\core\handlers\base.py", line 197, in _get_response
    response = wrapped_callback(request, *callback_args, **callback_kwargs)
               ^^^^^^^^^^^^^^^^^^^^^^^^^^^^^^^^^^^^^^^^^^^^^^^^^^^^^^^^^^^^
  File "C:\Users\Ivan\PycharmProjects\Django_geek_dz\myproject\myapp\views.py", line 37, in user_products
    return render(request, 'myapp/user_products.html', context)
           ^^^^^^^^^^^^^^^^^^^^^^^^^^^^^^^^^^^^^^^^^^^^^^^^^^^^
  File "C:\Users\Ivan\PycharmProjects\Django_geek_dz\.venv\Lib\site-packages\django\shortcuts.py", line 25, in render
    content = loader.render_to_string(template_name, context, request, using=using)
              ^^^^^^^^^^^^^^^^^^^^^^^^^^^^^^^^^^^^^^^^^^^^^^^^^^^^^^^^^^^^^^^^^^^^^
  File "C:\Users\Ivan\PycharmProjects\Django_geek_dz\.venv\Lib\site-packages\django\template\loader.py", line 61, in render_to_string
    template = get_template(template_name, using=using)
               ^^^^^^^^^^^^^^^^^^^^^^^^^^^^^^^^^^^^^^^^
  File "C:\Users\Ivan\PycharmProjects\Django_geek_dz\.venv\Lib\site-packages\django\template\loader.py", line 19, in get_template
    raise TemplateDoesNotExist(template_name, chain=chain)
django.template.exceptions.TemplateDoesNotExist: myapp/user_products.html
ERROR 2024-06-11 16:06:56,953 basehttp 16852 17364 "GET /clients/products/2/5 HTTP/1.1" 500 83555
ERROR 2024-06-11 16:06:57,415 log 16852 17364 Internal Server Error: /clients/products/2/5
Traceback (most recent call last):
  File "C:\Users\Ivan\PycharmProjects\Django_geek_dz\.venv\Lib\site-packages\django\core\handlers\exception.py", line 55, in inner
    response = get_response(request)
               ^^^^^^^^^^^^^^^^^^^^^
  File "C:\Users\Ivan\PycharmProjects\Django_geek_dz\.venv\Lib\site-packages\django\core\handlers\base.py", line 197, in _get_response
    response = wrapped_callback(request, *callback_args, **callback_kwargs)
               ^^^^^^^^^^^^^^^^^^^^^^^^^^^^^^^^^^^^^^^^^^^^^^^^^^^^^^^^^^^^
  File "C:\Users\Ivan\PycharmProjects\Django_geek_dz\myproject\myapp\views.py", line 37, in user_products
    return render(request, 'myapp/user_products.html', context)
           ^^^^^^^^^^^^^^^^^^^^^^^^^^^^^^^^^^^^^^^^^^^^^^^^^^^^
  File "C:\Users\Ivan\PycharmProjects\Django_geek_dz\.venv\Lib\site-packages\django\shortcuts.py", line 25, in render
    content = loader.render_to_string(template_name, context, request, using=using)
              ^^^^^^^^^^^^^^^^^^^^^^^^^^^^^^^^^^^^^^^^^^^^^^^^^^^^^^^^^^^^^^^^^^^^^
  File "C:\Users\Ivan\PycharmProjects\Django_geek_dz\.venv\Lib\site-packages\django\template\loader.py", line 61, in render_to_string
    template = get_template(template_name, using=using)
               ^^^^^^^^^^^^^^^^^^^^^^^^^^^^^^^^^^^^^^^^
  File "C:\Users\Ivan\PycharmProjects\Django_geek_dz\.venv\Lib\site-packages\django\template\loader.py", line 19, in get_template
    raise TemplateDoesNotExist(template_name, chain=chain)
django.template.exceptions.TemplateDoesNotExist: myapp/user_products.html
ERROR 2024-06-11 16:06:57,416 basehttp 16852 17364 "GET /clients/products/2/5 HTTP/1.1" 500 83555
ERROR 2024-06-11 16:06:58,959 log 16852 17364 Internal Server Error: /clients/products/2/5
Traceback (most recent call last):
  File "C:\Users\Ivan\PycharmProjects\Django_geek_dz\.venv\Lib\site-packages\django\core\handlers\exception.py", line 55, in inner
    response = get_response(request)
               ^^^^^^^^^^^^^^^^^^^^^
  File "C:\Users\Ivan\PycharmProjects\Django_geek_dz\.venv\Lib\site-packages\django\core\handlers\base.py", line 197, in _get_response
    response = wrapped_callback(request, *callback_args, **callback_kwargs)
               ^^^^^^^^^^^^^^^^^^^^^^^^^^^^^^^^^^^^^^^^^^^^^^^^^^^^^^^^^^^^
  File "C:\Users\Ivan\PycharmProjects\Django_geek_dz\myproject\myapp\views.py", line 37, in user_products
    return render(request, 'myapp/user_products.html', context)
           ^^^^^^^^^^^^^^^^^^^^^^^^^^^^^^^^^^^^^^^^^^^^^^^^^^^^
  File "C:\Users\Ivan\PycharmProjects\Django_geek_dz\.venv\Lib\site-packages\django\shortcuts.py", line 25, in render
    content = loader.render_to_string(template_name, context, request, using=using)
              ^^^^^^^^^^^^^^^^^^^^^^^^^^^^^^^^^^^^^^^^^^^^^^^^^^^^^^^^^^^^^^^^^^^^^
  File "C:\Users\Ivan\PycharmProjects\Django_geek_dz\.venv\Lib\site-packages\django\template\loader.py", line 61, in render_to_string
    template = get_template(template_name, using=using)
               ^^^^^^^^^^^^^^^^^^^^^^^^^^^^^^^^^^^^^^^^
  File "C:\Users\Ivan\PycharmProjects\Django_geek_dz\.venv\Lib\site-packages\django\template\loader.py", line 19, in get_template
    raise TemplateDoesNotExist(template_name, chain=chain)
django.template.exceptions.TemplateDoesNotExist: myapp/user_products.html
ERROR 2024-06-11 16:06:58,960 basehttp 16852 17364 "GET /clients/products/2/5 HTTP/1.1" 500 83555
ERROR 2024-06-11 16:07:34,524 log 16852 17364 Internal Server Error: /clients/products/6/3
Traceback (most recent call last):
  File "C:\Users\Ivan\PycharmProjects\Django_geek_dz\.venv\Lib\site-packages\django\core\handlers\exception.py", line 55, in inner
    response = get_response(request)
               ^^^^^^^^^^^^^^^^^^^^^
  File "C:\Users\Ivan\PycharmProjects\Django_geek_dz\.venv\Lib\site-packages\django\core\handlers\base.py", line 197, in _get_response
    response = wrapped_callback(request, *callback_args, **callback_kwargs)
               ^^^^^^^^^^^^^^^^^^^^^^^^^^^^^^^^^^^^^^^^^^^^^^^^^^^^^^^^^^^^
  File "C:\Users\Ivan\PycharmProjects\Django_geek_dz\myproject\myapp\views.py", line 37, in user_products
    return render(request, 'myapp/user_products.html', context)
           ^^^^^^^^^^^^^^^^^^^^^^^^^^^^^^^^^^^^^^^^^^^^^^^^^^^^
  File "C:\Users\Ivan\PycharmProjects\Django_geek_dz\.venv\Lib\site-packages\django\shortcuts.py", line 25, in render
    content = loader.render_to_string(template_name, context, request, using=using)
              ^^^^^^^^^^^^^^^^^^^^^^^^^^^^^^^^^^^^^^^^^^^^^^^^^^^^^^^^^^^^^^^^^^^^^
  File "C:\Users\Ivan\PycharmProjects\Django_geek_dz\.venv\Lib\site-packages\django\template\loader.py", line 61, in render_to_string
    template = get_template(template_name, using=using)
               ^^^^^^^^^^^^^^^^^^^^^^^^^^^^^^^^^^^^^^^^
  File "C:\Users\Ivan\PycharmProjects\Django_geek_dz\.venv\Lib\site-packages\django\template\loader.py", line 19, in get_template
    raise TemplateDoesNotExist(template_name, chain=chain)
django.template.exceptions.TemplateDoesNotExist: myapp/user_products.html
ERROR 2024-06-11 16:07:34,526 basehttp 16852 17364 "GET /clients/products/6/3 HTTP/1.1" 500 83431
INFO 2024-06-11 16:08:08,067 autoreload 16852 16380 C:\Users\Ivan\PycharmProjects\Django_geek_dz\myproject\myapp\urls.py changed, reloading.
INFO 2024-06-11 16:08:08,502 autoreload 12944 15580 C:\Users\Ivan\PycharmProjects\Django_geek_dz\myproject\myapp\urls.py changed, reloading.
INFO 2024-06-11 16:08:08,559 autoreload 1244 13080 Watching for file changes with StatReloader
INFO 2024-06-11 16:08:08,994 autoreload 10224 14712 Watching for file changes with StatReloader
ERROR 2024-06-11 16:08:10,837 log 1244 10728 Internal Server Error: /clients/products/6/3
Traceback (most recent call last):
  File "C:\Users\Ivan\PycharmProjects\Django_geek_dz\.venv\Lib\site-packages\django\core\handlers\exception.py", line 55, in inner
    response = get_response(request)
               ^^^^^^^^^^^^^^^^^^^^^
  File "C:\Users\Ivan\PycharmProjects\Django_geek_dz\.venv\Lib\site-packages\django\core\handlers\base.py", line 197, in _get_response
    response = wrapped_callback(request, *callback_args, **callback_kwargs)
               ^^^^^^^^^^^^^^^^^^^^^^^^^^^^^^^^^^^^^^^^^^^^^^^^^^^^^^^^^^^^
  File "C:\Users\Ivan\PycharmProjects\Django_geek_dz\myproject\myapp\views.py", line 37, in user_products
    return render(request, 'myapp/user_products.html', context)
           ^^^^^^^^^^^^^^^^^^^^^^^^^^^^^^^^^^^^^^^^^^^^^^^^^^^^
  File "C:\Users\Ivan\PycharmProjects\Django_geek_dz\.venv\Lib\site-packages\django\shortcuts.py", line 25, in render
    content = loader.render_to_string(template_name, context, request, using=using)
              ^^^^^^^^^^^^^^^^^^^^^^^^^^^^^^^^^^^^^^^^^^^^^^^^^^^^^^^^^^^^^^^^^^^^^
  File "C:\Users\Ivan\PycharmProjects\Django_geek_dz\.venv\Lib\site-packages\django\template\loader.py", line 61, in render_to_string
    template = get_template(template_name, using=using)
               ^^^^^^^^^^^^^^^^^^^^^^^^^^^^^^^^^^^^^^^^
  File "C:\Users\Ivan\PycharmProjects\Django_geek_dz\.venv\Lib\site-packages\django\template\loader.py", line 19, in get_template
    raise TemplateDoesNotExist(template_name, chain=chain)
django.template.exceptions.TemplateDoesNotExist: myapp/user_products.html
ERROR 2024-06-11 16:08:10,838 basehttp 1244 10728 "GET /clients/products/6/3 HTTP/1.1" 500 83568
ERROR 2024-06-11 16:08:11,648 log 1244 10728 Internal Server Error: /clients/products/6/3
Traceback (most recent call last):
  File "C:\Users\Ivan\PycharmProjects\Django_geek_dz\.venv\Lib\site-packages\django\core\handlers\exception.py", line 55, in inner
    response = get_response(request)
               ^^^^^^^^^^^^^^^^^^^^^
  File "C:\Users\Ivan\PycharmProjects\Django_geek_dz\.venv\Lib\site-packages\django\core\handlers\base.py", line 197, in _get_response
    response = wrapped_callback(request, *callback_args, **callback_kwargs)
               ^^^^^^^^^^^^^^^^^^^^^^^^^^^^^^^^^^^^^^^^^^^^^^^^^^^^^^^^^^^^
  File "C:\Users\Ivan\PycharmProjects\Django_geek_dz\myproject\myapp\views.py", line 37, in user_products
    return render(request, 'myapp/user_products.html', context)
           ^^^^^^^^^^^^^^^^^^^^^^^^^^^^^^^^^^^^^^^^^^^^^^^^^^^^
  File "C:\Users\Ivan\PycharmProjects\Django_geek_dz\.venv\Lib\site-packages\django\shortcuts.py", line 25, in render
    content = loader.render_to_string(template_name, context, request, using=using)
              ^^^^^^^^^^^^^^^^^^^^^^^^^^^^^^^^^^^^^^^^^^^^^^^^^^^^^^^^^^^^^^^^^^^^^
  File "C:\Users\Ivan\PycharmProjects\Django_geek_dz\.venv\Lib\site-packages\django\template\loader.py", line 61, in render_to_string
    template = get_template(template_name, using=using)
               ^^^^^^^^^^^^^^^^^^^^^^^^^^^^^^^^^^^^^^^^
  File "C:\Users\Ivan\PycharmProjects\Django_geek_dz\.venv\Lib\site-packages\django\template\loader.py", line 19, in get_template
    raise TemplateDoesNotExist(template_name, chain=chain)
django.template.exceptions.TemplateDoesNotExist: myapp/user_products.html
ERROR 2024-06-11 16:08:11,649 basehttp 1244 10728 "GET /clients/products/6/3 HTTP/1.1" 500 83568
INFO 2024-06-18 10:57:00,276 autoreload 9356 1936 Watching for file changes with StatReloader
INFO 2024-06-18 10:57:02,377 views 9356 11540 посещение страницы about в: 2024-06-18 10:57:02.377697
INFO 2024-06-18 10:57:02,397 basehttp 9356 11540 "GET / HTTP/1.1" 200 742
WARNING 2024-06-18 10:57:02,613 log 9356 11540 Not Found: /favicon.ico
WARNING 2024-06-18 10:57:02,614 basehttp 9356 11540 "GET /favicon.ico HTTP/1.1" 404 2441
INFO 2024-06-18 10:58:01,235 autoreload 9356 1936 C:\Users\Ivan\PycharmProjects\Django_geek_dz\myproject\myapp\urls.py changed, reloading.
INFO 2024-06-18 10:58:01,724 autoreload 11016 1964 Watching for file changes with StatReloader
INFO 2024-06-18 10:58:04,098 views 11016 6280 посещение страницы about в: 2024-06-18 10:58:04.098238
INFO 2024-06-18 10:58:04,103 basehttp 11016 6280 "GET / HTTP/1.1" 200 742
WARNING 2024-06-18 10:58:08,756 log 11016 6280 Not Found: /test
WARNING 2024-06-18 10:58:08,756 basehttp 11016 6280 "GET /test HTTP/1.1" 404 2585
INFO 2024-06-18 10:58:32,913 autoreload 11016 1964 C:\Users\Ivan\PycharmProjects\Django_geek_dz\myproject\myapp\urls.py changed, reloading.
INFO 2024-06-18 10:58:33,399 autoreload 12760 13144 Watching for file changes with StatReloader
INFO 2024-06-18 10:58:35,550 basehttp 12760 1500 "GET /test HTTP/1.1" 301 0
ERROR 2024-06-18 10:58:35,608 log 12760 15080 Internal Server Error: /test/
Traceback (most recent call last):
  File "C:\Users\Ivan\PycharmProjects\Django_geek_dz\.venv\Lib\site-packages\django\core\handlers\exception.py", line 55, in inner
    response = get_response(request)
               ^^^^^^^^^^^^^^^^^^^^^
  File "C:\Users\Ivan\PycharmProjects\Django_geek_dz\.venv\Lib\site-packages\django\core\handlers\base.py", line 197, in _get_response
    response = wrapped_callback(request, *callback_args, **callback_kwargs)
               ^^^^^^^^^^^^^^^^^^^^^^^^^^^^^^^^^^^^^^^^^^^^^^^^^^^^^^^^^^^^
TypeError: user_products() missing 2 required positional arguments: 'customer_id' and 'days_history'
ERROR 2024-06-18 10:58:35,609 basehttp 12760 15080 "GET /test/ HTTP/1.1" 500 62692
ERROR 2024-06-18 10:59:20,517 log 12760 15080 Internal Server Error: /test/
Traceback (most recent call last):
  File "C:\Users\Ivan\PycharmProjects\Django_geek_dz\.venv\Lib\site-packages\django\core\handlers\exception.py", line 55, in inner
    response = get_response(request)
               ^^^^^^^^^^^^^^^^^^^^^
  File "C:\Users\Ivan\PycharmProjects\Django_geek_dz\.venv\Lib\site-packages\django\core\handlers\base.py", line 197, in _get_response
    response = wrapped_callback(request, *callback_args, **callback_kwargs)
               ^^^^^^^^^^^^^^^^^^^^^^^^^^^^^^^^^^^^^^^^^^^^^^^^^^^^^^^^^^^^
TypeError: user_products() missing 2 required positional arguments: 'customer_id' and 'days_history'
ERROR 2024-06-18 10:59:20,518 basehttp 12760 15080 "GET /test/ HTTP/1.1" 500 62692
INFO 2024-06-18 11:00:24,685 autoreload 12760 13144 C:\Users\Ivan\PycharmProjects\Django_geek_dz\myproject\myapp\views.py changed, reloading.
INFO 2024-06-18 11:00:25,181 autoreload 1176 15716 Watching for file changes with StatReloader
ERROR 2024-06-18 11:00:25,532 log 1176 13804 Internal Server Error: /test/
Traceback (most recent call last):
  File "C:\Users\Ivan\PycharmProjects\Django_geek_dz\.venv\Lib\site-packages\django\core\handlers\exception.py", line 55, in inner
    response = get_response(request)
               ^^^^^^^^^^^^^^^^^^^^^
  File "C:\Users\Ivan\PycharmProjects\Django_geek_dz\.venv\Lib\site-packages\django\core\handlers\base.py", line 197, in _get_response
    response = wrapped_callback(request, *callback_args, **callback_kwargs)
               ^^^^^^^^^^^^^^^^^^^^^^^^^^^^^^^^^^^^^^^^^^^^^^^^^^^^^^^^^^^^
  File "C:\Users\Ivan\PycharmProjects\Django_geek_dz\myproject\myapp\views.py", line 25, in user_products
    return render(request, "myapp/user_products.html", context)
           ^^^^^^^^^^^^^^^^^^^^^^^^^^^^^^^^^^^^^^^^^^^^^^^^^^^^
  File "C:\Users\Ivan\PycharmProjects\Django_geek_dz\.venv\Lib\site-packages\django\shortcuts.py", line 25, in render
    content = loader.render_to_string(template_name, context, request, using=using)
              ^^^^^^^^^^^^^^^^^^^^^^^^^^^^^^^^^^^^^^^^^^^^^^^^^^^^^^^^^^^^^^^^^^^^^
  File "C:\Users\Ivan\PycharmProjects\Django_geek_dz\.venv\Lib\site-packages\django\template\loader.py", line 61, in render_to_string
    template = get_template(template_name, using=using)
               ^^^^^^^^^^^^^^^^^^^^^^^^^^^^^^^^^^^^^^^^
  File "C:\Users\Ivan\PycharmProjects\Django_geek_dz\.venv\Lib\site-packages\django\template\loader.py", line 19, in get_template
    raise TemplateDoesNotExist(template_name, chain=chain)
django.template.exceptions.TemplateDoesNotExist: myapp/user_products.html
ERROR 2024-06-18 11:00:25,534 basehttp 1176 13804 "GET /test/ HTTP/1.1" 500 82138
INFO 2024-06-18 11:03:03,598 autoreload 10116 15388 Watching for file changes with StatReloader
ERROR 2024-06-18 11:03:06,048 log 10116 7856 Internal Server Error: /test/
Traceback (most recent call last):
  File "C:\Users\Ivan\PycharmProjects\Django_geek_dz\.venv\Lib\site-packages\django\core\handlers\exception.py", line 55, in inner
    response = get_response(request)
               ^^^^^^^^^^^^^^^^^^^^^
  File "C:\Users\Ivan\PycharmProjects\Django_geek_dz\.venv\Lib\site-packages\django\core\handlers\base.py", line 197, in _get_response
    response = wrapped_callback(request, *callback_args, **callback_kwargs)
               ^^^^^^^^^^^^^^^^^^^^^^^^^^^^^^^^^^^^^^^^^^^^^^^^^^^^^^^^^^^^
  File "C:\Users\Ivan\PycharmProjects\Django_geek_dz\myproject\myapp\views.py", line 25, in user_products
    return render(request, "myapp/user_products.html", context)
           ^^^^^^^^^^^^^^^^^^^^^^^^^^^^^^^^^^^^^^^^^^^^^^^^^^^^
  File "C:\Users\Ivan\PycharmProjects\Django_geek_dz\.venv\Lib\site-packages\django\shortcuts.py", line 25, in render
    content = loader.render_to_string(template_name, context, request, using=using)
              ^^^^^^^^^^^^^^^^^^^^^^^^^^^^^^^^^^^^^^^^^^^^^^^^^^^^^^^^^^^^^^^^^^^^^
  File "C:\Users\Ivan\PycharmProjects\Django_geek_dz\.venv\Lib\site-packages\django\template\loader.py", line 61, in render_to_string
    template = get_template(template_name, using=using)
               ^^^^^^^^^^^^^^^^^^^^^^^^^^^^^^^^^^^^^^^^
  File "C:\Users\Ivan\PycharmProjects\Django_geek_dz\.venv\Lib\site-packages\django\template\loader.py", line 19, in get_template
    raise TemplateDoesNotExist(template_name, chain=chain)
django.template.exceptions.TemplateDoesNotExist: myapp/user_products.html
ERROR 2024-06-18 11:03:06,050 basehttp 10116 7856 "GET /test/ HTTP/1.1" 500 82138
ERROR 2024-06-18 11:03:06,742 log 10116 7856 Internal Server Error: /test/
Traceback (most recent call last):
  File "C:\Users\Ivan\PycharmProjects\Django_geek_dz\.venv\Lib\site-packages\django\core\handlers\exception.py", line 55, in inner
    response = get_response(request)
               ^^^^^^^^^^^^^^^^^^^^^
  File "C:\Users\Ivan\PycharmProjects\Django_geek_dz\.venv\Lib\site-packages\django\core\handlers\base.py", line 197, in _get_response
    response = wrapped_callback(request, *callback_args, **callback_kwargs)
               ^^^^^^^^^^^^^^^^^^^^^^^^^^^^^^^^^^^^^^^^^^^^^^^^^^^^^^^^^^^^
  File "C:\Users\Ivan\PycharmProjects\Django_geek_dz\myproject\myapp\views.py", line 25, in user_products
    return render(request, "myapp/user_products.html", context)
           ^^^^^^^^^^^^^^^^^^^^^^^^^^^^^^^^^^^^^^^^^^^^^^^^^^^^
  File "C:\Users\Ivan\PycharmProjects\Django_geek_dz\.venv\Lib\site-packages\django\shortcuts.py", line 25, in render
    content = loader.render_to_string(template_name, context, request, using=using)
              ^^^^^^^^^^^^^^^^^^^^^^^^^^^^^^^^^^^^^^^^^^^^^^^^^^^^^^^^^^^^^^^^^^^^^
  File "C:\Users\Ivan\PycharmProjects\Django_geek_dz\.venv\Lib\site-packages\django\template\loader.py", line 61, in render_to_string
    template = get_template(template_name, using=using)
               ^^^^^^^^^^^^^^^^^^^^^^^^^^^^^^^^^^^^^^^^
  File "C:\Users\Ivan\PycharmProjects\Django_geek_dz\.venv\Lib\site-packages\django\template\loader.py", line 19, in get_template
    raise TemplateDoesNotExist(template_name, chain=chain)
django.template.exceptions.TemplateDoesNotExist: myapp/user_products.html
ERROR 2024-06-18 11:03:06,743 basehttp 10116 7856 "GET /test/ HTTP/1.1" 500 82138
ERROR 2024-06-18 11:03:07,126 log 10116 7856 Internal Server Error: /test/
Traceback (most recent call last):
  File "C:\Users\Ivan\PycharmProjects\Django_geek_dz\.venv\Lib\site-packages\django\core\handlers\exception.py", line 55, in inner
    response = get_response(request)
               ^^^^^^^^^^^^^^^^^^^^^
  File "C:\Users\Ivan\PycharmProjects\Django_geek_dz\.venv\Lib\site-packages\django\core\handlers\base.py", line 197, in _get_response
    response = wrapped_callback(request, *callback_args, **callback_kwargs)
               ^^^^^^^^^^^^^^^^^^^^^^^^^^^^^^^^^^^^^^^^^^^^^^^^^^^^^^^^^^^^
  File "C:\Users\Ivan\PycharmProjects\Django_geek_dz\myproject\myapp\views.py", line 25, in user_products
    return render(request, "myapp/user_products.html", context)
           ^^^^^^^^^^^^^^^^^^^^^^^^^^^^^^^^^^^^^^^^^^^^^^^^^^^^
  File "C:\Users\Ivan\PycharmProjects\Django_geek_dz\.venv\Lib\site-packages\django\shortcuts.py", line 25, in render
    content = loader.render_to_string(template_name, context, request, using=using)
              ^^^^^^^^^^^^^^^^^^^^^^^^^^^^^^^^^^^^^^^^^^^^^^^^^^^^^^^^^^^^^^^^^^^^^
  File "C:\Users\Ivan\PycharmProjects\Django_geek_dz\.venv\Lib\site-packages\django\template\loader.py", line 61, in render_to_string
    template = get_template(template_name, using=using)
               ^^^^^^^^^^^^^^^^^^^^^^^^^^^^^^^^^^^^^^^^
  File "C:\Users\Ivan\PycharmProjects\Django_geek_dz\.venv\Lib\site-packages\django\template\loader.py", line 19, in get_template
    raise TemplateDoesNotExist(template_name, chain=chain)
django.template.exceptions.TemplateDoesNotExist: myapp/user_products.html
ERROR 2024-06-18 11:03:07,128 basehttp 10116 7856 "GET /test/ HTTP/1.1" 500 82138
ERROR 2024-06-18 11:05:01,681 log 10116 7856 Internal Server Error: /test/
Traceback (most recent call last):
  File "C:\Users\Ivan\PycharmProjects\Django_geek_dz\.venv\Lib\site-packages\django\core\handlers\exception.py", line 55, in inner
    response = get_response(request)
               ^^^^^^^^^^^^^^^^^^^^^
  File "C:\Users\Ivan\PycharmProjects\Django_geek_dz\.venv\Lib\site-packages\django\core\handlers\base.py", line 197, in _get_response
    response = wrapped_callback(request, *callback_args, **callback_kwargs)
               ^^^^^^^^^^^^^^^^^^^^^^^^^^^^^^^^^^^^^^^^^^^^^^^^^^^^^^^^^^^^
  File "C:\Users\Ivan\PycharmProjects\Django_geek_dz\myproject\myapp\views.py", line 25, in user_products
    return render(request, "myapp/user_products.html", context)
           ^^^^^^^^^^^^^^^^^^^^^^^^^^^^^^^^^^^^^^^^^^^^^^^^^^^^
  File "C:\Users\Ivan\PycharmProjects\Django_geek_dz\.venv\Lib\site-packages\django\shortcuts.py", line 25, in render
    content = loader.render_to_string(template_name, context, request, using=using)
              ^^^^^^^^^^^^^^^^^^^^^^^^^^^^^^^^^^^^^^^^^^^^^^^^^^^^^^^^^^^^^^^^^^^^^
  File "C:\Users\Ivan\PycharmProjects\Django_geek_dz\.venv\Lib\site-packages\django\template\loader.py", line 61, in render_to_string
    template = get_template(template_name, using=using)
               ^^^^^^^^^^^^^^^^^^^^^^^^^^^^^^^^^^^^^^^^
  File "C:\Users\Ivan\PycharmProjects\Django_geek_dz\.venv\Lib\site-packages\django\template\loader.py", line 19, in get_template
    raise TemplateDoesNotExist(template_name, chain=chain)
django.template.exceptions.TemplateDoesNotExist: myapp/user_products.html
ERROR 2024-06-18 11:05:01,683 basehttp 10116 7856 "GET /test/ HTTP/1.1" 500 82138
ERROR 2024-06-18 11:05:28,829 log 10116 7856 Internal Server Error: /test/
Traceback (most recent call last):
  File "C:\Users\Ivan\PycharmProjects\Django_geek_dz\.venv\Lib\site-packages\django\core\handlers\exception.py", line 55, in inner
    response = get_response(request)
               ^^^^^^^^^^^^^^^^^^^^^
  File "C:\Users\Ivan\PycharmProjects\Django_geek_dz\.venv\Lib\site-packages\django\core\handlers\base.py", line 197, in _get_response
    response = wrapped_callback(request, *callback_args, **callback_kwargs)
               ^^^^^^^^^^^^^^^^^^^^^^^^^^^^^^^^^^^^^^^^^^^^^^^^^^^^^^^^^^^^
  File "C:\Users\Ivan\PycharmProjects\Django_geek_dz\myproject\myapp\views.py", line 25, in user_products
    return render(request, "myapp/user_products.html", context)
           ^^^^^^^^^^^^^^^^^^^^^^^^^^^^^^^^^^^^^^^^^^^^^^^^^^^^
  File "C:\Users\Ivan\PycharmProjects\Django_geek_dz\.venv\Lib\site-packages\django\shortcuts.py", line 25, in render
    content = loader.render_to_string(template_name, context, request, using=using)
              ^^^^^^^^^^^^^^^^^^^^^^^^^^^^^^^^^^^^^^^^^^^^^^^^^^^^^^^^^^^^^^^^^^^^^
  File "C:\Users\Ivan\PycharmProjects\Django_geek_dz\.venv\Lib\site-packages\django\template\loader.py", line 61, in render_to_string
    template = get_template(template_name, using=using)
               ^^^^^^^^^^^^^^^^^^^^^^^^^^^^^^^^^^^^^^^^
  File "C:\Users\Ivan\PycharmProjects\Django_geek_dz\.venv\Lib\site-packages\django\template\loader.py", line 19, in get_template
    raise TemplateDoesNotExist(template_name, chain=chain)
django.template.exceptions.TemplateDoesNotExist: myapp/user_products.html
ERROR 2024-06-18 11:05:28,831 basehttp 10116 7856 "GET /test/ HTTP/1.1" 500 82138
ERROR 2024-06-18 11:05:29,934 log 10116 7856 Internal Server Error: /test/
Traceback (most recent call last):
  File "C:\Users\Ivan\PycharmProjects\Django_geek_dz\.venv\Lib\site-packages\django\core\handlers\exception.py", line 55, in inner
    response = get_response(request)
               ^^^^^^^^^^^^^^^^^^^^^
  File "C:\Users\Ivan\PycharmProjects\Django_geek_dz\.venv\Lib\site-packages\django\core\handlers\base.py", line 197, in _get_response
    response = wrapped_callback(request, *callback_args, **callback_kwargs)
               ^^^^^^^^^^^^^^^^^^^^^^^^^^^^^^^^^^^^^^^^^^^^^^^^^^^^^^^^^^^^
  File "C:\Users\Ivan\PycharmProjects\Django_geek_dz\myproject\myapp\views.py", line 25, in user_products
    return render(request, "myapp/user_products.html", context)
           ^^^^^^^^^^^^^^^^^^^^^^^^^^^^^^^^^^^^^^^^^^^^^^^^^^^^
  File "C:\Users\Ivan\PycharmProjects\Django_geek_dz\.venv\Lib\site-packages\django\shortcuts.py", line 25, in render
    content = loader.render_to_string(template_name, context, request, using=using)
              ^^^^^^^^^^^^^^^^^^^^^^^^^^^^^^^^^^^^^^^^^^^^^^^^^^^^^^^^^^^^^^^^^^^^^
  File "C:\Users\Ivan\PycharmProjects\Django_geek_dz\.venv\Lib\site-packages\django\template\loader.py", line 61, in render_to_string
    template = get_template(template_name, using=using)
               ^^^^^^^^^^^^^^^^^^^^^^^^^^^^^^^^^^^^^^^^
  File "C:\Users\Ivan\PycharmProjects\Django_geek_dz\.venv\Lib\site-packages\django\template\loader.py", line 19, in get_template
    raise TemplateDoesNotExist(template_name, chain=chain)
django.template.exceptions.TemplateDoesNotExist: myapp/user_products.html
ERROR 2024-06-18 11:05:29,935 basehttp 10116 7856 "GET /test/ HTTP/1.1" 500 82138
ERROR 2024-06-18 11:05:30,438 log 10116 7856 Internal Server Error: /test/
Traceback (most recent call last):
  File "C:\Users\Ivan\PycharmProjects\Django_geek_dz\.venv\Lib\site-packages\django\core\handlers\exception.py", line 55, in inner
    response = get_response(request)
               ^^^^^^^^^^^^^^^^^^^^^
  File "C:\Users\Ivan\PycharmProjects\Django_geek_dz\.venv\Lib\site-packages\django\core\handlers\base.py", line 197, in _get_response
    response = wrapped_callback(request, *callback_args, **callback_kwargs)
               ^^^^^^^^^^^^^^^^^^^^^^^^^^^^^^^^^^^^^^^^^^^^^^^^^^^^^^^^^^^^
  File "C:\Users\Ivan\PycharmProjects\Django_geek_dz\myproject\myapp\views.py", line 25, in user_products
    return render(request, "myapp/user_products.html", context)
           ^^^^^^^^^^^^^^^^^^^^^^^^^^^^^^^^^^^^^^^^^^^^^^^^^^^^
  File "C:\Users\Ivan\PycharmProjects\Django_geek_dz\.venv\Lib\site-packages\django\shortcuts.py", line 25, in render
    content = loader.render_to_string(template_name, context, request, using=using)
              ^^^^^^^^^^^^^^^^^^^^^^^^^^^^^^^^^^^^^^^^^^^^^^^^^^^^^^^^^^^^^^^^^^^^^
  File "C:\Users\Ivan\PycharmProjects\Django_geek_dz\.venv\Lib\site-packages\django\template\loader.py", line 61, in render_to_string
    template = get_template(template_name, using=using)
               ^^^^^^^^^^^^^^^^^^^^^^^^^^^^^^^^^^^^^^^^
  File "C:\Users\Ivan\PycharmProjects\Django_geek_dz\.venv\Lib\site-packages\django\template\loader.py", line 19, in get_template
    raise TemplateDoesNotExist(template_name, chain=chain)
django.template.exceptions.TemplateDoesNotExist: myapp/user_products.html
ERROR 2024-06-18 11:05:30,440 basehttp 10116 7856 "GET /test/ HTTP/1.1" 500 82138
ERROR 2024-06-18 11:05:48,763 log 10116 7856 Internal Server Error: /test/
Traceback (most recent call last):
  File "C:\Users\Ivan\PycharmProjects\Django_geek_dz\.venv\Lib\site-packages\django\core\handlers\exception.py", line 55, in inner
    response = get_response(request)
               ^^^^^^^^^^^^^^^^^^^^^
  File "C:\Users\Ivan\PycharmProjects\Django_geek_dz\.venv\Lib\site-packages\django\core\handlers\base.py", line 197, in _get_response
    response = wrapped_callback(request, *callback_args, **callback_kwargs)
               ^^^^^^^^^^^^^^^^^^^^^^^^^^^^^^^^^^^^^^^^^^^^^^^^^^^^^^^^^^^^
  File "C:\Users\Ivan\PycharmProjects\Django_geek_dz\myproject\myapp\views.py", line 25, in user_products
    return render(request, "myapp/user_products.html", context)
           ^^^^^^^^^^^^^^^^^^^^^^^^^^^^^^^^^^^^^^^^^^^^^^^^^^^^
  File "C:\Users\Ivan\PycharmProjects\Django_geek_dz\.venv\Lib\site-packages\django\shortcuts.py", line 25, in render
    content = loader.render_to_string(template_name, context, request, using=using)
              ^^^^^^^^^^^^^^^^^^^^^^^^^^^^^^^^^^^^^^^^^^^^^^^^^^^^^^^^^^^^^^^^^^^^^
  File "C:\Users\Ivan\PycharmProjects\Django_geek_dz\.venv\Lib\site-packages\django\template\loader.py", line 61, in render_to_string
    template = get_template(template_name, using=using)
               ^^^^^^^^^^^^^^^^^^^^^^^^^^^^^^^^^^^^^^^^
  File "C:\Users\Ivan\PycharmProjects\Django_geek_dz\.venv\Lib\site-packages\django\template\loader.py", line 19, in get_template
    raise TemplateDoesNotExist(template_name, chain=chain)
django.template.exceptions.TemplateDoesNotExist: myapp/user_products.html
ERROR 2024-06-18 11:05:48,764 basehttp 10116 7856 "GET /test/ HTTP/1.1" 500 82138
ERROR 2024-06-18 11:05:49,282 log 10116 7856 Internal Server Error: /test/
Traceback (most recent call last):
  File "C:\Users\Ivan\PycharmProjects\Django_geek_dz\.venv\Lib\site-packages\django\core\handlers\exception.py", line 55, in inner
    response = get_response(request)
               ^^^^^^^^^^^^^^^^^^^^^
  File "C:\Users\Ivan\PycharmProjects\Django_geek_dz\.venv\Lib\site-packages\django\core\handlers\base.py", line 197, in _get_response
    response = wrapped_callback(request, *callback_args, **callback_kwargs)
               ^^^^^^^^^^^^^^^^^^^^^^^^^^^^^^^^^^^^^^^^^^^^^^^^^^^^^^^^^^^^
  File "C:\Users\Ivan\PycharmProjects\Django_geek_dz\myproject\myapp\views.py", line 25, in user_products
    return render(request, "myapp/user_products.html", context)
           ^^^^^^^^^^^^^^^^^^^^^^^^^^^^^^^^^^^^^^^^^^^^^^^^^^^^
  File "C:\Users\Ivan\PycharmProjects\Django_geek_dz\.venv\Lib\site-packages\django\shortcuts.py", line 25, in render
    content = loader.render_to_string(template_name, context, request, using=using)
              ^^^^^^^^^^^^^^^^^^^^^^^^^^^^^^^^^^^^^^^^^^^^^^^^^^^^^^^^^^^^^^^^^^^^^
  File "C:\Users\Ivan\PycharmProjects\Django_geek_dz\.venv\Lib\site-packages\django\template\loader.py", line 61, in render_to_string
    template = get_template(template_name, using=using)
               ^^^^^^^^^^^^^^^^^^^^^^^^^^^^^^^^^^^^^^^^
  File "C:\Users\Ivan\PycharmProjects\Django_geek_dz\.venv\Lib\site-packages\django\template\loader.py", line 19, in get_template
    raise TemplateDoesNotExist(template_name, chain=chain)
django.template.exceptions.TemplateDoesNotExist: myapp/user_products.html
ERROR 2024-06-18 11:05:49,285 basehttp 10116 7856 "GET /test/ HTTP/1.1" 500 82138
ERROR 2024-06-18 11:05:49,635 log 10116 7856 Internal Server Error: /test/
Traceback (most recent call last):
  File "C:\Users\Ivan\PycharmProjects\Django_geek_dz\.venv\Lib\site-packages\django\core\handlers\exception.py", line 55, in inner
    response = get_response(request)
               ^^^^^^^^^^^^^^^^^^^^^
  File "C:\Users\Ivan\PycharmProjects\Django_geek_dz\.venv\Lib\site-packages\django\core\handlers\base.py", line 197, in _get_response
    response = wrapped_callback(request, *callback_args, **callback_kwargs)
               ^^^^^^^^^^^^^^^^^^^^^^^^^^^^^^^^^^^^^^^^^^^^^^^^^^^^^^^^^^^^
  File "C:\Users\Ivan\PycharmProjects\Django_geek_dz\myproject\myapp\views.py", line 25, in user_products
    return render(request, "myapp/user_products.html", context)
           ^^^^^^^^^^^^^^^^^^^^^^^^^^^^^^^^^^^^^^^^^^^^^^^^^^^^
  File "C:\Users\Ivan\PycharmProjects\Django_geek_dz\.venv\Lib\site-packages\django\shortcuts.py", line 25, in render
    content = loader.render_to_string(template_name, context, request, using=using)
              ^^^^^^^^^^^^^^^^^^^^^^^^^^^^^^^^^^^^^^^^^^^^^^^^^^^^^^^^^^^^^^^^^^^^^
  File "C:\Users\Ivan\PycharmProjects\Django_geek_dz\.venv\Lib\site-packages\django\template\loader.py", line 61, in render_to_string
    template = get_template(template_name, using=using)
               ^^^^^^^^^^^^^^^^^^^^^^^^^^^^^^^^^^^^^^^^
  File "C:\Users\Ivan\PycharmProjects\Django_geek_dz\.venv\Lib\site-packages\django\template\loader.py", line 19, in get_template
    raise TemplateDoesNotExist(template_name, chain=chain)
django.template.exceptions.TemplateDoesNotExist: myapp/user_products.html
ERROR 2024-06-18 11:05:49,636 basehttp 10116 7856 "GET /test/ HTTP/1.1" 500 82138
ERROR 2024-06-18 11:05:49,819 log 10116 7856 Internal Server Error: /test/
Traceback (most recent call last):
  File "C:\Users\Ivan\PycharmProjects\Django_geek_dz\.venv\Lib\site-packages\django\core\handlers\exception.py", line 55, in inner
    response = get_response(request)
               ^^^^^^^^^^^^^^^^^^^^^
  File "C:\Users\Ivan\PycharmProjects\Django_geek_dz\.venv\Lib\site-packages\django\core\handlers\base.py", line 197, in _get_response
    response = wrapped_callback(request, *callback_args, **callback_kwargs)
               ^^^^^^^^^^^^^^^^^^^^^^^^^^^^^^^^^^^^^^^^^^^^^^^^^^^^^^^^^^^^
  File "C:\Users\Ivan\PycharmProjects\Django_geek_dz\myproject\myapp\views.py", line 25, in user_products
    return render(request, "myapp/user_products.html", context)
           ^^^^^^^^^^^^^^^^^^^^^^^^^^^^^^^^^^^^^^^^^^^^^^^^^^^^
  File "C:\Users\Ivan\PycharmProjects\Django_geek_dz\.venv\Lib\site-packages\django\shortcuts.py", line 25, in render
    content = loader.render_to_string(template_name, context, request, using=using)
              ^^^^^^^^^^^^^^^^^^^^^^^^^^^^^^^^^^^^^^^^^^^^^^^^^^^^^^^^^^^^^^^^^^^^^
  File "C:\Users\Ivan\PycharmProjects\Django_geek_dz\.venv\Lib\site-packages\django\template\loader.py", line 61, in render_to_string
    template = get_template(template_name, using=using)
               ^^^^^^^^^^^^^^^^^^^^^^^^^^^^^^^^^^^^^^^^
  File "C:\Users\Ivan\PycharmProjects\Django_geek_dz\.venv\Lib\site-packages\django\template\loader.py", line 19, in get_template
    raise TemplateDoesNotExist(template_name, chain=chain)
django.template.exceptions.TemplateDoesNotExist: myapp/user_products.html
ERROR 2024-06-18 11:05:49,820 basehttp 10116 7856 "GET /test/ HTTP/1.1" 500 82138
ERROR 2024-06-18 11:05:50,003 log 10116 7856 Internal Server Error: /test/
Traceback (most recent call last):
  File "C:\Users\Ivan\PycharmProjects\Django_geek_dz\.venv\Lib\site-packages\django\core\handlers\exception.py", line 55, in inner
    response = get_response(request)
               ^^^^^^^^^^^^^^^^^^^^^
  File "C:\Users\Ivan\PycharmProjects\Django_geek_dz\.venv\Lib\site-packages\django\core\handlers\base.py", line 197, in _get_response
    response = wrapped_callback(request, *callback_args, **callback_kwargs)
               ^^^^^^^^^^^^^^^^^^^^^^^^^^^^^^^^^^^^^^^^^^^^^^^^^^^^^^^^^^^^
  File "C:\Users\Ivan\PycharmProjects\Django_geek_dz\myproject\myapp\views.py", line 25, in user_products
    return render(request, "myapp/user_products.html", context)
           ^^^^^^^^^^^^^^^^^^^^^^^^^^^^^^^^^^^^^^^^^^^^^^^^^^^^
  File "C:\Users\Ivan\PycharmProjects\Django_geek_dz\.venv\Lib\site-packages\django\shortcuts.py", line 25, in render
    content = loader.render_to_string(template_name, context, request, using=using)
              ^^^^^^^^^^^^^^^^^^^^^^^^^^^^^^^^^^^^^^^^^^^^^^^^^^^^^^^^^^^^^^^^^^^^^
  File "C:\Users\Ivan\PycharmProjects\Django_geek_dz\.venv\Lib\site-packages\django\template\loader.py", line 61, in render_to_string
    template = get_template(template_name, using=using)
               ^^^^^^^^^^^^^^^^^^^^^^^^^^^^^^^^^^^^^^^^
  File "C:\Users\Ivan\PycharmProjects\Django_geek_dz\.venv\Lib\site-packages\django\template\loader.py", line 19, in get_template
    raise TemplateDoesNotExist(template_name, chain=chain)
django.template.exceptions.TemplateDoesNotExist: myapp/user_products.html
ERROR 2024-06-18 11:05:50,005 basehttp 10116 7856 "GET /test/ HTTP/1.1" 500 82138
ERROR 2024-06-18 11:05:50,210 log 10116 7856 Internal Server Error: /test/
Traceback (most recent call last):
  File "C:\Users\Ivan\PycharmProjects\Django_geek_dz\.venv\Lib\site-packages\django\core\handlers\exception.py", line 55, in inner
    response = get_response(request)
               ^^^^^^^^^^^^^^^^^^^^^
  File "C:\Users\Ivan\PycharmProjects\Django_geek_dz\.venv\Lib\site-packages\django\core\handlers\base.py", line 197, in _get_response
    response = wrapped_callback(request, *callback_args, **callback_kwargs)
               ^^^^^^^^^^^^^^^^^^^^^^^^^^^^^^^^^^^^^^^^^^^^^^^^^^^^^^^^^^^^
  File "C:\Users\Ivan\PycharmProjects\Django_geek_dz\myproject\myapp\views.py", line 25, in user_products
    return render(request, "myapp/user_products.html", context)
           ^^^^^^^^^^^^^^^^^^^^^^^^^^^^^^^^^^^^^^^^^^^^^^^^^^^^
  File "C:\Users\Ivan\PycharmProjects\Django_geek_dz\.venv\Lib\site-packages\django\shortcuts.py", line 25, in render
    content = loader.render_to_string(template_name, context, request, using=using)
              ^^^^^^^^^^^^^^^^^^^^^^^^^^^^^^^^^^^^^^^^^^^^^^^^^^^^^^^^^^^^^^^^^^^^^
  File "C:\Users\Ivan\PycharmProjects\Django_geek_dz\.venv\Lib\site-packages\django\template\loader.py", line 61, in render_to_string
    template = get_template(template_name, using=using)
               ^^^^^^^^^^^^^^^^^^^^^^^^^^^^^^^^^^^^^^^^
  File "C:\Users\Ivan\PycharmProjects\Django_geek_dz\.venv\Lib\site-packages\django\template\loader.py", line 19, in get_template
    raise TemplateDoesNotExist(template_name, chain=chain)
django.template.exceptions.TemplateDoesNotExist: myapp/user_products.html
ERROR 2024-06-18 11:05:50,211 basehttp 10116 7856 "GET /test/ HTTP/1.1" 500 82138
INFO 2024-06-18 11:06:22,143 autoreload 7136 17252 Watching for file changes with StatReloader
INFO 2024-06-18 11:06:25,667 basehttp 7136 14540 "GET /test/ HTTP/1.1" 200 124
INFO 2024-06-18 11:06:28,291 basehttp 7136 14540 "GET /test/ HTTP/1.1" 200 124
INFO 2024-06-18 11:06:28,803 basehttp 7136 14540 "GET /test/ HTTP/1.1" 200 124
INFO 2024-06-18 11:06:41,420 autoreload 16944 5408 Watching for file changes with StatReloader
INFO 2024-06-18 11:06:43,825 basehttp 16944 17024 "GET /test/ HTTP/1.1" 200 133
INFO 2024-06-18 11:07:42,578 basehttp 16944 17024 "GET /test/ HTTP/1.1" 200 210
INFO 2024-06-18 11:34:18,255 autoreload 16944 5408 C:\Users\Ivan\PycharmProjects\Django_geek_dz\myproject\myapp\models.py changed, reloading.
INFO 2024-06-18 11:34:18,888 autoreload 16388 8952 Watching for file changes with StatReloader
INFO 2024-06-18 11:36:24,305 autoreload 16388 8952 C:\Users\Ivan\PycharmProjects\Django_geek_dz\myproject\myapp\views.py changed, reloading.
INFO 2024-06-18 11:36:24,758 autoreload 10104 15840 Watching for file changes with StatReloader
INFO 2024-06-18 11:37:57,373 autoreload 10104 15840 C:\Users\Ivan\PycharmProjects\Django_geek_dz\myproject\myapp\urls.py changed, reloading.
INFO 2024-06-18 11:37:57,831 autoreload 3192 12792 Watching for file changes with StatReloader
INFO 2024-06-18 11:56:01,979 autoreload 3192 12792 C:\Users\Ivan\PycharmProjects\Django_geek_dz\myproject\myapp\views.py changed, reloading.
INFO 2024-06-18 11:56:02,480 autoreload 3516 8840 Watching for file changes with StatReloader
INFO 2024-06-18 11:58:05,950 autoreload 3516 8840 C:\Users\Ivan\PycharmProjects\Django_geek_dz\myproject\myapp\views.py changed, reloading.
INFO 2024-06-18 11:58:06,443 autoreload 2976 6184 Watching for file changes with StatReloader
INFO 2024-06-18 11:59:13,455 autoreload 2976 6184 C:\Users\Ivan\PycharmProjects\Django_geek_dz\myproject\myapp\views.py changed, reloading.
INFO 2024-06-18 11:59:13,934 autoreload 15404 11168 Watching for file changes with StatReloader
INFO 2024-06-18 12:03:34,950 autoreload 15404 11168 C:\Users\Ivan\PycharmProjects\Django_geek_dz\myproject\myapp\views.py changed, reloading.
INFO 2024-06-18 12:03:35,440 autoreload 1416 11920 Watching for file changes with StatReloader
INFO 2024-06-18 12:03:50,074 autoreload 1416 11920 C:\Users\Ivan\PycharmProjects\Django_geek_dz\myproject\myapp\views.py changed, reloading.
INFO 2024-06-18 12:03:50,587 autoreload 13724 6184 Watching for file changes with StatReloader
INFO 2024-06-18 12:04:24,758 autoreload 13724 6184 C:\Users\Ivan\PycharmProjects\Django_geek_dz\myproject\myapp\views.py changed, reloading.
INFO 2024-06-18 12:04:25,222 autoreload 15152 9720 Watching for file changes with StatReloader
INFO 2024-06-18 12:04:51,138 autoreload 15152 9720 C:\Users\Ivan\PycharmProjects\Django_geek_dz\myproject\myapp\views.py changed, reloading.
INFO 2024-06-18 12:04:51,598 autoreload 7476 12432 Watching for file changes with StatReloader
INFO 2024-06-18 12:05:44,186 autoreload 7476 12432 C:\Users\Ivan\PycharmProjects\Django_geek_dz\myproject\myapp\views.py changed, reloading.
INFO 2024-06-18 12:05:44,659 autoreload 8592 9808 Watching for file changes with StatReloader
WARNING 2024-06-18 13:39:37,135 log 8592 9428 Not Found: /test/
WARNING 2024-06-18 13:39:37,136 basehttp 8592 9428 "GET /test/ HTTP/1.1" 404 2606
INFO 2024-06-18 13:39:49,815 basehttp 8592 9428 "GET /user_products HTTP/1.1" 301 0
ERROR 2024-06-18 13:39:49,848 log 8592 2284 Internal Server Error: /user_products/
Traceback (most recent call last):
  File "C:\Users\Ivan\PycharmProjects\Django_geek_dz\.venv\Lib\site-packages\django\core\handlers\exception.py", line 55, in inner
    response = get_response(request)
               ^^^^^^^^^^^^^^^^^^^^^
  File "C:\Users\Ivan\PycharmProjects\Django_geek_dz\.venv\Lib\site-packages\django\core\handlers\base.py", line 197, in _get_response
    response = wrapped_callback(request, *callback_args, **callback_kwargs)
               ^^^^^^^^^^^^^^^^^^^^^^^^^^^^^^^^^^^^^^^^^^^^^^^^^^^^^^^^^^^^
TypeError: user_products() missing 1 required positional argument: 'user_id'
ERROR 2024-06-18 13:39:49,849 basehttp 8592 2284 "GET /user_products/ HTTP/1.1" 500 62500
WARNING 2024-06-18 13:39:54,060 log 8592 2284 Not Found: /user_products/1
WARNING 2024-06-18 13:39:54,060 basehttp 8592 2284 "GET /user_products/1 HTTP/1.1" 404 2636
ERROR 2024-06-18 13:41:16,526 log 8592 2284 Internal Server Error: /user_products/
Traceback (most recent call last):
  File "C:\Users\Ivan\PycharmProjects\Django_geek_dz\.venv\Lib\site-packages\django\core\handlers\exception.py", line 55, in inner
    response = get_response(request)
               ^^^^^^^^^^^^^^^^^^^^^
  File "C:\Users\Ivan\PycharmProjects\Django_geek_dz\.venv\Lib\site-packages\django\core\handlers\base.py", line 197, in _get_response
    response = wrapped_callback(request, *callback_args, **callback_kwargs)
               ^^^^^^^^^^^^^^^^^^^^^^^^^^^^^^^^^^^^^^^^^^^^^^^^^^^^^^^^^^^^
TypeError: user_products() missing 1 required positional argument: 'user_id'
ERROR 2024-06-18 13:41:16,527 basehttp 8592 2284 "GET /user_products/ HTTP/1.1" 500 62500
WARNING 2024-06-18 13:41:19,423 log 8592 2284 Not Found: /user_products/1
WARNING 2024-06-18 13:41:19,424 basehttp 8592 2284 "GET /user_products/1 HTTP/1.1" 404 2636
INFO 2024-06-18 13:42:03,726 autoreload 8592 9808 C:\Users\Ivan\PycharmProjects\Django_geek_dz\myproject\myapp\views.py changed, reloading.
INFO 2024-06-18 13:42:04,220 autoreload 7160 13572 Watching for file changes with StatReloader
WARNING 2024-06-18 13:42:07,252 log 7160 16944 Not Found: /user_products/1
WARNING 2024-06-18 13:42:07,252 basehttp 7160 16944 "GET /user_products/1 HTTP/1.1" 404 2636
ERROR 2024-06-18 13:42:09,426 log 7160 16944 Internal Server Error: /user_products/
Traceback (most recent call last):
  File "C:\Users\Ivan\PycharmProjects\Django_geek_dz\.venv\Lib\site-packages\django\core\handlers\exception.py", line 55, in inner
    response = get_response(request)
               ^^^^^^^^^^^^^^^^^^^^^
  File "C:\Users\Ivan\PycharmProjects\Django_geek_dz\.venv\Lib\site-packages\django\core\handlers\base.py", line 197, in _get_response
    response = wrapped_callback(request, *callback_args, **callback_kwargs)
               ^^^^^^^^^^^^^^^^^^^^^^^^^^^^^^^^^^^^^^^^^^^^^^^^^^^^^^^^^^^^
TypeError: user_products() missing 1 required positional argument: 'user_id'
ERROR 2024-06-18 13:42:09,426 basehttp 7160 16944 "GET /user_products/ HTTP/1.1" 500 62500
WARNING 2024-06-18 13:42:37,706 log 7160 16944 Not Found: /user_products/2
WARNING 2024-06-18 13:42:37,707 basehttp 7160 16944 "GET /user_products/2 HTTP/1.1" 404 2636
INFO 2024-06-18 14:06:18,144 autoreload 13260 17272 Watching for file changes with StatReloader
WARNING 2024-06-18 14:06:22,423 log 13260 1940 Not Found: /user_products/2
WARNING 2024-06-18 14:06:22,423 basehttp 13260 1940 "GET /user_products/2 HTTP/1.1" 404 2636
WARNING 2024-06-18 14:06:23,261 log 13260 1940 Not Found: /user_products/2
WARNING 2024-06-18 14:06:23,261 basehttp 13260 1940 "GET /user_products/2 HTTP/1.1" 404 2636
WARNING 2024-06-18 14:06:25,755 log 13260 1940 Not Found: /user_products/1
WARNING 2024-06-18 14:06:25,756 basehttp 13260 1940 "GET /user_products/1 HTTP/1.1" 404 2636
ERROR 2024-06-18 14:06:28,658 log 13260 1940 Internal Server Error: /user_products/
Traceback (most recent call last):
  File "C:\Users\Ivan\PycharmProjects\Django_geek_dz\.venv\Lib\site-packages\django\core\handlers\exception.py", line 55, in inner
    response = get_response(request)
               ^^^^^^^^^^^^^^^^^^^^^
  File "C:\Users\Ivan\PycharmProjects\Django_geek_dz\.venv\Lib\site-packages\django\core\handlers\base.py", line 197, in _get_response
    response = wrapped_callback(request, *callback_args, **callback_kwargs)
               ^^^^^^^^^^^^^^^^^^^^^^^^^^^^^^^^^^^^^^^^^^^^^^^^^^^^^^^^^^^^
TypeError: user_products() missing 1 required positional argument: 'user_id'
ERROR 2024-06-18 14:06:28,659 basehttp 13260 1940 "GET /user_products/ HTTP/1.1" 500 62500
INFO 2024-06-18 14:09:29,646 autoreload 13260 17272 C:\Users\Ivan\PycharmProjects\Django_geek_dz\myproject\myapp\views.py changed, reloading.
INFO 2024-06-18 14:09:30,132 autoreload 17620 16856 Watching for file changes with StatReloader
ERROR 2024-06-18 14:09:33,574 log 17620 18008 Internal Server Error: /user_products/
Traceback (most recent call last):
  File "C:\Users\Ivan\PycharmProjects\Django_geek_dz\.venv\Lib\site-packages\django\core\handlers\exception.py", line 55, in inner
    response = get_response(request)
               ^^^^^^^^^^^^^^^^^^^^^
  File "C:\Users\Ivan\PycharmProjects\Django_geek_dz\.venv\Lib\site-packages\django\core\handlers\base.py", line 197, in _get_response
    response = wrapped_callback(request, *callback_args, **callback_kwargs)
               ^^^^^^^^^^^^^^^^^^^^^^^^^^^^^^^^^^^^^^^^^^^^^^^^^^^^^^^^^^^^
TypeError: user_products() missing 1 required positional argument: 'user_id'
ERROR 2024-06-18 14:09:33,575 basehttp 17620 18008 "GET /user_products/ HTTP/1.1" 500 62637
WARNING 2024-06-18 14:09:37,160 log 17620 18008 Not Found: /user_products/2
WARNING 2024-06-18 14:09:37,160 basehttp 17620 18008 "GET /user_products/2 HTTP/1.1" 404 2636
INFO 2024-06-18 14:10:11,567 autoreload 17620 16856 C:\Users\Ivan\PycharmProjects\Django_geek_dz\myproject\myapp\urls.py changed, reloading.
INFO 2024-06-18 14:10:12,031 autoreload 8148 5480 Watching for file changes with StatReloader
INFO 2024-06-18 14:10:15,859 basehttp 8148 16580 "GET /user_products/2 HTTP/1.1" 301 0
ERROR 2024-06-18 14:10:15,889 log 8148 17832 Internal Server Error: /user_products/2/
Traceback (most recent call last):
  File "C:\Users\Ivan\PycharmProjects\Django_geek_dz\.venv\Lib\site-packages\django\core\handlers\exception.py", line 55, in inner
    response = get_response(request)
               ^^^^^^^^^^^^^^^^^^^^^
  File "C:\Users\Ivan\PycharmProjects\Django_geek_dz\.venv\Lib\site-packages\django\core\handlers\base.py", line 197, in _get_response
    response = wrapped_callback(request, *callback_args, **callback_kwargs)
               ^^^^^^^^^^^^^^^^^^^^^^^^^^^^^^^^^^^^^^^^^^^^^^^^^^^^^^^^^^^^
TypeError: user_products() got an unexpected keyword argument 'customer_id'
ERROR 2024-06-18 14:10:15,889 basehttp 8148 17832 "GET /user_products/2/ HTTP/1.1" 500 62677
INFO 2024-06-18 14:10:21,149 basehttp 8148 17832 "GET /user_products/1 HTTP/1.1" 301 0
ERROR 2024-06-18 14:10:21,166 log 8148 10408 Internal Server Error: /user_products/1/
Traceback (most recent call last):
  File "C:\Users\Ivan\PycharmProjects\Django_geek_dz\.venv\Lib\site-packages\django\core\handlers\exception.py", line 55, in inner
    response = get_response(request)
               ^^^^^^^^^^^^^^^^^^^^^
  File "C:\Users\Ivan\PycharmProjects\Django_geek_dz\.venv\Lib\site-packages\django\core\handlers\base.py", line 197, in _get_response
    response = wrapped_callback(request, *callback_args, **callback_kwargs)
               ^^^^^^^^^^^^^^^^^^^^^^^^^^^^^^^^^^^^^^^^^^^^^^^^^^^^^^^^^^^^
TypeError: user_products() got an unexpected keyword argument 'customer_id'
ERROR 2024-06-18 14:10:21,166 basehttp 8148 10408 "GET /user_products/1/ HTTP/1.1" 500 62540
INFO 2024-06-18 14:10:46,362 autoreload 8148 5480 C:\Users\Ivan\PycharmProjects\Django_geek_dz\myproject\myapp\urls.py changed, reloading.
INFO 2024-06-18 14:10:46,853 autoreload 11232 14224 Watching for file changes with StatReloader
ERROR 2024-06-18 14:10:48,570 log 11232 14332 Internal Server Error: /user_products/1/
Traceback (most recent call last):
  File "C:\Users\Ivan\PycharmProjects\Django_geek_dz\.venv\Lib\site-packages\django\core\handlers\exception.py", line 55, in inner
    response = get_response(request)
               ^^^^^^^^^^^^^^^^^^^^^
  File "C:\Users\Ivan\PycharmProjects\Django_geek_dz\.venv\Lib\site-packages\django\core\handlers\base.py", line 197, in _get_response
    response = wrapped_callback(request, *callback_args, **callback_kwargs)
               ^^^^^^^^^^^^^^^^^^^^^^^^^^^^^^^^^^^^^^^^^^^^^^^^^^^^^^^^^^^^
  File "C:\Users\Ivan\PycharmProjects\Django_geek_dz\myproject\myapp\views.py", line 26, in user_products
    last_7_days = timezone.now() - timedelta(days=7)
                  ^^^^^^^^^^^^
AttributeError: type object 'datetime.timezone' has no attribute 'now'
ERROR 2024-06-18 14:10:48,576 basehttp 11232 14332 "GET /user_products/1/ HTTP/1.1" 500 66879
INFO 2024-06-18 14:13:56,209 autoreload 11232 14224 C:\Users\Ivan\PycharmProjects\Django_geek_dz\myproject\myapp\views.py changed, reloading.
INFO 2024-06-18 14:13:56,692 autoreload 15904 17508 Watching for file changes with StatReloader
ERROR 2024-06-18 14:13:57,576 log 15904 6680 Internal Server Error: /user_products/1/
Traceback (most recent call last):
  File "C:\Users\Ivan\PycharmProjects\Django_geek_dz\.venv\Lib\site-packages\django\core\handlers\exception.py", line 55, in inner
    response = get_response(request)
               ^^^^^^^^^^^^^^^^^^^^^
  File "C:\Users\Ivan\PycharmProjects\Django_geek_dz\.venv\Lib\site-packages\django\core\handlers\base.py", line 197, in _get_response
    response = wrapped_callback(request, *callback_args, **callback_kwargs)
               ^^^^^^^^^^^^^^^^^^^^^^^^^^^^^^^^^^^^^^^^^^^^^^^^^^^^^^^^^^^^
  File "C:\Users\Ivan\PycharmProjects\Django_geek_dz\myproject\myapp\views.py", line 27, in user_products
    user_order_7 = Product.objects.filter(order__customer=user, order__order_date__gte=last_7_days).distinct()
                   ^^^^^^^^^^^^^^^^^^^^^^^^^^^^^^^^^^^^^^^^^^^^^^^^^^^^^^^^^^^^^^^^^^^^^^^^^^^^^^^^
  File "C:\Users\Ivan\PycharmProjects\Django_geek_dz\.venv\Lib\site-packages\django\db\models\manager.py", line 87, in manager_method
    return getattr(self.get_queryset(), name)(*args, **kwargs)
           ^^^^^^^^^^^^^^^^^^^^^^^^^^^^^^^^^^^^^^^^^^^^^^^^^^^
  File "C:\Users\Ivan\PycharmProjects\Django_geek_dz\.venv\Lib\site-packages\django\db\models\query.py", line 1476, in filter
    return self._filter_or_exclude(False, args, kwargs)
           ^^^^^^^^^^^^^^^^^^^^^^^^^^^^^^^^^^^^^^^^^^^^
  File "C:\Users\Ivan\PycharmProjects\Django_geek_dz\.venv\Lib\site-packages\django\db\models\query.py", line 1494, in _filter_or_exclude
    clone._filter_or_exclude_inplace(negate, args, kwargs)
  File "C:\Users\Ivan\PycharmProjects\Django_geek_dz\.venv\Lib\site-packages\django\db\models\query.py", line 1501, in _filter_or_exclude_inplace
    self._query.add_q(Q(*args, **kwargs))
  File "C:\Users\Ivan\PycharmProjects\Django_geek_dz\.venv\Lib\site-packages\django\db\models\sql\query.py", line 1613, in add_q
    clause, _ = self._add_q(q_object, self.used_aliases)
                ^^^^^^^^^^^^^^^^^^^^^^^^^^^^^^^^^^^^^^^^
  File "C:\Users\Ivan\PycharmProjects\Django_geek_dz\.venv\Lib\site-packages\django\db\models\sql\query.py", line 1645, in _add_q
    child_clause, needed_inner = self.build_filter(
                                 ^^^^^^^^^^^^^^^^^^
  File "C:\Users\Ivan\PycharmProjects\Django_geek_dz\.venv\Lib\site-packages\django\db\models\sql\query.py", line 1559, in build_filter
    condition = self.build_lookup(lookups, col, value)
                ^^^^^^^^^^^^^^^^^^^^^^^^^^^^^^^^^^^^^^
  File "C:\Users\Ivan\PycharmProjects\Django_geek_dz\.venv\Lib\site-packages\django\db\models\sql\query.py", line 1376, in build_lookup
    lhs = self.try_transform(lhs, name)
          ^^^^^^^^^^^^^^^^^^^^^^^^^^^^^
  File "C:\Users\Ivan\PycharmProjects\Django_geek_dz\.venv\Lib\site-packages\django\db\models\sql\query.py", line 1427, in try_transform
    raise FieldError(
django.core.exceptions.FieldError: Unsupported lookup 'order_date' for ForeignKey or join on the field not permitted.
ERROR 2024-06-18 14:13:57,579 basehttp 15904 6680 "GET /user_products/1/ HTTP/1.1" 500 118817
INFO 2024-06-18 14:14:50,380 autoreload 15904 17508 C:\Users\Ivan\PycharmProjects\Django_geek_dz\myproject\myapp\views.py changed, reloading.
INFO 2024-06-18 14:14:50,839 autoreload 18072 2696 Watching for file changes with StatReloader
